2020-01-15 13:07:44,480 DEBUG - (yroll.macalino) - Successfully loaded and updated table
2020-01-15 13:08:44,960 ERROR - Internal Server Error: /dashboard/jenkins-api/jenkinscreate/
Traceback (most recent call last):
  File "/app/argus_final/venv/lib/python2.7/site-packages/django/core/handlers/exception.py", line 41, in inner
    response = get_response(request)
  File "/app/argus_final/venv/lib/python2.7/site-packages/django/core/handlers/base.py", line 187, in _get_response
    response = self.process_exception_by_middleware(e, request)
  File "/app/argus_final/venv/lib/python2.7/site-packages/django/core/handlers/base.py", line 185, in _get_response
    response = wrapped_callback(request, *callback_args, **callback_kwargs)
  File "/app/argus_final/venv/lib/python2.7/site-packages/django/views/decorators/csrf.py", line 58, in wrapped_view
    return view_func(*args, **kwargs)
  File "/app/argus_final/venv/lib/python2.7/site-packages/django/views/generic/base.py", line 68, in view
    return self.dispatch(request, *args, **kwargs)
  File "/app/argus_final/venv/lib/python2.7/site-packages/rest_framework/views.py", line 495, in dispatch
    response = self.handle_exception(exc)
  File "/app/argus_final/venv/lib/python2.7/site-packages/rest_framework/views.py", line 455, in handle_exception
    self.raise_uncaught_exception(exc)
  File "/app/argus_final/venv/lib/python2.7/site-packages/rest_framework/views.py", line 492, in dispatch
    response = handler(request, *args, **kwargs)
  File "/app/argus_final/venv/lib/python2.7/site-packages/rest_framework/generics.py", line 192, in post
    return self.create(request, *args, **kwargs)
  File "/app/argus_final/venv/lib/python2.7/site-packages/rest_framework/mixins.py", line 21, in create
    self.perform_create(serializer)
  File "/app/argus_final/venv/lib/python2.7/site-packages/rest_framework/mixins.py", line 26, in perform_create
    serializer.save()
  File "/app/argus_final/venv/lib/python2.7/site-packages/rest_framework/serializers.py", line 214, in save
    self.instance = self.create(validated_data)
  File "/app/argus_final/venv/lib/python2.7/site-packages/rest_framework/serializers.py", line 962, in create
    raise TypeError(msg)
TypeError: Got a `TypeError` when calling `JenkinsModel.objects.create()`. This may be because you have a writable field on the serializer class that is not a valid argument to `JenkinsModel.objects.create()`. You may need to make the field read-only, or override the JenkinsSerializer.create() method to handle this correctly.
Original exception was:
 Traceback (most recent call last):
  File "/app/argus_final/venv/lib/python2.7/site-packages/rest_framework/serializers.py", line 943, in create
    instance = ModelClass._default_manager.create(**validated_data)
  File "/app/argus_final/venv/lib/python2.7/site-packages/django/db/models/manager.py", line 85, in manager_method
    return getattr(self.get_queryset(), name)(*args, **kwargs)
  File "/app/argus_final/venv/lib/python2.7/site-packages/django/db/models/query.py", line 392, in create
    obj = self.model(**kwargs)
  File "/app/argus_final/venv/lib/python2.7/site-packages/django/db/models/base.py", line 573, in __init__
    raise TypeError("'%s' is an invalid keyword argument for this function" % list(kwargs)[0])
TypeError: 'JOBNUMBER' is an invalid keyword argument for this function

