2020-08-10 09:32:28,974 DEBUG - (rock.lim) - Successfully loaded and updated table
2020-08-10 10:06:40,330 ERROR - Internal Server Error: /fwdcontrol/cloud-nginx-backup/
Traceback (most recent call last):
  File "/app/argus_final/venv/lib/python2.7/site-packages/django/core/handlers/exception.py", line 41, in inner
    response = get_response(request)
  File "/app/argus_final/venv/lib/python2.7/site-packages/django/core/handlers/base.py", line 187, in _get_response
    response = self.process_exception_by_middleware(e, request)
  File "/app/argus_final/venv/lib/python2.7/site-packages/django/core/handlers/base.py", line 185, in _get_response
    response = wrapped_callback(request, *callback_args, **callback_kwargs)
  File "/app/argus_final/venv/lib/python2.7/site-packages/django/contrib/auth/decorators.py", line 23, in _wrapped_view
    return view_func(request, *args, **kwargs)
  File "/app/argus_final/venv/lib/python2.7/site-packages/django/views/generic/base.py", line 68, in view
    return self.dispatch(request, *args, **kwargs)
  File "/app/argus_final/venv/lib/python2.7/site-packages/django/utils/decorators.py", line 67, in _wrapper
    return bound_func(*args, **kwargs)
  File "/app/argus_final/venv/lib/python2.7/site-packages/django/views/decorators/csrf.py", line 58, in wrapped_view
    return view_func(*args, **kwargs)
  File "/app/argus_final/venv/lib/python2.7/site-packages/django/utils/decorators.py", line 63, in bound_func
    return func.__get__(self, type(self))(*args2, **kwargs2)
  File "/app/argus_final/app/argus/argus/mixins.py", line 14, in dispatch
    return super(GENERIC_PERMISSION_MIXIN, self).dispatch(request, *args, **kwargs)
  File "/app/argus_final/venv/lib/python2.7/site-packages/django/views/generic/base.py", line 88, in dispatch
    return handler(request, *args, **kwargs)
  File "/app/argus_final/app/argus/fwdcontrol/views.py", line 46, in get
    context['content'] = result.get()
  File "/app/argus_final/venv/lib/python2.7/site-packages/celery/result.py", line 224, in get
    on_message=on_message,
  File "/app/argus_final/venv/lib/python2.7/site-packages/celery/backends/async.py", line 190, in wait_for_pending
    return result.maybe_throw(callback=callback, propagate=propagate)
  File "/app/argus_final/venv/lib/python2.7/site-packages/celery/result.py", line 329, in maybe_throw
    self.throw(value, self._to_remote_traceback(tb))
  File "/app/argus_final/venv/lib/python2.7/site-packages/celery/result.py", line 322, in throw
    self.on_ready.throw(*args, **kwargs)
  File "/app/argus_final/venv/lib/python2.7/site-packages/vine/promises.py", line 217, in throw
    reraise(type(exc), exc, tb)
  File "<string>", line 1, in reraise
IOError: (u'[', u'E', u'r', u'r', u'n', u'o', u' ', u'2', u']', u' ', u'N', u'o', u' ', u's', u'u', u'c', u'h', u' ', u'f', u'i', u'l', u'e', u' ', u'o', u'r', u' ', u'd', u'i', u'r', u'e', u'c', u't', u'o', u'r', u'y', u':', u' ', u'u', u"'", u'/', u's', u'r', u'v', u'/', u'c', u'l', u'o', u'u', u'd', u'-', u'n', u'g', u'i', u'n', u'x', u'-', u'b', u'a', u'c', u'k', u'u', u'p', u'/', u'c', u'o', u'n', u'f', u'.', u'd', u'/', u'.', u'h', u't', u'p', u'a', u's', u's', u'w', u'd', u"'")
2020-08-10 10:06:44,792 ERROR - Internal Server Error: /fwdcontrol/office-haproxy-gdc/
Traceback (most recent call last):
  File "/app/argus_final/venv/lib/python2.7/site-packages/django/core/handlers/exception.py", line 41, in inner
    response = get_response(request)
  File "/app/argus_final/venv/lib/python2.7/site-packages/django/core/handlers/base.py", line 187, in _get_response
    response = self.process_exception_by_middleware(e, request)
  File "/app/argus_final/venv/lib/python2.7/site-packages/django/core/handlers/base.py", line 185, in _get_response
    response = wrapped_callback(request, *callback_args, **callback_kwargs)
  File "/app/argus_final/venv/lib/python2.7/site-packages/django/contrib/auth/decorators.py", line 23, in _wrapped_view
    return view_func(request, *args, **kwargs)
  File "/app/argus_final/venv/lib/python2.7/site-packages/django/views/generic/base.py", line 68, in view
    return self.dispatch(request, *args, **kwargs)
  File "/app/argus_final/venv/lib/python2.7/site-packages/django/utils/decorators.py", line 67, in _wrapper
    return bound_func(*args, **kwargs)
  File "/app/argus_final/venv/lib/python2.7/site-packages/django/views/decorators/csrf.py", line 58, in wrapped_view
    return view_func(*args, **kwargs)
  File "/app/argus_final/venv/lib/python2.7/site-packages/django/utils/decorators.py", line 63, in bound_func
    return func.__get__(self, type(self))(*args2, **kwargs2)
  File "/app/argus_final/app/argus/argus/mixins.py", line 14, in dispatch
    return super(GENERIC_PERMISSION_MIXIN, self).dispatch(request, *args, **kwargs)
  File "/app/argus_final/venv/lib/python2.7/site-packages/django/views/generic/base.py", line 88, in dispatch
    return handler(request, *args, **kwargs)
  File "/app/argus_final/app/argus/fwdcontrol/views.py", line 46, in get
    context['content'] = result.get()
  File "/app/argus_final/venv/lib/python2.7/site-packages/celery/result.py", line 224, in get
    on_message=on_message,
  File "/app/argus_final/venv/lib/python2.7/site-packages/celery/backends/async.py", line 190, in wait_for_pending
    return result.maybe_throw(callback=callback, propagate=propagate)
  File "/app/argus_final/venv/lib/python2.7/site-packages/celery/result.py", line 329, in maybe_throw
    self.throw(value, self._to_remote_traceback(tb))
  File "/app/argus_final/venv/lib/python2.7/site-packages/celery/result.py", line 322, in throw
    self.on_ready.throw(*args, **kwargs)
  File "/app/argus_final/venv/lib/python2.7/site-packages/vine/promises.py", line 217, in throw
    reraise(type(exc), exc, tb)
  File "<string>", line 1, in reraise
IOError: (u'[', u'E', u'r', u'r', u'n', u'o', u' ', u'2', u']', u' ', u'N', u'o', u' ', u's', u'u', u'c', u'h', u' ', u'f', u'i', u'l', u'e', u' ', u'o', u'r', u' ', u'd', u'i', u'r', u'e', u'c', u't', u'o', u'r', u'y', u':', u' ', u'u', u"'", u'/', u's', u'r', u'v', u'/', u'o', u'f', u'f', u'i', u'c', u'e', u'-', u'h', u'a', u'p', u'r', u'o', u'x', u'y', u'-', u'g', u'd', u'c', u'/', u'c', u'o', u'n', u'f', u'.', u'd', u'/', u'0', u'1', u'-', u'g', u'l', u'o', u'b', u'a', u'l', u'.', u'c', u'f', u'g', u"'")
2020-08-10 10:06:47,261 ERROR - Internal Server Error: /fwdcontrol/office-nginx-ftz/
Traceback (most recent call last):
  File "/app/argus_final/venv/lib/python2.7/site-packages/django/core/handlers/exception.py", line 41, in inner
    response = get_response(request)
  File "/app/argus_final/venv/lib/python2.7/site-packages/django/core/handlers/base.py", line 187, in _get_response
    response = self.process_exception_by_middleware(e, request)
  File "/app/argus_final/venv/lib/python2.7/site-packages/django/core/handlers/base.py", line 185, in _get_response
    response = wrapped_callback(request, *callback_args, **callback_kwargs)
  File "/app/argus_final/venv/lib/python2.7/site-packages/django/contrib/auth/decorators.py", line 23, in _wrapped_view
    return view_func(request, *args, **kwargs)
  File "/app/argus_final/venv/lib/python2.7/site-packages/django/views/generic/base.py", line 68, in view
    return self.dispatch(request, *args, **kwargs)
  File "/app/argus_final/venv/lib/python2.7/site-packages/django/utils/decorators.py", line 67, in _wrapper
    return bound_func(*args, **kwargs)
  File "/app/argus_final/venv/lib/python2.7/site-packages/django/views/decorators/csrf.py", line 58, in wrapped_view
    return view_func(*args, **kwargs)
  File "/app/argus_final/venv/lib/python2.7/site-packages/django/utils/decorators.py", line 63, in bound_func
    return func.__get__(self, type(self))(*args2, **kwargs2)
  File "/app/argus_final/app/argus/argus/mixins.py", line 14, in dispatch
    return super(GENERIC_PERMISSION_MIXIN, self).dispatch(request, *args, **kwargs)
  File "/app/argus_final/venv/lib/python2.7/site-packages/django/views/generic/base.py", line 88, in dispatch
    return handler(request, *args, **kwargs)
  File "/app/argus_final/app/argus/fwdcontrol/views.py", line 67, in get
    context['FILES']=result.get()
  File "/app/argus_final/venv/lib/python2.7/site-packages/celery/result.py", line 224, in get
    on_message=on_message,
  File "/app/argus_final/venv/lib/python2.7/site-packages/celery/backends/async.py", line 190, in wait_for_pending
    return result.maybe_throw(callback=callback, propagate=propagate)
  File "/app/argus_final/venv/lib/python2.7/site-packages/celery/result.py", line 329, in maybe_throw
    self.throw(value, self._to_remote_traceback(tb))
  File "/app/argus_final/venv/lib/python2.7/site-packages/celery/result.py", line 322, in throw
    self.on_ready.throw(*args, **kwargs)
  File "/app/argus_final/venv/lib/python2.7/site-packages/vine/promises.py", line 217, in throw
    reraise(type(exc), exc, tb)
  File "<string>", line 1, in reraise
OSError: (u'[', u'E', u'r', u'r', u'n', u'o', u' ', u'2', u']', u' ', u'N', u'o', u' ', u's', u'u', u'c', u'h', u' ', u'f', u'i', u'l', u'e', u' ', u'o', u'r', u' ', u'd', u'i', u'r', u'e', u'c', u't', u'o', u'r', u'y', u':', u' ', u'u', u"'", u'/', u's', u'r', u'v', u'/', u'o', u'f', u'f', u'i', u'c', u'e', u'-', u'n', u'g', u'i', u'n', u'x', u'-', u'f', u't', u'z', u'/', u'c', u'o', u'n', u'f', u'.', u'd', u'/', u"'")
