2020-07-24 14:06:30,609 DEBUG - (carl.dasig) - Successfully loaded and updated table
2020-07-24 14:06:34,845 ERROR - Internal Server Error: /monitoring/
Traceback (most recent call last):
  File "/app/argus_final/venv/lib/python2.7/site-packages/django/core/handlers/exception.py", line 41, in inner
    response = get_response(request)
  File "/app/argus_final/venv/lib/python2.7/site-packages/django/core/handlers/base.py", line 187, in _get_response
    response = self.process_exception_by_middleware(e, request)
  File "/app/argus_final/venv/lib/python2.7/site-packages/django/core/handlers/base.py", line 185, in _get_response
    response = wrapped_callback(request, *callback_args, **callback_kwargs)
  File "/app/argus_final/venv/lib/python2.7/site-packages/django/contrib/auth/decorators.py", line 23, in _wrapped_view
    return view_func(request, *args, **kwargs)
  File "/app/argus_final/venv/lib/python2.7/site-packages/django/views/generic/base.py", line 68, in view
    return self.dispatch(request, *args, **kwargs)
  File "/app/argus_final/app/argus/argus/mixins.py", line 14, in dispatch
    return super(GENERIC_PERMISSION_MIXIN, self).dispatch(request, *args, **kwargs)
  File "/app/argus_final/venv/lib/python2.7/site-packages/django/views/generic/base.py", line 88, in dispatch
    return handler(request, *args, **kwargs)
  File "/app/argus_final/app/argus/monitoring/views.py", line 30, in get
    context['data'] = ZABBIX.getAllTriggeredTriggers()
  File "/app/argus_final/app/argus/global_objects/zabbix_api.py", line 80, in getAllTriggeredTriggers
    triggers = self.zapi.do_request('trigger.get',req)
  File "/app/argus_final/venv/lib/python2.7/site-packages/pyzabbix/api.py", line 251, in do_request
    res = urlopen(req)
  File "/app/argus_final/venv/lib/python2.7/site-packages/pyzabbix/api.py", line 117, in inner
    res = func(req)
  File "/app/argus_final/venv/lib/python2.7/site-packages/pyzabbix/api.py", line 126, in urlopen
    return urllib2.urlopen(*args, **kwargs)
  File "/usr/lib64/python2.7/urllib2.py", line 154, in urlopen
    return opener.open(url, data, timeout)
  File "/usr/lib64/python2.7/urllib2.py", line 431, in open
    response = self._open(req, data)
  File "/usr/lib64/python2.7/urllib2.py", line 449, in _open
    '_open', req)
  File "/usr/lib64/python2.7/urllib2.py", line 409, in _call_chain
    result = func(*args)
  File "/usr/lib64/python2.7/urllib2.py", line 1244, in http_open
    return self.do_open(httplib.HTTPConnection, req)
  File "/usr/lib64/python2.7/urllib2.py", line 1214, in do_open
    raise URLError(err)
URLError: <urlopen error [Errno 110] Connection timed out>
2020-07-24 14:06:37,245 ERROR - Internal Server Error: /monitoring/
Traceback (most recent call last):
  File "/app/argus_final/venv/lib/python2.7/site-packages/django/core/handlers/exception.py", line 41, in inner
    response = get_response(request)
  File "/app/argus_final/venv/lib/python2.7/site-packages/django/core/handlers/base.py", line 187, in _get_response
    response = self.process_exception_by_middleware(e, request)
  File "/app/argus_final/venv/lib/python2.7/site-packages/django/core/handlers/base.py", line 185, in _get_response
    response = wrapped_callback(request, *callback_args, **callback_kwargs)
  File "/app/argus_final/venv/lib/python2.7/site-packages/django/contrib/auth/decorators.py", line 23, in _wrapped_view
    return view_func(request, *args, **kwargs)
  File "/app/argus_final/venv/lib/python2.7/site-packages/django/views/generic/base.py", line 68, in view
    return self.dispatch(request, *args, **kwargs)
  File "/app/argus_final/app/argus/argus/mixins.py", line 14, in dispatch
    return super(GENERIC_PERMISSION_MIXIN, self).dispatch(request, *args, **kwargs)
  File "/app/argus_final/venv/lib/python2.7/site-packages/django/views/generic/base.py", line 88, in dispatch
    return handler(request, *args, **kwargs)
  File "/app/argus_final/app/argus/monitoring/views.py", line 43, in get
    context['data'] = ZABBIX.getScreenGraphs('Network')
  File "/app/argus_final/app/argus/global_objects/zabbix_api.py", line 223, in getScreenGraphs
    'name':screenName
  File "/app/argus_final/venv/lib/python2.7/site-packages/pyzabbix/api.py", line 251, in do_request
    res = urlopen(req)
  File "/app/argus_final/venv/lib/python2.7/site-packages/pyzabbix/api.py", line 117, in inner
    res = func(req)
  File "/app/argus_final/venv/lib/python2.7/site-packages/pyzabbix/api.py", line 126, in urlopen
    return urllib2.urlopen(*args, **kwargs)
  File "/usr/lib64/python2.7/urllib2.py", line 154, in urlopen
    return opener.open(url, data, timeout)
  File "/usr/lib64/python2.7/urllib2.py", line 431, in open
    response = self._open(req, data)
  File "/usr/lib64/python2.7/urllib2.py", line 449, in _open
    '_open', req)
  File "/usr/lib64/python2.7/urllib2.py", line 409, in _call_chain
    result = func(*args)
  File "/usr/lib64/python2.7/urllib2.py", line 1244, in http_open
    return self.do_open(httplib.HTTPConnection, req)
  File "/usr/lib64/python2.7/urllib2.py", line 1214, in do_open
    raise URLError(err)
URLError: <urlopen error [Errno 110] Connection timed out>
2020-07-24 14:06:49,613 ERROR - Internal Server Error: /monitoring/
Traceback (most recent call last):
  File "/app/argus_final/venv/lib/python2.7/site-packages/django/core/handlers/exception.py", line 41, in inner
    response = get_response(request)
  File "/app/argus_final/venv/lib/python2.7/site-packages/django/core/handlers/base.py", line 187, in _get_response
    response = self.process_exception_by_middleware(e, request)
  File "/app/argus_final/venv/lib/python2.7/site-packages/django/core/handlers/base.py", line 185, in _get_response
    response = wrapped_callback(request, *callback_args, **callback_kwargs)
  File "/app/argus_final/venv/lib/python2.7/site-packages/django/contrib/auth/decorators.py", line 23, in _wrapped_view
    return view_func(request, *args, **kwargs)
  File "/app/argus_final/venv/lib/python2.7/site-packages/django/views/generic/base.py", line 68, in view
    return self.dispatch(request, *args, **kwargs)
  File "/app/argus_final/app/argus/argus/mixins.py", line 14, in dispatch
    return super(GENERIC_PERMISSION_MIXIN, self).dispatch(request, *args, **kwargs)
  File "/app/argus_final/venv/lib/python2.7/site-packages/django/views/generic/base.py", line 88, in dispatch
    return handler(request, *args, **kwargs)
  File "/app/argus_final/app/argus/monitoring/views.py", line 40, in get
    context['data'] = ZABBIX.getAllEvents(daysfromnow=period)[-limit:]
  File "/app/argus_final/app/argus/global_objects/zabbix_api.py", line 121, in getAllEvents
    events = self.zapi.do_request('event.get',req)
  File "/app/argus_final/venv/lib/python2.7/site-packages/pyzabbix/api.py", line 251, in do_request
    res = urlopen(req)
  File "/app/argus_final/venv/lib/python2.7/site-packages/pyzabbix/api.py", line 117, in inner
    res = func(req)
  File "/app/argus_final/venv/lib/python2.7/site-packages/pyzabbix/api.py", line 126, in urlopen
    return urllib2.urlopen(*args, **kwargs)
  File "/usr/lib64/python2.7/urllib2.py", line 154, in urlopen
    return opener.open(url, data, timeout)
  File "/usr/lib64/python2.7/urllib2.py", line 431, in open
    response = self._open(req, data)
  File "/usr/lib64/python2.7/urllib2.py", line 449, in _open
    '_open', req)
  File "/usr/lib64/python2.7/urllib2.py", line 409, in _call_chain
    result = func(*args)
  File "/usr/lib64/python2.7/urllib2.py", line 1244, in http_open
    return self.do_open(httplib.HTTPConnection, req)
  File "/usr/lib64/python2.7/urllib2.py", line 1214, in do_open
    raise URLError(err)
URLError: <urlopen error [Errno 110] Connection timed out>
2020-07-24 14:06:55,353 ERROR - Internal Server Error: /monitoring/
Traceback (most recent call last):
  File "/app/argus_final/venv/lib/python2.7/site-packages/django/core/handlers/exception.py", line 41, in inner
    response = get_response(request)
  File "/app/argus_final/venv/lib/python2.7/site-packages/django/core/handlers/base.py", line 187, in _get_response
    response = self.process_exception_by_middleware(e, request)
  File "/app/argus_final/venv/lib/python2.7/site-packages/django/core/handlers/base.py", line 185, in _get_response
    response = wrapped_callback(request, *callback_args, **callback_kwargs)
  File "/app/argus_final/venv/lib/python2.7/site-packages/django/contrib/auth/decorators.py", line 23, in _wrapped_view
    return view_func(request, *args, **kwargs)
  File "/app/argus_final/venv/lib/python2.7/site-packages/django/views/generic/base.py", line 68, in view
    return self.dispatch(request, *args, **kwargs)
  File "/app/argus_final/app/argus/argus/mixins.py", line 14, in dispatch
    return super(GENERIC_PERMISSION_MIXIN, self).dispatch(request, *args, **kwargs)
  File "/app/argus_final/venv/lib/python2.7/site-packages/django/views/generic/base.py", line 88, in dispatch
    return handler(request, *args, **kwargs)
  File "/app/argus_final/app/argus/monitoring/views.py", line 30, in get
    context['data'] = ZABBIX.getAllTriggeredTriggers()
  File "/app/argus_final/app/argus/global_objects/zabbix_api.py", line 80, in getAllTriggeredTriggers
    triggers = self.zapi.do_request('trigger.get',req)
  File "/app/argus_final/venv/lib/python2.7/site-packages/pyzabbix/api.py", line 251, in do_request
    res = urlopen(req)
  File "/app/argus_final/venv/lib/python2.7/site-packages/pyzabbix/api.py", line 117, in inner
    res = func(req)
  File "/app/argus_final/venv/lib/python2.7/site-packages/pyzabbix/api.py", line 126, in urlopen
    return urllib2.urlopen(*args, **kwargs)
  File "/usr/lib64/python2.7/urllib2.py", line 154, in urlopen
    return opener.open(url, data, timeout)
  File "/usr/lib64/python2.7/urllib2.py", line 431, in open
    response = self._open(req, data)
  File "/usr/lib64/python2.7/urllib2.py", line 449, in _open
    '_open', req)
  File "/usr/lib64/python2.7/urllib2.py", line 409, in _call_chain
    result = func(*args)
  File "/usr/lib64/python2.7/urllib2.py", line 1244, in http_open
    return self.do_open(httplib.HTTPConnection, req)
  File "/usr/lib64/python2.7/urllib2.py", line 1214, in do_open
    raise URLError(err)
URLError: <urlopen error [Errno 110] Connection timed out>
2020-07-24 14:06:58,421 ERROR - Internal Server Error: /monitoring/
Traceback (most recent call last):
  File "/app/argus_final/venv/lib/python2.7/site-packages/django/core/handlers/exception.py", line 41, in inner
    response = get_response(request)
  File "/app/argus_final/venv/lib/python2.7/site-packages/django/core/handlers/base.py", line 187, in _get_response
    response = self.process_exception_by_middleware(e, request)
  File "/app/argus_final/venv/lib/python2.7/site-packages/django/core/handlers/base.py", line 185, in _get_response
    response = wrapped_callback(request, *callback_args, **callback_kwargs)
  File "/app/argus_final/venv/lib/python2.7/site-packages/django/contrib/auth/decorators.py", line 23, in _wrapped_view
    return view_func(request, *args, **kwargs)
  File "/app/argus_final/venv/lib/python2.7/site-packages/django/views/generic/base.py", line 68, in view
    return self.dispatch(request, *args, **kwargs)
  File "/app/argus_final/app/argus/argus/mixins.py", line 14, in dispatch
    return super(GENERIC_PERMISSION_MIXIN, self).dispatch(request, *args, **kwargs)
  File "/app/argus_final/venv/lib/python2.7/site-packages/django/views/generic/base.py", line 88, in dispatch
    return handler(request, *args, **kwargs)
  File "/app/argus_final/app/argus/monitoring/views.py", line 40, in get
    context['data'] = ZABBIX.getAllEvents(daysfromnow=period)[-limit:]
  File "/app/argus_final/app/argus/global_objects/zabbix_api.py", line 121, in getAllEvents
    events = self.zapi.do_request('event.get',req)
  File "/app/argus_final/venv/lib/python2.7/site-packages/pyzabbix/api.py", line 251, in do_request
    res = urlopen(req)
  File "/app/argus_final/venv/lib/python2.7/site-packages/pyzabbix/api.py", line 117, in inner
    res = func(req)
  File "/app/argus_final/venv/lib/python2.7/site-packages/pyzabbix/api.py", line 126, in urlopen
    return urllib2.urlopen(*args, **kwargs)
  File "/usr/lib64/python2.7/urllib2.py", line 154, in urlopen
    return opener.open(url, data, timeout)
  File "/usr/lib64/python2.7/urllib2.py", line 431, in open
    response = self._open(req, data)
  File "/usr/lib64/python2.7/urllib2.py", line 449, in _open
    '_open', req)
  File "/usr/lib64/python2.7/urllib2.py", line 409, in _call_chain
    result = func(*args)
  File "/usr/lib64/python2.7/urllib2.py", line 1244, in http_open
    return self.do_open(httplib.HTTPConnection, req)
  File "/usr/lib64/python2.7/urllib2.py", line 1214, in do_open
    raise URLError(err)
URLError: <urlopen error [Errno 110] Connection timed out>
2020-07-24 14:07:23,397 ERROR - Internal Server Error: /monitoring/
Traceback (most recent call last):
  File "/app/argus_final/venv/lib/python2.7/site-packages/django/core/handlers/exception.py", line 41, in inner
    response = get_response(request)
  File "/app/argus_final/venv/lib/python2.7/site-packages/django/core/handlers/base.py", line 187, in _get_response
    response = self.process_exception_by_middleware(e, request)
  File "/app/argus_final/venv/lib/python2.7/site-packages/django/core/handlers/base.py", line 185, in _get_response
    response = wrapped_callback(request, *callback_args, **callback_kwargs)
  File "/app/argus_final/venv/lib/python2.7/site-packages/django/contrib/auth/decorators.py", line 23, in _wrapped_view
    return view_func(request, *args, **kwargs)
  File "/app/argus_final/venv/lib/python2.7/site-packages/django/views/generic/base.py", line 68, in view
    return self.dispatch(request, *args, **kwargs)
  File "/app/argus_final/app/argus/argus/mixins.py", line 14, in dispatch
    return super(GENERIC_PERMISSION_MIXIN, self).dispatch(request, *args, **kwargs)
  File "/app/argus_final/venv/lib/python2.7/site-packages/django/views/generic/base.py", line 88, in dispatch
    return handler(request, *args, **kwargs)
  File "/app/argus_final/app/argus/monitoring/views.py", line 30, in get
    context['data'] = ZABBIX.getAllTriggeredTriggers()
  File "/app/argus_final/app/argus/global_objects/zabbix_api.py", line 80, in getAllTriggeredTriggers
    triggers = self.zapi.do_request('trigger.get',req)
  File "/app/argus_final/venv/lib/python2.7/site-packages/pyzabbix/api.py", line 251, in do_request
    res = urlopen(req)
  File "/app/argus_final/venv/lib/python2.7/site-packages/pyzabbix/api.py", line 117, in inner
    res = func(req)
  File "/app/argus_final/venv/lib/python2.7/site-packages/pyzabbix/api.py", line 126, in urlopen
    return urllib2.urlopen(*args, **kwargs)
  File "/usr/lib64/python2.7/urllib2.py", line 154, in urlopen
    return opener.open(url, data, timeout)
  File "/usr/lib64/python2.7/urllib2.py", line 431, in open
    response = self._open(req, data)
  File "/usr/lib64/python2.7/urllib2.py", line 449, in _open
    '_open', req)
  File "/usr/lib64/python2.7/urllib2.py", line 409, in _call_chain
    result = func(*args)
  File "/usr/lib64/python2.7/urllib2.py", line 1244, in http_open
    return self.do_open(httplib.HTTPConnection, req)
  File "/usr/lib64/python2.7/urllib2.py", line 1214, in do_open
    raise URLError(err)
URLError: <urlopen error [Errno 110] Connection timed out>
2020-07-24 14:07:26,697 ERROR - Internal Server Error: /monitoring/
Traceback (most recent call last):
  File "/app/argus_final/venv/lib/python2.7/site-packages/django/core/handlers/exception.py", line 41, in inner
    response = get_response(request)
  File "/app/argus_final/venv/lib/python2.7/site-packages/django/core/handlers/base.py", line 187, in _get_response
    response = self.process_exception_by_middleware(e, request)
  File "/app/argus_final/venv/lib/python2.7/site-packages/django/core/handlers/base.py", line 185, in _get_response
    response = wrapped_callback(request, *callback_args, **callback_kwargs)
  File "/app/argus_final/venv/lib/python2.7/site-packages/django/contrib/auth/decorators.py", line 23, in _wrapped_view
    return view_func(request, *args, **kwargs)
  File "/app/argus_final/venv/lib/python2.7/site-packages/django/views/generic/base.py", line 68, in view
    return self.dispatch(request, *args, **kwargs)
  File "/app/argus_final/app/argus/argus/mixins.py", line 14, in dispatch
    return super(GENERIC_PERMISSION_MIXIN, self).dispatch(request, *args, **kwargs)
  File "/app/argus_final/venv/lib/python2.7/site-packages/django/views/generic/base.py", line 88, in dispatch
    return handler(request, *args, **kwargs)
  File "/app/argus_final/app/argus/monitoring/views.py", line 40, in get
    context['data'] = ZABBIX.getAllEvents(daysfromnow=period)[-limit:]
  File "/app/argus_final/app/argus/global_objects/zabbix_api.py", line 121, in getAllEvents
    events = self.zapi.do_request('event.get',req)
  File "/app/argus_final/venv/lib/python2.7/site-packages/pyzabbix/api.py", line 251, in do_request
    res = urlopen(req)
  File "/app/argus_final/venv/lib/python2.7/site-packages/pyzabbix/api.py", line 117, in inner
    res = func(req)
  File "/app/argus_final/venv/lib/python2.7/site-packages/pyzabbix/api.py", line 126, in urlopen
    return urllib2.urlopen(*args, **kwargs)
  File "/usr/lib64/python2.7/urllib2.py", line 154, in urlopen
    return opener.open(url, data, timeout)
  File "/usr/lib64/python2.7/urllib2.py", line 431, in open
    response = self._open(req, data)
  File "/usr/lib64/python2.7/urllib2.py", line 449, in _open
    '_open', req)
  File "/usr/lib64/python2.7/urllib2.py", line 409, in _call_chain
    result = func(*args)
  File "/usr/lib64/python2.7/urllib2.py", line 1244, in http_open
    return self.do_open(httplib.HTTPConnection, req)
  File "/usr/lib64/python2.7/urllib2.py", line 1214, in do_open
    raise URLError(err)
URLError: <urlopen error [Errno 110] Connection timed out>
2020-07-24 14:07:32,353 ERROR - Internal Server Error: /monitoring/
Traceback (most recent call last):
  File "/app/argus_final/venv/lib/python2.7/site-packages/django/core/handlers/exception.py", line 41, in inner
    response = get_response(request)
  File "/app/argus_final/venv/lib/python2.7/site-packages/django/core/handlers/base.py", line 187, in _get_response
    response = self.process_exception_by_middleware(e, request)
  File "/app/argus_final/venv/lib/python2.7/site-packages/django/core/handlers/base.py", line 185, in _get_response
    response = wrapped_callback(request, *callback_args, **callback_kwargs)
  File "/app/argus_final/venv/lib/python2.7/site-packages/django/contrib/auth/decorators.py", line 23, in _wrapped_view
    return view_func(request, *args, **kwargs)
  File "/app/argus_final/venv/lib/python2.7/site-packages/django/views/generic/base.py", line 68, in view
    return self.dispatch(request, *args, **kwargs)
  File "/app/argus_final/app/argus/argus/mixins.py", line 14, in dispatch
    return super(GENERIC_PERMISSION_MIXIN, self).dispatch(request, *args, **kwargs)
  File "/app/argus_final/venv/lib/python2.7/site-packages/django/views/generic/base.py", line 88, in dispatch
    return handler(request, *args, **kwargs)
  File "/app/argus_final/app/argus/monitoring/views.py", line 30, in get
    context['data'] = ZABBIX.getAllTriggeredTriggers()
  File "/app/argus_final/app/argus/global_objects/zabbix_api.py", line 80, in getAllTriggeredTriggers
    triggers = self.zapi.do_request('trigger.get',req)
  File "/app/argus_final/venv/lib/python2.7/site-packages/pyzabbix/api.py", line 251, in do_request
    res = urlopen(req)
  File "/app/argus_final/venv/lib/python2.7/site-packages/pyzabbix/api.py", line 117, in inner
    res = func(req)
  File "/app/argus_final/venv/lib/python2.7/site-packages/pyzabbix/api.py", line 126, in urlopen
    return urllib2.urlopen(*args, **kwargs)
  File "/usr/lib64/python2.7/urllib2.py", line 154, in urlopen
    return opener.open(url, data, timeout)
  File "/usr/lib64/python2.7/urllib2.py", line 431, in open
    response = self._open(req, data)
  File "/usr/lib64/python2.7/urllib2.py", line 449, in _open
    '_open', req)
  File "/usr/lib64/python2.7/urllib2.py", line 409, in _call_chain
    result = func(*args)
  File "/usr/lib64/python2.7/urllib2.py", line 1244, in http_open
    return self.do_open(httplib.HTTPConnection, req)
  File "/usr/lib64/python2.7/urllib2.py", line 1214, in do_open
    raise URLError(err)
URLError: <urlopen error [Errno 110] Connection timed out>
2020-07-24 14:07:49,305 ERROR - Internal Server Error: /monitoring/
Traceback (most recent call last):
  File "/app/argus_final/venv/lib/python2.7/site-packages/django/core/handlers/exception.py", line 41, in inner
    response = get_response(request)
  File "/app/argus_final/venv/lib/python2.7/site-packages/django/core/handlers/base.py", line 187, in _get_response
    response = self.process_exception_by_middleware(e, request)
  File "/app/argus_final/venv/lib/python2.7/site-packages/django/core/handlers/base.py", line 185, in _get_response
    response = wrapped_callback(request, *callback_args, **callback_kwargs)
  File "/app/argus_final/venv/lib/python2.7/site-packages/django/contrib/auth/decorators.py", line 23, in _wrapped_view
    return view_func(request, *args, **kwargs)
  File "/app/argus_final/venv/lib/python2.7/site-packages/django/views/generic/base.py", line 68, in view
    return self.dispatch(request, *args, **kwargs)
  File "/app/argus_final/app/argus/argus/mixins.py", line 14, in dispatch
    return super(GENERIC_PERMISSION_MIXIN, self).dispatch(request, *args, **kwargs)
  File "/app/argus_final/venv/lib/python2.7/site-packages/django/views/generic/base.py", line 88, in dispatch
    return handler(request, *args, **kwargs)
  File "/app/argus_final/app/argus/monitoring/views.py", line 30, in get
    context['data'] = ZABBIX.getAllTriggeredTriggers()
  File "/app/argus_final/app/argus/global_objects/zabbix_api.py", line 80, in getAllTriggeredTriggers
    triggers = self.zapi.do_request('trigger.get',req)
  File "/app/argus_final/venv/lib/python2.7/site-packages/pyzabbix/api.py", line 251, in do_request
    res = urlopen(req)
  File "/app/argus_final/venv/lib/python2.7/site-packages/pyzabbix/api.py", line 117, in inner
    res = func(req)
  File "/app/argus_final/venv/lib/python2.7/site-packages/pyzabbix/api.py", line 126, in urlopen
    return urllib2.urlopen(*args, **kwargs)
  File "/usr/lib64/python2.7/urllib2.py", line 154, in urlopen
    return opener.open(url, data, timeout)
  File "/usr/lib64/python2.7/urllib2.py", line 431, in open
    response = self._open(req, data)
  File "/usr/lib64/python2.7/urllib2.py", line 449, in _open
    '_open', req)
  File "/usr/lib64/python2.7/urllib2.py", line 409, in _call_chain
    result = func(*args)
  File "/usr/lib64/python2.7/urllib2.py", line 1244, in http_open
    return self.do_open(httplib.HTTPConnection, req)
  File "/usr/lib64/python2.7/urllib2.py", line 1214, in do_open
    raise URLError(err)
URLError: <urlopen error [Errno 110] Connection timed out>
2020-07-24 14:07:52,373 ERROR - Internal Server Error: /monitoring/
Traceback (most recent call last):
  File "/app/argus_final/venv/lib/python2.7/site-packages/django/core/handlers/exception.py", line 41, in inner
    response = get_response(request)
  File "/app/argus_final/venv/lib/python2.7/site-packages/django/core/handlers/base.py", line 187, in _get_response
    response = self.process_exception_by_middleware(e, request)
  File "/app/argus_final/venv/lib/python2.7/site-packages/django/core/handlers/base.py", line 185, in _get_response
    response = wrapped_callback(request, *callback_args, **callback_kwargs)
  File "/app/argus_final/venv/lib/python2.7/site-packages/django/contrib/auth/decorators.py", line 23, in _wrapped_view
    return view_func(request, *args, **kwargs)
  File "/app/argus_final/venv/lib/python2.7/site-packages/django/views/generic/base.py", line 68, in view
    return self.dispatch(request, *args, **kwargs)
  File "/app/argus_final/app/argus/argus/mixins.py", line 14, in dispatch
    return super(GENERIC_PERMISSION_MIXIN, self).dispatch(request, *args, **kwargs)
  File "/app/argus_final/venv/lib/python2.7/site-packages/django/views/generic/base.py", line 88, in dispatch
    return handler(request, *args, **kwargs)
  File "/app/argus_final/app/argus/monitoring/views.py", line 40, in get
    context['data'] = ZABBIX.getAllEvents(daysfromnow=period)[-limit:]
  File "/app/argus_final/app/argus/global_objects/zabbix_api.py", line 121, in getAllEvents
    events = self.zapi.do_request('event.get',req)
  File "/app/argus_final/venv/lib/python2.7/site-packages/pyzabbix/api.py", line 251, in do_request
    res = urlopen(req)
  File "/app/argus_final/venv/lib/python2.7/site-packages/pyzabbix/api.py", line 117, in inner
    res = func(req)
  File "/app/argus_final/venv/lib/python2.7/site-packages/pyzabbix/api.py", line 126, in urlopen
    return urllib2.urlopen(*args, **kwargs)
  File "/usr/lib64/python2.7/urllib2.py", line 154, in urlopen
    return opener.open(url, data, timeout)
  File "/usr/lib64/python2.7/urllib2.py", line 431, in open
    response = self._open(req, data)
  File "/usr/lib64/python2.7/urllib2.py", line 449, in _open
    '_open', req)
  File "/usr/lib64/python2.7/urllib2.py", line 409, in _call_chain
    result = func(*args)
  File "/usr/lib64/python2.7/urllib2.py", line 1244, in http_open
    return self.do_open(httplib.HTTPConnection, req)
  File "/usr/lib64/python2.7/urllib2.py", line 1214, in do_open
    raise URLError(err)
URLError: <urlopen error [Errno 110] Connection timed out>
2020-07-24 14:07:59,873 ERROR - Internal Server Error: /monitoring/
Traceback (most recent call last):
  File "/app/argus_final/venv/lib/python2.7/site-packages/django/core/handlers/exception.py", line 41, in inner
    response = get_response(request)
  File "/app/argus_final/venv/lib/python2.7/site-packages/django/core/handlers/base.py", line 187, in _get_response
    response = self.process_exception_by_middleware(e, request)
  File "/app/argus_final/venv/lib/python2.7/site-packages/django/core/handlers/base.py", line 185, in _get_response
    response = wrapped_callback(request, *callback_args, **callback_kwargs)
  File "/app/argus_final/venv/lib/python2.7/site-packages/django/contrib/auth/decorators.py", line 23, in _wrapped_view
    return view_func(request, *args, **kwargs)
  File "/app/argus_final/venv/lib/python2.7/site-packages/django/views/generic/base.py", line 68, in view
    return self.dispatch(request, *args, **kwargs)
  File "/app/argus_final/app/argus/argus/mixins.py", line 14, in dispatch
    return super(GENERIC_PERMISSION_MIXIN, self).dispatch(request, *args, **kwargs)
  File "/app/argus_final/venv/lib/python2.7/site-packages/django/views/generic/base.py", line 88, in dispatch
    return handler(request, *args, **kwargs)
  File "/app/argus_final/app/argus/monitoring/views.py", line 30, in get
    context['data'] = ZABBIX.getAllTriggeredTriggers()
  File "/app/argus_final/app/argus/global_objects/zabbix_api.py", line 80, in getAllTriggeredTriggers
    triggers = self.zapi.do_request('trigger.get',req)
  File "/app/argus_final/venv/lib/python2.7/site-packages/pyzabbix/api.py", line 251, in do_request
    res = urlopen(req)
  File "/app/argus_final/venv/lib/python2.7/site-packages/pyzabbix/api.py", line 117, in inner
    res = func(req)
  File "/app/argus_final/venv/lib/python2.7/site-packages/pyzabbix/api.py", line 126, in urlopen
    return urllib2.urlopen(*args, **kwargs)
  File "/usr/lib64/python2.7/urllib2.py", line 154, in urlopen
    return opener.open(url, data, timeout)
  File "/usr/lib64/python2.7/urllib2.py", line 431, in open
    response = self._open(req, data)
  File "/usr/lib64/python2.7/urllib2.py", line 449, in _open
    '_open', req)
  File "/usr/lib64/python2.7/urllib2.py", line 409, in _call_chain
    result = func(*args)
  File "/usr/lib64/python2.7/urllib2.py", line 1244, in http_open
    return self.do_open(httplib.HTTPConnection, req)
  File "/usr/lib64/python2.7/urllib2.py", line 1214, in do_open
    raise URLError(err)
URLError: <urlopen error [Errno 110] Connection timed out>
2020-07-24 14:08:09,357 ERROR - Internal Server Error: /monitoring/
Traceback (most recent call last):
  File "/app/argus_final/venv/lib/python2.7/site-packages/django/core/handlers/exception.py", line 41, in inner
    response = get_response(request)
  File "/app/argus_final/venv/lib/python2.7/site-packages/django/core/handlers/base.py", line 187, in _get_response
    response = self.process_exception_by_middleware(e, request)
  File "/app/argus_final/venv/lib/python2.7/site-packages/django/core/handlers/base.py", line 185, in _get_response
    response = wrapped_callback(request, *callback_args, **callback_kwargs)
  File "/app/argus_final/venv/lib/python2.7/site-packages/django/contrib/auth/decorators.py", line 23, in _wrapped_view
    return view_func(request, *args, **kwargs)
  File "/app/argus_final/venv/lib/python2.7/site-packages/django/views/generic/base.py", line 68, in view
    return self.dispatch(request, *args, **kwargs)
  File "/app/argus_final/app/argus/argus/mixins.py", line 14, in dispatch
    return super(GENERIC_PERMISSION_MIXIN, self).dispatch(request, *args, **kwargs)
  File "/app/argus_final/venv/lib/python2.7/site-packages/django/views/generic/base.py", line 88, in dispatch
    return handler(request, *args, **kwargs)
  File "/app/argus_final/app/argus/monitoring/views.py", line 30, in get
    context['data'] = ZABBIX.getAllTriggeredTriggers()
  File "/app/argus_final/app/argus/global_objects/zabbix_api.py", line 80, in getAllTriggeredTriggers
    triggers = self.zapi.do_request('trigger.get',req)
  File "/app/argus_final/venv/lib/python2.7/site-packages/pyzabbix/api.py", line 251, in do_request
    res = urlopen(req)
  File "/app/argus_final/venv/lib/python2.7/site-packages/pyzabbix/api.py", line 117, in inner
    res = func(req)
  File "/app/argus_final/venv/lib/python2.7/site-packages/pyzabbix/api.py", line 126, in urlopen
    return urllib2.urlopen(*args, **kwargs)
  File "/usr/lib64/python2.7/urllib2.py", line 154, in urlopen
    return opener.open(url, data, timeout)
  File "/usr/lib64/python2.7/urllib2.py", line 431, in open
    response = self._open(req, data)
  File "/usr/lib64/python2.7/urllib2.py", line 449, in _open
    '_open', req)
  File "/usr/lib64/python2.7/urllib2.py", line 409, in _call_chain
    result = func(*args)
  File "/usr/lib64/python2.7/urllib2.py", line 1244, in http_open
    return self.do_open(httplib.HTTPConnection, req)
  File "/usr/lib64/python2.7/urllib2.py", line 1214, in do_open
    raise URLError(err)
URLError: <urlopen error [Errno 110] Connection timed out>
2020-07-24 14:08:12,425 ERROR - Internal Server Error: /monitoring/
Traceback (most recent call last):
  File "/app/argus_final/venv/lib/python2.7/site-packages/django/core/handlers/exception.py", line 41, in inner
    response = get_response(request)
  File "/app/argus_final/venv/lib/python2.7/site-packages/django/core/handlers/base.py", line 187, in _get_response
    response = self.process_exception_by_middleware(e, request)
  File "/app/argus_final/venv/lib/python2.7/site-packages/django/core/handlers/base.py", line 185, in _get_response
    response = wrapped_callback(request, *callback_args, **callback_kwargs)
  File "/app/argus_final/venv/lib/python2.7/site-packages/django/contrib/auth/decorators.py", line 23, in _wrapped_view
    return view_func(request, *args, **kwargs)
  File "/app/argus_final/venv/lib/python2.7/site-packages/django/views/generic/base.py", line 68, in view
    return self.dispatch(request, *args, **kwargs)
  File "/app/argus_final/app/argus/argus/mixins.py", line 14, in dispatch
    return super(GENERIC_PERMISSION_MIXIN, self).dispatch(request, *args, **kwargs)
  File "/app/argus_final/venv/lib/python2.7/site-packages/django/views/generic/base.py", line 88, in dispatch
    return handler(request, *args, **kwargs)
  File "/app/argus_final/app/argus/monitoring/views.py", line 40, in get
    context['data'] = ZABBIX.getAllEvents(daysfromnow=period)[-limit:]
  File "/app/argus_final/app/argus/global_objects/zabbix_api.py", line 121, in getAllEvents
    events = self.zapi.do_request('event.get',req)
  File "/app/argus_final/venv/lib/python2.7/site-packages/pyzabbix/api.py", line 251, in do_request
    res = urlopen(req)
  File "/app/argus_final/venv/lib/python2.7/site-packages/pyzabbix/api.py", line 117, in inner
    res = func(req)
  File "/app/argus_final/venv/lib/python2.7/site-packages/pyzabbix/api.py", line 126, in urlopen
    return urllib2.urlopen(*args, **kwargs)
  File "/usr/lib64/python2.7/urllib2.py", line 154, in urlopen
    return opener.open(url, data, timeout)
  File "/usr/lib64/python2.7/urllib2.py", line 431, in open
    response = self._open(req, data)
  File "/usr/lib64/python2.7/urllib2.py", line 449, in _open
    '_open', req)
  File "/usr/lib64/python2.7/urllib2.py", line 409, in _call_chain
    result = func(*args)
  File "/usr/lib64/python2.7/urllib2.py", line 1244, in http_open
    return self.do_open(httplib.HTTPConnection, req)
  File "/usr/lib64/python2.7/urllib2.py", line 1214, in do_open
    raise URLError(err)
URLError: <urlopen error [Errno 110] Connection timed out>
2020-07-24 14:08:14,425 ERROR - Internal Server Error: /monitoring/
Traceback (most recent call last):
  File "/app/argus_final/venv/lib/python2.7/site-packages/django/core/handlers/exception.py", line 41, in inner
    response = get_response(request)
  File "/app/argus_final/venv/lib/python2.7/site-packages/django/core/handlers/base.py", line 187, in _get_response
    response = self.process_exception_by_middleware(e, request)
  File "/app/argus_final/venv/lib/python2.7/site-packages/django/core/handlers/base.py", line 185, in _get_response
    response = wrapped_callback(request, *callback_args, **callback_kwargs)
  File "/app/argus_final/venv/lib/python2.7/site-packages/django/contrib/auth/decorators.py", line 23, in _wrapped_view
    return view_func(request, *args, **kwargs)
  File "/app/argus_final/venv/lib/python2.7/site-packages/django/views/generic/base.py", line 68, in view
    return self.dispatch(request, *args, **kwargs)
  File "/app/argus_final/app/argus/argus/mixins.py", line 14, in dispatch
    return super(GENERIC_PERMISSION_MIXIN, self).dispatch(request, *args, **kwargs)
  File "/app/argus_final/venv/lib/python2.7/site-packages/django/views/generic/base.py", line 88, in dispatch
    return handler(request, *args, **kwargs)
  File "/app/argus_final/app/argus/monitoring/views.py", line 30, in get
    context['data'] = ZABBIX.getAllTriggeredTriggers()
  File "/app/argus_final/app/argus/global_objects/zabbix_api.py", line 80, in getAllTriggeredTriggers
    triggers = self.zapi.do_request('trigger.get',req)
  File "/app/argus_final/venv/lib/python2.7/site-packages/pyzabbix/api.py", line 251, in do_request
    res = urlopen(req)
  File "/app/argus_final/venv/lib/python2.7/site-packages/pyzabbix/api.py", line 117, in inner
    res = func(req)
  File "/app/argus_final/venv/lib/python2.7/site-packages/pyzabbix/api.py", line 126, in urlopen
    return urllib2.urlopen(*args, **kwargs)
  File "/usr/lib64/python2.7/urllib2.py", line 154, in urlopen
    return opener.open(url, data, timeout)
  File "/usr/lib64/python2.7/urllib2.py", line 431, in open
    response = self._open(req, data)
  File "/usr/lib64/python2.7/urllib2.py", line 449, in _open
    '_open', req)
  File "/usr/lib64/python2.7/urllib2.py", line 409, in _call_chain
    result = func(*args)
  File "/usr/lib64/python2.7/urllib2.py", line 1244, in http_open
    return self.do_open(httplib.HTTPConnection, req)
  File "/usr/lib64/python2.7/urllib2.py", line 1214, in do_open
    raise URLError(err)
URLError: <urlopen error [Errno 110] Connection timed out>
2020-07-24 14:08:46,353 ERROR - Internal Server Error: /monitoring/
Traceback (most recent call last):
  File "/app/argus_final/venv/lib/python2.7/site-packages/django/core/handlers/exception.py", line 41, in inner
    response = get_response(request)
  File "/app/argus_final/venv/lib/python2.7/site-packages/django/core/handlers/base.py", line 187, in _get_response
    response = self.process_exception_by_middleware(e, request)
  File "/app/argus_final/venv/lib/python2.7/site-packages/django/core/handlers/base.py", line 185, in _get_response
    response = wrapped_callback(request, *callback_args, **callback_kwargs)
  File "/app/argus_final/venv/lib/python2.7/site-packages/django/contrib/auth/decorators.py", line 23, in _wrapped_view
    return view_func(request, *args, **kwargs)
  File "/app/argus_final/venv/lib/python2.7/site-packages/django/views/generic/base.py", line 68, in view
    return self.dispatch(request, *args, **kwargs)
  File "/app/argus_final/app/argus/argus/mixins.py", line 14, in dispatch
    return super(GENERIC_PERMISSION_MIXIN, self).dispatch(request, *args, **kwargs)
  File "/app/argus_final/venv/lib/python2.7/site-packages/django/views/generic/base.py", line 88, in dispatch
    return handler(request, *args, **kwargs)
  File "/app/argus_final/app/argus/monitoring/views.py", line 30, in get
    context['data'] = ZABBIX.getAllTriggeredTriggers()
  File "/app/argus_final/app/argus/global_objects/zabbix_api.py", line 80, in getAllTriggeredTriggers
    triggers = self.zapi.do_request('trigger.get',req)
  File "/app/argus_final/venv/lib/python2.7/site-packages/pyzabbix/api.py", line 251, in do_request
    res = urlopen(req)
  File "/app/argus_final/venv/lib/python2.7/site-packages/pyzabbix/api.py", line 117, in inner
    res = func(req)
  File "/app/argus_final/venv/lib/python2.7/site-packages/pyzabbix/api.py", line 126, in urlopen
    return urllib2.urlopen(*args, **kwargs)
  File "/usr/lib64/python2.7/urllib2.py", line 154, in urlopen
    return opener.open(url, data, timeout)
  File "/usr/lib64/python2.7/urllib2.py", line 431, in open
    response = self._open(req, data)
  File "/usr/lib64/python2.7/urllib2.py", line 449, in _open
    '_open', req)
  File "/usr/lib64/python2.7/urllib2.py", line 409, in _call_chain
    result = func(*args)
  File "/usr/lib64/python2.7/urllib2.py", line 1244, in http_open
    return self.do_open(httplib.HTTPConnection, req)
  File "/usr/lib64/python2.7/urllib2.py", line 1214, in do_open
    raise URLError(err)
URLError: <urlopen error [Errno 110] Connection timed out>
2020-07-24 14:08:49,421 ERROR - Internal Server Error: /monitoring/
Traceback (most recent call last):
  File "/app/argus_final/venv/lib/python2.7/site-packages/django/core/handlers/exception.py", line 41, in inner
    response = get_response(request)
  File "/app/argus_final/venv/lib/python2.7/site-packages/django/core/handlers/base.py", line 187, in _get_response
    response = self.process_exception_by_middleware(e, request)
  File "/app/argus_final/venv/lib/python2.7/site-packages/django/core/handlers/base.py", line 185, in _get_response
    response = wrapped_callback(request, *callback_args, **callback_kwargs)
  File "/app/argus_final/venv/lib/python2.7/site-packages/django/contrib/auth/decorators.py", line 23, in _wrapped_view
    return view_func(request, *args, **kwargs)
  File "/app/argus_final/venv/lib/python2.7/site-packages/django/views/generic/base.py", line 68, in view
    return self.dispatch(request, *args, **kwargs)
  File "/app/argus_final/app/argus/argus/mixins.py", line 14, in dispatch
    return super(GENERIC_PERMISSION_MIXIN, self).dispatch(request, *args, **kwargs)
  File "/app/argus_final/venv/lib/python2.7/site-packages/django/views/generic/base.py", line 88, in dispatch
    return handler(request, *args, **kwargs)
  File "/app/argus_final/app/argus/monitoring/views.py", line 40, in get
    context['data'] = ZABBIX.getAllEvents(daysfromnow=period)[-limit:]
  File "/app/argus_final/app/argus/global_objects/zabbix_api.py", line 121, in getAllEvents
    events = self.zapi.do_request('event.get',req)
  File "/app/argus_final/venv/lib/python2.7/site-packages/pyzabbix/api.py", line 251, in do_request
    res = urlopen(req)
  File "/app/argus_final/venv/lib/python2.7/site-packages/pyzabbix/api.py", line 117, in inner
    res = func(req)
  File "/app/argus_final/venv/lib/python2.7/site-packages/pyzabbix/api.py", line 126, in urlopen
    return urllib2.urlopen(*args, **kwargs)
  File "/usr/lib64/python2.7/urllib2.py", line 154, in urlopen
    return opener.open(url, data, timeout)
  File "/usr/lib64/python2.7/urllib2.py", line 431, in open
    response = self._open(req, data)
  File "/usr/lib64/python2.7/urllib2.py", line 449, in _open
    '_open', req)
  File "/usr/lib64/python2.7/urllib2.py", line 409, in _call_chain
    result = func(*args)
  File "/usr/lib64/python2.7/urllib2.py", line 1244, in http_open
    return self.do_open(httplib.HTTPConnection, req)
  File "/usr/lib64/python2.7/urllib2.py", line 1214, in do_open
    raise URLError(err)
URLError: <urlopen error [Errno 110] Connection timed out>
2020-07-24 14:08:51,049 ERROR - Internal Server Error: /monitoring/
Traceback (most recent call last):
  File "/app/argus_final/venv/lib/python2.7/site-packages/django/core/handlers/exception.py", line 41, in inner
    response = get_response(request)
  File "/app/argus_final/venv/lib/python2.7/site-packages/django/core/handlers/base.py", line 187, in _get_response
    response = self.process_exception_by_middleware(e, request)
  File "/app/argus_final/venv/lib/python2.7/site-packages/django/core/handlers/base.py", line 185, in _get_response
    response = wrapped_callback(request, *callback_args, **callback_kwargs)
  File "/app/argus_final/venv/lib/python2.7/site-packages/django/contrib/auth/decorators.py", line 23, in _wrapped_view
    return view_func(request, *args, **kwargs)
  File "/app/argus_final/venv/lib/python2.7/site-packages/django/views/generic/base.py", line 68, in view
    return self.dispatch(request, *args, **kwargs)
  File "/app/argus_final/app/argus/argus/mixins.py", line 14, in dispatch
    return super(GENERIC_PERMISSION_MIXIN, self).dispatch(request, *args, **kwargs)
  File "/app/argus_final/venv/lib/python2.7/site-packages/django/views/generic/base.py", line 88, in dispatch
    return handler(request, *args, **kwargs)
  File "/app/argus_final/app/argus/monitoring/views.py", line 30, in get
    context['data'] = ZABBIX.getAllTriggeredTriggers()
  File "/app/argus_final/app/argus/global_objects/zabbix_api.py", line 80, in getAllTriggeredTriggers
    triggers = self.zapi.do_request('trigger.get',req)
  File "/app/argus_final/venv/lib/python2.7/site-packages/pyzabbix/api.py", line 251, in do_request
    res = urlopen(req)
  File "/app/argus_final/venv/lib/python2.7/site-packages/pyzabbix/api.py", line 117, in inner
    res = func(req)
  File "/app/argus_final/venv/lib/python2.7/site-packages/pyzabbix/api.py", line 126, in urlopen
    return urllib2.urlopen(*args, **kwargs)
  File "/usr/lib64/python2.7/urllib2.py", line 154, in urlopen
    return opener.open(url, data, timeout)
  File "/usr/lib64/python2.7/urllib2.py", line 431, in open
    response = self._open(req, data)
  File "/usr/lib64/python2.7/urllib2.py", line 449, in _open
    '_open', req)
  File "/usr/lib64/python2.7/urllib2.py", line 409, in _call_chain
    result = func(*args)
  File "/usr/lib64/python2.7/urllib2.py", line 1244, in http_open
    return self.do_open(httplib.HTTPConnection, req)
  File "/usr/lib64/python2.7/urllib2.py", line 1214, in do_open
    raise URLError(err)
URLError: <urlopen error [Errno 110] Connection timed out>
2020-07-24 14:08:54,177 ERROR - Internal Server Error: /monitoring/
Traceback (most recent call last):
  File "/app/argus_final/venv/lib/python2.7/site-packages/django/core/handlers/exception.py", line 41, in inner
    response = get_response(request)
  File "/app/argus_final/venv/lib/python2.7/site-packages/django/core/handlers/base.py", line 187, in _get_response
    response = self.process_exception_by_middleware(e, request)
  File "/app/argus_final/venv/lib/python2.7/site-packages/django/core/handlers/base.py", line 185, in _get_response
    response = wrapped_callback(request, *callback_args, **callback_kwargs)
  File "/app/argus_final/venv/lib/python2.7/site-packages/django/contrib/auth/decorators.py", line 23, in _wrapped_view
    return view_func(request, *args, **kwargs)
  File "/app/argus_final/venv/lib/python2.7/site-packages/django/views/generic/base.py", line 68, in view
    return self.dispatch(request, *args, **kwargs)
  File "/app/argus_final/app/argus/argus/mixins.py", line 14, in dispatch
    return super(GENERIC_PERMISSION_MIXIN, self).dispatch(request, *args, **kwargs)
  File "/app/argus_final/venv/lib/python2.7/site-packages/django/views/generic/base.py", line 88, in dispatch
    return handler(request, *args, **kwargs)
  File "/app/argus_final/app/argus/monitoring/views.py", line 40, in get
    context['data'] = ZABBIX.getAllEvents(daysfromnow=period)[-limit:]
  File "/app/argus_final/app/argus/global_objects/zabbix_api.py", line 121, in getAllEvents
    events = self.zapi.do_request('event.get',req)
  File "/app/argus_final/venv/lib/python2.7/site-packages/pyzabbix/api.py", line 251, in do_request
    res = urlopen(req)
  File "/app/argus_final/venv/lib/python2.7/site-packages/pyzabbix/api.py", line 117, in inner
    res = func(req)
  File "/app/argus_final/venv/lib/python2.7/site-packages/pyzabbix/api.py", line 126, in urlopen
    return urllib2.urlopen(*args, **kwargs)
  File "/usr/lib64/python2.7/urllib2.py", line 154, in urlopen
    return opener.open(url, data, timeout)
  File "/usr/lib64/python2.7/urllib2.py", line 431, in open
    response = self._open(req, data)
  File "/usr/lib64/python2.7/urllib2.py", line 449, in _open
    '_open', req)
  File "/usr/lib64/python2.7/urllib2.py", line 409, in _call_chain
    result = func(*args)
  File "/usr/lib64/python2.7/urllib2.py", line 1244, in http_open
    return self.do_open(httplib.HTTPConnection, req)
  File "/usr/lib64/python2.7/urllib2.py", line 1214, in do_open
    raise URLError(err)
URLError: <urlopen error [Errno 110] Connection timed out>
2020-07-24 14:10:00,349 ERROR - Internal Server Error: /monitoring/
Traceback (most recent call last):
  File "/app/argus_final/venv/lib/python2.7/site-packages/django/core/handlers/exception.py", line 41, in inner
    response = get_response(request)
  File "/app/argus_final/venv/lib/python2.7/site-packages/django/core/handlers/base.py", line 187, in _get_response
    response = self.process_exception_by_middleware(e, request)
  File "/app/argus_final/venv/lib/python2.7/site-packages/django/core/handlers/base.py", line 185, in _get_response
    response = wrapped_callback(request, *callback_args, **callback_kwargs)
  File "/app/argus_final/venv/lib/python2.7/site-packages/django/contrib/auth/decorators.py", line 23, in _wrapped_view
    return view_func(request, *args, **kwargs)
  File "/app/argus_final/venv/lib/python2.7/site-packages/django/views/generic/base.py", line 68, in view
    return self.dispatch(request, *args, **kwargs)
  File "/app/argus_final/app/argus/argus/mixins.py", line 14, in dispatch
    return super(GENERIC_PERMISSION_MIXIN, self).dispatch(request, *args, **kwargs)
  File "/app/argus_final/venv/lib/python2.7/site-packages/django/views/generic/base.py", line 88, in dispatch
    return handler(request, *args, **kwargs)
  File "/app/argus_final/app/argus/monitoring/views.py", line 30, in get
    context['data'] = ZABBIX.getAllTriggeredTriggers()
  File "/app/argus_final/app/argus/global_objects/zabbix_api.py", line 80, in getAllTriggeredTriggers
    triggers = self.zapi.do_request('trigger.get',req)
  File "/app/argus_final/venv/lib/python2.7/site-packages/pyzabbix/api.py", line 251, in do_request
    res = urlopen(req)
  File "/app/argus_final/venv/lib/python2.7/site-packages/pyzabbix/api.py", line 117, in inner
    res = func(req)
  File "/app/argus_final/venv/lib/python2.7/site-packages/pyzabbix/api.py", line 126, in urlopen
    return urllib2.urlopen(*args, **kwargs)
  File "/usr/lib64/python2.7/urllib2.py", line 154, in urlopen
    return opener.open(url, data, timeout)
  File "/usr/lib64/python2.7/urllib2.py", line 431, in open
    response = self._open(req, data)
  File "/usr/lib64/python2.7/urllib2.py", line 449, in _open
    '_open', req)
  File "/usr/lib64/python2.7/urllib2.py", line 409, in _call_chain
    result = func(*args)
  File "/usr/lib64/python2.7/urllib2.py", line 1244, in http_open
    return self.do_open(httplib.HTTPConnection, req)
  File "/usr/lib64/python2.7/urllib2.py", line 1214, in do_open
    raise URLError(err)
URLError: <urlopen error [Errno 110] Connection timed out>
2020-07-24 14:10:03,417 ERROR - Internal Server Error: /monitoring/
Traceback (most recent call last):
  File "/app/argus_final/venv/lib/python2.7/site-packages/django/core/handlers/exception.py", line 41, in inner
    response = get_response(request)
  File "/app/argus_final/venv/lib/python2.7/site-packages/django/core/handlers/base.py", line 187, in _get_response
    response = self.process_exception_by_middleware(e, request)
  File "/app/argus_final/venv/lib/python2.7/site-packages/django/core/handlers/base.py", line 185, in _get_response
    response = wrapped_callback(request, *callback_args, **callback_kwargs)
  File "/app/argus_final/venv/lib/python2.7/site-packages/django/contrib/auth/decorators.py", line 23, in _wrapped_view
    return view_func(request, *args, **kwargs)
  File "/app/argus_final/venv/lib/python2.7/site-packages/django/views/generic/base.py", line 68, in view
    return self.dispatch(request, *args, **kwargs)
  File "/app/argus_final/app/argus/argus/mixins.py", line 14, in dispatch
    return super(GENERIC_PERMISSION_MIXIN, self).dispatch(request, *args, **kwargs)
  File "/app/argus_final/venv/lib/python2.7/site-packages/django/views/generic/base.py", line 88, in dispatch
    return handler(request, *args, **kwargs)
  File "/app/argus_final/app/argus/monitoring/views.py", line 40, in get
    context['data'] = ZABBIX.getAllEvents(daysfromnow=period)[-limit:]
  File "/app/argus_final/app/argus/global_objects/zabbix_api.py", line 121, in getAllEvents
    events = self.zapi.do_request('event.get',req)
  File "/app/argus_final/venv/lib/python2.7/site-packages/pyzabbix/api.py", line 251, in do_request
    res = urlopen(req)
  File "/app/argus_final/venv/lib/python2.7/site-packages/pyzabbix/api.py", line 117, in inner
    res = func(req)
  File "/app/argus_final/venv/lib/python2.7/site-packages/pyzabbix/api.py", line 126, in urlopen
    return urllib2.urlopen(*args, **kwargs)
  File "/usr/lib64/python2.7/urllib2.py", line 154, in urlopen
    return opener.open(url, data, timeout)
  File "/usr/lib64/python2.7/urllib2.py", line 431, in open
    response = self._open(req, data)
  File "/usr/lib64/python2.7/urllib2.py", line 449, in _open
    '_open', req)
  File "/usr/lib64/python2.7/urllib2.py", line 409, in _call_chain
    result = func(*args)
  File "/usr/lib64/python2.7/urllib2.py", line 1244, in http_open
    return self.do_open(httplib.HTTPConnection, req)
  File "/usr/lib64/python2.7/urllib2.py", line 1214, in do_open
    raise URLError(err)
URLError: <urlopen error [Errno 110] Connection timed out>
2020-07-24 14:10:37,353 ERROR - Internal Server Error: /monitoring/
Traceback (most recent call last):
  File "/app/argus_final/venv/lib/python2.7/site-packages/django/core/handlers/exception.py", line 41, in inner
    response = get_response(request)
  File "/app/argus_final/venv/lib/python2.7/site-packages/django/core/handlers/base.py", line 187, in _get_response
    response = self.process_exception_by_middleware(e, request)
  File "/app/argus_final/venv/lib/python2.7/site-packages/django/core/handlers/base.py", line 185, in _get_response
    response = wrapped_callback(request, *callback_args, **callback_kwargs)
  File "/app/argus_final/venv/lib/python2.7/site-packages/django/contrib/auth/decorators.py", line 23, in _wrapped_view
    return view_func(request, *args, **kwargs)
  File "/app/argus_final/venv/lib/python2.7/site-packages/django/views/generic/base.py", line 68, in view
    return self.dispatch(request, *args, **kwargs)
  File "/app/argus_final/app/argus/argus/mixins.py", line 14, in dispatch
    return super(GENERIC_PERMISSION_MIXIN, self).dispatch(request, *args, **kwargs)
  File "/app/argus_final/venv/lib/python2.7/site-packages/django/views/generic/base.py", line 88, in dispatch
    return handler(request, *args, **kwargs)
  File "/app/argus_final/app/argus/monitoring/views.py", line 30, in get
    context['data'] = ZABBIX.getAllTriggeredTriggers()
  File "/app/argus_final/app/argus/global_objects/zabbix_api.py", line 80, in getAllTriggeredTriggers
    triggers = self.zapi.do_request('trigger.get',req)
  File "/app/argus_final/venv/lib/python2.7/site-packages/pyzabbix/api.py", line 251, in do_request
    res = urlopen(req)
  File "/app/argus_final/venv/lib/python2.7/site-packages/pyzabbix/api.py", line 117, in inner
    res = func(req)
  File "/app/argus_final/venv/lib/python2.7/site-packages/pyzabbix/api.py", line 126, in urlopen
    return urllib2.urlopen(*args, **kwargs)
  File "/usr/lib64/python2.7/urllib2.py", line 154, in urlopen
    return opener.open(url, data, timeout)
  File "/usr/lib64/python2.7/urllib2.py", line 431, in open
    response = self._open(req, data)
  File "/usr/lib64/python2.7/urllib2.py", line 449, in _open
    '_open', req)
  File "/usr/lib64/python2.7/urllib2.py", line 409, in _call_chain
    result = func(*args)
  File "/usr/lib64/python2.7/urllib2.py", line 1244, in http_open
    return self.do_open(httplib.HTTPConnection, req)
  File "/usr/lib64/python2.7/urllib2.py", line 1214, in do_open
    raise URLError(err)
URLError: <urlopen error [Errno 110] Connection timed out>
2020-07-24 14:10:40,421 ERROR - Internal Server Error: /monitoring/
Traceback (most recent call last):
  File "/app/argus_final/venv/lib/python2.7/site-packages/django/core/handlers/exception.py", line 41, in inner
    response = get_response(request)
  File "/app/argus_final/venv/lib/python2.7/site-packages/django/core/handlers/base.py", line 187, in _get_response
    response = self.process_exception_by_middleware(e, request)
  File "/app/argus_final/venv/lib/python2.7/site-packages/django/core/handlers/base.py", line 185, in _get_response
    response = wrapped_callback(request, *callback_args, **callback_kwargs)
  File "/app/argus_final/venv/lib/python2.7/site-packages/django/contrib/auth/decorators.py", line 23, in _wrapped_view
    return view_func(request, *args, **kwargs)
  File "/app/argus_final/venv/lib/python2.7/site-packages/django/views/generic/base.py", line 68, in view
    return self.dispatch(request, *args, **kwargs)
  File "/app/argus_final/app/argus/argus/mixins.py", line 14, in dispatch
    return super(GENERIC_PERMISSION_MIXIN, self).dispatch(request, *args, **kwargs)
  File "/app/argus_final/venv/lib/python2.7/site-packages/django/views/generic/base.py", line 88, in dispatch
    return handler(request, *args, **kwargs)
  File "/app/argus_final/app/argus/monitoring/views.py", line 40, in get
    context['data'] = ZABBIX.getAllEvents(daysfromnow=period)[-limit:]
  File "/app/argus_final/app/argus/global_objects/zabbix_api.py", line 121, in getAllEvents
    events = self.zapi.do_request('event.get',req)
  File "/app/argus_final/venv/lib/python2.7/site-packages/pyzabbix/api.py", line 251, in do_request
    res = urlopen(req)
  File "/app/argus_final/venv/lib/python2.7/site-packages/pyzabbix/api.py", line 117, in inner
    res = func(req)
  File "/app/argus_final/venv/lib/python2.7/site-packages/pyzabbix/api.py", line 126, in urlopen
    return urllib2.urlopen(*args, **kwargs)
  File "/usr/lib64/python2.7/urllib2.py", line 154, in urlopen
    return opener.open(url, data, timeout)
  File "/usr/lib64/python2.7/urllib2.py", line 431, in open
    response = self._open(req, data)
  File "/usr/lib64/python2.7/urllib2.py", line 449, in _open
    '_open', req)
  File "/usr/lib64/python2.7/urllib2.py", line 409, in _call_chain
    result = func(*args)
  File "/usr/lib64/python2.7/urllib2.py", line 1244, in http_open
    return self.do_open(httplib.HTTPConnection, req)
  File "/usr/lib64/python2.7/urllib2.py", line 1214, in do_open
    raise URLError(err)
URLError: <urlopen error [Errno 110] Connection timed out>
2020-07-24 14:10:43,881 ERROR - Internal Server Error: /monitoring/
Traceback (most recent call last):
  File "/app/argus_final/venv/lib/python2.7/site-packages/django/core/handlers/exception.py", line 41, in inner
    response = get_response(request)
  File "/app/argus_final/venv/lib/python2.7/site-packages/django/core/handlers/base.py", line 187, in _get_response
    response = self.process_exception_by_middleware(e, request)
  File "/app/argus_final/venv/lib/python2.7/site-packages/django/core/handlers/base.py", line 185, in _get_response
    response = wrapped_callback(request, *callback_args, **callback_kwargs)
  File "/app/argus_final/venv/lib/python2.7/site-packages/django/contrib/auth/decorators.py", line 23, in _wrapped_view
    return view_func(request, *args, **kwargs)
  File "/app/argus_final/venv/lib/python2.7/site-packages/django/views/generic/base.py", line 68, in view
    return self.dispatch(request, *args, **kwargs)
  File "/app/argus_final/app/argus/argus/mixins.py", line 14, in dispatch
    return super(GENERIC_PERMISSION_MIXIN, self).dispatch(request, *args, **kwargs)
  File "/app/argus_final/venv/lib/python2.7/site-packages/django/views/generic/base.py", line 88, in dispatch
    return handler(request, *args, **kwargs)
  File "/app/argus_final/app/argus/monitoring/views.py", line 30, in get
    context['data'] = ZABBIX.getAllTriggeredTriggers()
  File "/app/argus_final/app/argus/global_objects/zabbix_api.py", line 80, in getAllTriggeredTriggers
    triggers = self.zapi.do_request('trigger.get',req)
  File "/app/argus_final/venv/lib/python2.7/site-packages/pyzabbix/api.py", line 251, in do_request
    res = urlopen(req)
  File "/app/argus_final/venv/lib/python2.7/site-packages/pyzabbix/api.py", line 117, in inner
    res = func(req)
  File "/app/argus_final/venv/lib/python2.7/site-packages/pyzabbix/api.py", line 126, in urlopen
    return urllib2.urlopen(*args, **kwargs)
  File "/usr/lib64/python2.7/urllib2.py", line 154, in urlopen
    return opener.open(url, data, timeout)
  File "/usr/lib64/python2.7/urllib2.py", line 431, in open
    response = self._open(req, data)
  File "/usr/lib64/python2.7/urllib2.py", line 449, in _open
    '_open', req)
  File "/usr/lib64/python2.7/urllib2.py", line 409, in _call_chain
    result = func(*args)
  File "/usr/lib64/python2.7/urllib2.py", line 1244, in http_open
    return self.do_open(httplib.HTTPConnection, req)
  File "/usr/lib64/python2.7/urllib2.py", line 1214, in do_open
    raise URLError(err)
URLError: <urlopen error [Errno 110] Connection timed out>
2020-07-24 14:11:14,353 ERROR - Internal Server Error: /monitoring/
Traceback (most recent call last):
  File "/app/argus_final/venv/lib/python2.7/site-packages/django/core/handlers/exception.py", line 41, in inner
    response = get_response(request)
  File "/app/argus_final/venv/lib/python2.7/site-packages/django/core/handlers/base.py", line 187, in _get_response
    response = self.process_exception_by_middleware(e, request)
  File "/app/argus_final/venv/lib/python2.7/site-packages/django/core/handlers/base.py", line 185, in _get_response
    response = wrapped_callback(request, *callback_args, **callback_kwargs)
  File "/app/argus_final/venv/lib/python2.7/site-packages/django/contrib/auth/decorators.py", line 23, in _wrapped_view
    return view_func(request, *args, **kwargs)
  File "/app/argus_final/venv/lib/python2.7/site-packages/django/views/generic/base.py", line 68, in view
    return self.dispatch(request, *args, **kwargs)
  File "/app/argus_final/app/argus/argus/mixins.py", line 14, in dispatch
    return super(GENERIC_PERMISSION_MIXIN, self).dispatch(request, *args, **kwargs)
  File "/app/argus_final/venv/lib/python2.7/site-packages/django/views/generic/base.py", line 88, in dispatch
    return handler(request, *args, **kwargs)
  File "/app/argus_final/app/argus/monitoring/views.py", line 30, in get
    context['data'] = ZABBIX.getAllTriggeredTriggers()
  File "/app/argus_final/app/argus/global_objects/zabbix_api.py", line 80, in getAllTriggeredTriggers
    triggers = self.zapi.do_request('trigger.get',req)
  File "/app/argus_final/venv/lib/python2.7/site-packages/pyzabbix/api.py", line 251, in do_request
    res = urlopen(req)
  File "/app/argus_final/venv/lib/python2.7/site-packages/pyzabbix/api.py", line 117, in inner
    res = func(req)
  File "/app/argus_final/venv/lib/python2.7/site-packages/pyzabbix/api.py", line 126, in urlopen
    return urllib2.urlopen(*args, **kwargs)
  File "/usr/lib64/python2.7/urllib2.py", line 154, in urlopen
    return opener.open(url, data, timeout)
  File "/usr/lib64/python2.7/urllib2.py", line 431, in open
    response = self._open(req, data)
  File "/usr/lib64/python2.7/urllib2.py", line 449, in _open
    '_open', req)
  File "/usr/lib64/python2.7/urllib2.py", line 409, in _call_chain
    result = func(*args)
  File "/usr/lib64/python2.7/urllib2.py", line 1244, in http_open
    return self.do_open(httplib.HTTPConnection, req)
  File "/usr/lib64/python2.7/urllib2.py", line 1214, in do_open
    raise URLError(err)
URLError: <urlopen error [Errno 110] Connection timed out>
2020-07-24 14:11:17,425 ERROR - Internal Server Error: /monitoring/
Traceback (most recent call last):
  File "/app/argus_final/venv/lib/python2.7/site-packages/django/core/handlers/exception.py", line 41, in inner
    response = get_response(request)
  File "/app/argus_final/venv/lib/python2.7/site-packages/django/core/handlers/base.py", line 187, in _get_response
    response = self.process_exception_by_middleware(e, request)
  File "/app/argus_final/venv/lib/python2.7/site-packages/django/core/handlers/base.py", line 185, in _get_response
    response = wrapped_callback(request, *callback_args, **callback_kwargs)
  File "/app/argus_final/venv/lib/python2.7/site-packages/django/contrib/auth/decorators.py", line 23, in _wrapped_view
    return view_func(request, *args, **kwargs)
  File "/app/argus_final/venv/lib/python2.7/site-packages/django/views/generic/base.py", line 68, in view
    return self.dispatch(request, *args, **kwargs)
  File "/app/argus_final/app/argus/argus/mixins.py", line 14, in dispatch
    return super(GENERIC_PERMISSION_MIXIN, self).dispatch(request, *args, **kwargs)
  File "/app/argus_final/venv/lib/python2.7/site-packages/django/views/generic/base.py", line 88, in dispatch
    return handler(request, *args, **kwargs)
  File "/app/argus_final/app/argus/monitoring/views.py", line 40, in get
    context['data'] = ZABBIX.getAllEvents(daysfromnow=period)[-limit:]
  File "/app/argus_final/app/argus/global_objects/zabbix_api.py", line 121, in getAllEvents
    events = self.zapi.do_request('event.get',req)
  File "/app/argus_final/venv/lib/python2.7/site-packages/pyzabbix/api.py", line 251, in do_request
    res = urlopen(req)
  File "/app/argus_final/venv/lib/python2.7/site-packages/pyzabbix/api.py", line 117, in inner
    res = func(req)
  File "/app/argus_final/venv/lib/python2.7/site-packages/pyzabbix/api.py", line 126, in urlopen
    return urllib2.urlopen(*args, **kwargs)
  File "/usr/lib64/python2.7/urllib2.py", line 154, in urlopen
    return opener.open(url, data, timeout)
  File "/usr/lib64/python2.7/urllib2.py", line 431, in open
    response = self._open(req, data)
  File "/usr/lib64/python2.7/urllib2.py", line 449, in _open
    '_open', req)
  File "/usr/lib64/python2.7/urllib2.py", line 409, in _call_chain
    result = func(*args)
  File "/usr/lib64/python2.7/urllib2.py", line 1244, in http_open
    return self.do_open(httplib.HTTPConnection, req)
  File "/usr/lib64/python2.7/urllib2.py", line 1214, in do_open
    raise URLError(err)
URLError: <urlopen error [Errno 110] Connection timed out>
2020-07-24 14:11:36,881 ERROR - Internal Server Error: /monitoring/
Traceback (most recent call last):
  File "/app/argus_final/venv/lib/python2.7/site-packages/django/core/handlers/exception.py", line 41, in inner
    response = get_response(request)
  File "/app/argus_final/venv/lib/python2.7/site-packages/django/core/handlers/base.py", line 187, in _get_response
    response = self.process_exception_by_middleware(e, request)
  File "/app/argus_final/venv/lib/python2.7/site-packages/django/core/handlers/base.py", line 185, in _get_response
    response = wrapped_callback(request, *callback_args, **callback_kwargs)
  File "/app/argus_final/venv/lib/python2.7/site-packages/django/contrib/auth/decorators.py", line 23, in _wrapped_view
    return view_func(request, *args, **kwargs)
  File "/app/argus_final/venv/lib/python2.7/site-packages/django/views/generic/base.py", line 68, in view
    return self.dispatch(request, *args, **kwargs)
  File "/app/argus_final/app/argus/argus/mixins.py", line 14, in dispatch
    return super(GENERIC_PERMISSION_MIXIN, self).dispatch(request, *args, **kwargs)
  File "/app/argus_final/venv/lib/python2.7/site-packages/django/views/generic/base.py", line 88, in dispatch
    return handler(request, *args, **kwargs)
  File "/app/argus_final/app/argus/monitoring/views.py", line 30, in get
    context['data'] = ZABBIX.getAllTriggeredTriggers()
  File "/app/argus_final/app/argus/global_objects/zabbix_api.py", line 80, in getAllTriggeredTriggers
    triggers = self.zapi.do_request('trigger.get',req)
  File "/app/argus_final/venv/lib/python2.7/site-packages/pyzabbix/api.py", line 251, in do_request
    res = urlopen(req)
  File "/app/argus_final/venv/lib/python2.7/site-packages/pyzabbix/api.py", line 117, in inner
    res = func(req)
  File "/app/argus_final/venv/lib/python2.7/site-packages/pyzabbix/api.py", line 126, in urlopen
    return urllib2.urlopen(*args, **kwargs)
  File "/usr/lib64/python2.7/urllib2.py", line 154, in urlopen
    return opener.open(url, data, timeout)
  File "/usr/lib64/python2.7/urllib2.py", line 431, in open
    response = self._open(req, data)
  File "/usr/lib64/python2.7/urllib2.py", line 449, in _open
    '_open', req)
  File "/usr/lib64/python2.7/urllib2.py", line 409, in _call_chain
    result = func(*args)
  File "/usr/lib64/python2.7/urllib2.py", line 1244, in http_open
    return self.do_open(httplib.HTTPConnection, req)
  File "/usr/lib64/python2.7/urllib2.py", line 1214, in do_open
    raise URLError(err)
URLError: <urlopen error [Errno 110] Connection timed out>
2020-07-24 14:11:39,962 ERROR - Internal Server Error: /monitoring/
Traceback (most recent call last):
  File "/app/argus_final/venv/lib/python2.7/site-packages/django/core/handlers/exception.py", line 41, in inner
    response = get_response(request)
  File "/app/argus_final/venv/lib/python2.7/site-packages/django/core/handlers/base.py", line 187, in _get_response
    response = self.process_exception_by_middleware(e, request)
  File "/app/argus_final/venv/lib/python2.7/site-packages/django/core/handlers/base.py", line 185, in _get_response
    response = wrapped_callback(request, *callback_args, **callback_kwargs)
  File "/app/argus_final/venv/lib/python2.7/site-packages/django/contrib/auth/decorators.py", line 23, in _wrapped_view
    return view_func(request, *args, **kwargs)
  File "/app/argus_final/venv/lib/python2.7/site-packages/django/views/generic/base.py", line 68, in view
    return self.dispatch(request, *args, **kwargs)
  File "/app/argus_final/app/argus/argus/mixins.py", line 14, in dispatch
    return super(GENERIC_PERMISSION_MIXIN, self).dispatch(request, *args, **kwargs)
  File "/app/argus_final/venv/lib/python2.7/site-packages/django/views/generic/base.py", line 88, in dispatch
    return handler(request, *args, **kwargs)
  File "/app/argus_final/app/argus/monitoring/views.py", line 40, in get
    context['data'] = ZABBIX.getAllEvents(daysfromnow=period)[-limit:]
  File "/app/argus_final/app/argus/global_objects/zabbix_api.py", line 121, in getAllEvents
    events = self.zapi.do_request('event.get',req)
  File "/app/argus_final/venv/lib/python2.7/site-packages/pyzabbix/api.py", line 251, in do_request
    res = urlopen(req)
  File "/app/argus_final/venv/lib/python2.7/site-packages/pyzabbix/api.py", line 117, in inner
    res = func(req)
  File "/app/argus_final/venv/lib/python2.7/site-packages/pyzabbix/api.py", line 126, in urlopen
    return urllib2.urlopen(*args, **kwargs)
  File "/usr/lib64/python2.7/urllib2.py", line 154, in urlopen
    return opener.open(url, data, timeout)
  File "/usr/lib64/python2.7/urllib2.py", line 431, in open
    response = self._open(req, data)
  File "/usr/lib64/python2.7/urllib2.py", line 449, in _open
    '_open', req)
  File "/usr/lib64/python2.7/urllib2.py", line 409, in _call_chain
    result = func(*args)
  File "/usr/lib64/python2.7/urllib2.py", line 1244, in http_open
    return self.do_open(httplib.HTTPConnection, req)
  File "/usr/lib64/python2.7/urllib2.py", line 1214, in do_open
    raise URLError(err)
URLError: <urlopen error [Errno 110] Connection timed out>
2020-07-24 14:11:51,353 ERROR - Internal Server Error: /monitoring/
Traceback (most recent call last):
  File "/app/argus_final/venv/lib/python2.7/site-packages/django/core/handlers/exception.py", line 41, in inner
    response = get_response(request)
  File "/app/argus_final/venv/lib/python2.7/site-packages/django/core/handlers/base.py", line 187, in _get_response
    response = self.process_exception_by_middleware(e, request)
  File "/app/argus_final/venv/lib/python2.7/site-packages/django/core/handlers/base.py", line 185, in _get_response
    response = wrapped_callback(request, *callback_args, **callback_kwargs)
  File "/app/argus_final/venv/lib/python2.7/site-packages/django/contrib/auth/decorators.py", line 23, in _wrapped_view
    return view_func(request, *args, **kwargs)
  File "/app/argus_final/venv/lib/python2.7/site-packages/django/views/generic/base.py", line 68, in view
    return self.dispatch(request, *args, **kwargs)
  File "/app/argus_final/app/argus/argus/mixins.py", line 14, in dispatch
    return super(GENERIC_PERMISSION_MIXIN, self).dispatch(request, *args, **kwargs)
  File "/app/argus_final/venv/lib/python2.7/site-packages/django/views/generic/base.py", line 88, in dispatch
    return handler(request, *args, **kwargs)
  File "/app/argus_final/app/argus/monitoring/views.py", line 30, in get
    context['data'] = ZABBIX.getAllTriggeredTriggers()
  File "/app/argus_final/app/argus/global_objects/zabbix_api.py", line 80, in getAllTriggeredTriggers
    triggers = self.zapi.do_request('trigger.get',req)
  File "/app/argus_final/venv/lib/python2.7/site-packages/pyzabbix/api.py", line 251, in do_request
    res = urlopen(req)
  File "/app/argus_final/venv/lib/python2.7/site-packages/pyzabbix/api.py", line 117, in inner
    res = func(req)
  File "/app/argus_final/venv/lib/python2.7/site-packages/pyzabbix/api.py", line 126, in urlopen
    return urllib2.urlopen(*args, **kwargs)
  File "/usr/lib64/python2.7/urllib2.py", line 154, in urlopen
    return opener.open(url, data, timeout)
  File "/usr/lib64/python2.7/urllib2.py", line 431, in open
    response = self._open(req, data)
  File "/usr/lib64/python2.7/urllib2.py", line 449, in _open
    '_open', req)
  File "/usr/lib64/python2.7/urllib2.py", line 409, in _call_chain
    result = func(*args)
  File "/usr/lib64/python2.7/urllib2.py", line 1244, in http_open
    return self.do_open(httplib.HTTPConnection, req)
  File "/usr/lib64/python2.7/urllib2.py", line 1214, in do_open
    raise URLError(err)
URLError: <urlopen error [Errno 110] Connection timed out>
2020-07-24 14:11:54,425 ERROR - Internal Server Error: /monitoring/
Traceback (most recent call last):
  File "/app/argus_final/venv/lib/python2.7/site-packages/django/core/handlers/exception.py", line 41, in inner
    response = get_response(request)
  File "/app/argus_final/venv/lib/python2.7/site-packages/django/core/handlers/base.py", line 187, in _get_response
    response = self.process_exception_by_middleware(e, request)
  File "/app/argus_final/venv/lib/python2.7/site-packages/django/core/handlers/base.py", line 185, in _get_response
    response = wrapped_callback(request, *callback_args, **callback_kwargs)
  File "/app/argus_final/venv/lib/python2.7/site-packages/django/contrib/auth/decorators.py", line 23, in _wrapped_view
    return view_func(request, *args, **kwargs)
  File "/app/argus_final/venv/lib/python2.7/site-packages/django/views/generic/base.py", line 68, in view
    return self.dispatch(request, *args, **kwargs)
  File "/app/argus_final/app/argus/argus/mixins.py", line 14, in dispatch
    return super(GENERIC_PERMISSION_MIXIN, self).dispatch(request, *args, **kwargs)
  File "/app/argus_final/venv/lib/python2.7/site-packages/django/views/generic/base.py", line 88, in dispatch
    return handler(request, *args, **kwargs)
  File "/app/argus_final/app/argus/monitoring/views.py", line 40, in get
    context['data'] = ZABBIX.getAllEvents(daysfromnow=period)[-limit:]
  File "/app/argus_final/app/argus/global_objects/zabbix_api.py", line 121, in getAllEvents
    events = self.zapi.do_request('event.get',req)
  File "/app/argus_final/venv/lib/python2.7/site-packages/pyzabbix/api.py", line 251, in do_request
    res = urlopen(req)
  File "/app/argus_final/venv/lib/python2.7/site-packages/pyzabbix/api.py", line 117, in inner
    res = func(req)
  File "/app/argus_final/venv/lib/python2.7/site-packages/pyzabbix/api.py", line 126, in urlopen
    return urllib2.urlopen(*args, **kwargs)
  File "/usr/lib64/python2.7/urllib2.py", line 154, in urlopen
    return opener.open(url, data, timeout)
  File "/usr/lib64/python2.7/urllib2.py", line 431, in open
    response = self._open(req, data)
  File "/usr/lib64/python2.7/urllib2.py", line 449, in _open
    '_open', req)
  File "/usr/lib64/python2.7/urllib2.py", line 409, in _call_chain
    result = func(*args)
  File "/usr/lib64/python2.7/urllib2.py", line 1244, in http_open
    return self.do_open(httplib.HTTPConnection, req)
  File "/usr/lib64/python2.7/urllib2.py", line 1214, in do_open
    raise URLError(err)
URLError: <urlopen error [Errno 110] Connection timed out>
2020-07-24 14:12:16,121 ERROR - Internal Server Error: /monitoring/
Traceback (most recent call last):
  File "/app/argus_final/venv/lib/python2.7/site-packages/django/core/handlers/exception.py", line 41, in inner
    response = get_response(request)
  File "/app/argus_final/venv/lib/python2.7/site-packages/django/core/handlers/base.py", line 187, in _get_response
    response = self.process_exception_by_middleware(e, request)
  File "/app/argus_final/venv/lib/python2.7/site-packages/django/core/handlers/base.py", line 185, in _get_response
    response = wrapped_callback(request, *callback_args, **callback_kwargs)
  File "/app/argus_final/venv/lib/python2.7/site-packages/django/contrib/auth/decorators.py", line 23, in _wrapped_view
    return view_func(request, *args, **kwargs)
  File "/app/argus_final/venv/lib/python2.7/site-packages/django/views/generic/base.py", line 68, in view
    return self.dispatch(request, *args, **kwargs)
  File "/app/argus_final/app/argus/argus/mixins.py", line 14, in dispatch
    return super(GENERIC_PERMISSION_MIXIN, self).dispatch(request, *args, **kwargs)
  File "/app/argus_final/venv/lib/python2.7/site-packages/django/views/generic/base.py", line 88, in dispatch
    return handler(request, *args, **kwargs)
  File "/app/argus_final/app/argus/monitoring/views.py", line 40, in get
    context['data'] = ZABBIX.getAllEvents(daysfromnow=period)[-limit:]
  File "/app/argus_final/app/argus/global_objects/zabbix_api.py", line 121, in getAllEvents
    events = self.zapi.do_request('event.get',req)
  File "/app/argus_final/venv/lib/python2.7/site-packages/pyzabbix/api.py", line 251, in do_request
    res = urlopen(req)
  File "/app/argus_final/venv/lib/python2.7/site-packages/pyzabbix/api.py", line 117, in inner
    res = func(req)
  File "/app/argus_final/venv/lib/python2.7/site-packages/pyzabbix/api.py", line 126, in urlopen
    return urllib2.urlopen(*args, **kwargs)
  File "/usr/lib64/python2.7/urllib2.py", line 154, in urlopen
    return opener.open(url, data, timeout)
  File "/usr/lib64/python2.7/urllib2.py", line 431, in open
    response = self._open(req, data)
  File "/usr/lib64/python2.7/urllib2.py", line 449, in _open
    '_open', req)
  File "/usr/lib64/python2.7/urllib2.py", line 409, in _call_chain
    result = func(*args)
  File "/usr/lib64/python2.7/urllib2.py", line 1244, in http_open
    return self.do_open(httplib.HTTPConnection, req)
  File "/usr/lib64/python2.7/urllib2.py", line 1214, in do_open
    raise URLError(err)
URLError: <urlopen error [Errno 110] Connection timed out>
2020-07-24 14:12:32,497 ERROR - Internal Server Error: /monitoring/
Traceback (most recent call last):
  File "/app/argus_final/venv/lib/python2.7/site-packages/django/core/handlers/exception.py", line 41, in inner
    response = get_response(request)
  File "/app/argus_final/venv/lib/python2.7/site-packages/django/core/handlers/base.py", line 187, in _get_response
    response = self.process_exception_by_middleware(e, request)
  File "/app/argus_final/venv/lib/python2.7/site-packages/django/core/handlers/base.py", line 185, in _get_response
    response = wrapped_callback(request, *callback_args, **callback_kwargs)
  File "/app/argus_final/venv/lib/python2.7/site-packages/django/contrib/auth/decorators.py", line 23, in _wrapped_view
    return view_func(request, *args, **kwargs)
  File "/app/argus_final/venv/lib/python2.7/site-packages/django/views/generic/base.py", line 68, in view
    return self.dispatch(request, *args, **kwargs)
  File "/app/argus_final/app/argus/argus/mixins.py", line 14, in dispatch
    return super(GENERIC_PERMISSION_MIXIN, self).dispatch(request, *args, **kwargs)
  File "/app/argus_final/venv/lib/python2.7/site-packages/django/views/generic/base.py", line 88, in dispatch
    return handler(request, *args, **kwargs)
  File "/app/argus_final/app/argus/monitoring/views.py", line 40, in get
    context['data'] = ZABBIX.getAllEvents(daysfromnow=period)[-limit:]
  File "/app/argus_final/app/argus/global_objects/zabbix_api.py", line 121, in getAllEvents
    events = self.zapi.do_request('event.get',req)
  File "/app/argus_final/venv/lib/python2.7/site-packages/pyzabbix/api.py", line 251, in do_request
    res = urlopen(req)
  File "/app/argus_final/venv/lib/python2.7/site-packages/pyzabbix/api.py", line 117, in inner
    res = func(req)
  File "/app/argus_final/venv/lib/python2.7/site-packages/pyzabbix/api.py", line 126, in urlopen
    return urllib2.urlopen(*args, **kwargs)
  File "/usr/lib64/python2.7/urllib2.py", line 154, in urlopen
    return opener.open(url, data, timeout)
  File "/usr/lib64/python2.7/urllib2.py", line 431, in open
    response = self._open(req, data)
  File "/usr/lib64/python2.7/urllib2.py", line 449, in _open
    '_open', req)
  File "/usr/lib64/python2.7/urllib2.py", line 409, in _call_chain
    result = func(*args)
  File "/usr/lib64/python2.7/urllib2.py", line 1244, in http_open
    return self.do_open(httplib.HTTPConnection, req)
  File "/usr/lib64/python2.7/urllib2.py", line 1214, in do_open
    raise URLError(err)
URLError: <urlopen error [Errno 110] Connection timed out>
2020-07-24 14:12:49,197 ERROR - Internal Server Error: /monitoring/
Traceback (most recent call last):
  File "/app/argus_final/venv/lib/python2.7/site-packages/django/core/handlers/exception.py", line 41, in inner
    response = get_response(request)
  File "/app/argus_final/venv/lib/python2.7/site-packages/django/core/handlers/base.py", line 187, in _get_response
    response = self.process_exception_by_middleware(e, request)
  File "/app/argus_final/venv/lib/python2.7/site-packages/django/core/handlers/base.py", line 185, in _get_response
    response = wrapped_callback(request, *callback_args, **callback_kwargs)
  File "/app/argus_final/venv/lib/python2.7/site-packages/django/contrib/auth/decorators.py", line 23, in _wrapped_view
    return view_func(request, *args, **kwargs)
  File "/app/argus_final/venv/lib/python2.7/site-packages/django/views/generic/base.py", line 68, in view
    return self.dispatch(request, *args, **kwargs)
  File "/app/argus_final/app/argus/argus/mixins.py", line 14, in dispatch
    return super(GENERIC_PERMISSION_MIXIN, self).dispatch(request, *args, **kwargs)
  File "/app/argus_final/venv/lib/python2.7/site-packages/django/views/generic/base.py", line 88, in dispatch
    return handler(request, *args, **kwargs)
  File "/app/argus_final/app/argus/monitoring/views.py", line 30, in get
    context['data'] = ZABBIX.getAllTriggeredTriggers()
  File "/app/argus_final/app/argus/global_objects/zabbix_api.py", line 80, in getAllTriggeredTriggers
    triggers = self.zapi.do_request('trigger.get',req)
  File "/app/argus_final/venv/lib/python2.7/site-packages/pyzabbix/api.py", line 251, in do_request
    res = urlopen(req)
  File "/app/argus_final/venv/lib/python2.7/site-packages/pyzabbix/api.py", line 117, in inner
    res = func(req)
  File "/app/argus_final/venv/lib/python2.7/site-packages/pyzabbix/api.py", line 126, in urlopen
    return urllib2.urlopen(*args, **kwargs)
  File "/usr/lib64/python2.7/urllib2.py", line 154, in urlopen
    return opener.open(url, data, timeout)
  File "/usr/lib64/python2.7/urllib2.py", line 431, in open
    response = self._open(req, data)
  File "/usr/lib64/python2.7/urllib2.py", line 449, in _open
    '_open', req)
  File "/usr/lib64/python2.7/urllib2.py", line 409, in _call_chain
    result = func(*args)
  File "/usr/lib64/python2.7/urllib2.py", line 1244, in http_open
    return self.do_open(httplib.HTTPConnection, req)
  File "/usr/lib64/python2.7/urllib2.py", line 1214, in do_open
    raise URLError(err)
URLError: <urlopen error [Errno 110] Connection timed out>
2020-07-24 14:12:52,273 ERROR - Internal Server Error: /monitoring/
Traceback (most recent call last):
  File "/app/argus_final/venv/lib/python2.7/site-packages/django/core/handlers/exception.py", line 41, in inner
    response = get_response(request)
  File "/app/argus_final/venv/lib/python2.7/site-packages/django/core/handlers/base.py", line 187, in _get_response
    response = self.process_exception_by_middleware(e, request)
  File "/app/argus_final/venv/lib/python2.7/site-packages/django/core/handlers/base.py", line 185, in _get_response
    response = wrapped_callback(request, *callback_args, **callback_kwargs)
  File "/app/argus_final/venv/lib/python2.7/site-packages/django/contrib/auth/decorators.py", line 23, in _wrapped_view
    return view_func(request, *args, **kwargs)
  File "/app/argus_final/venv/lib/python2.7/site-packages/django/views/generic/base.py", line 68, in view
    return self.dispatch(request, *args, **kwargs)
  File "/app/argus_final/app/argus/argus/mixins.py", line 14, in dispatch
    return super(GENERIC_PERMISSION_MIXIN, self).dispatch(request, *args, **kwargs)
  File "/app/argus_final/venv/lib/python2.7/site-packages/django/views/generic/base.py", line 88, in dispatch
    return handler(request, *args, **kwargs)
  File "/app/argus_final/app/argus/monitoring/views.py", line 40, in get
    context['data'] = ZABBIX.getAllEvents(daysfromnow=period)[-limit:]
  File "/app/argus_final/app/argus/global_objects/zabbix_api.py", line 121, in getAllEvents
    events = self.zapi.do_request('event.get',req)
  File "/app/argus_final/venv/lib/python2.7/site-packages/pyzabbix/api.py", line 251, in do_request
    res = urlopen(req)
  File "/app/argus_final/venv/lib/python2.7/site-packages/pyzabbix/api.py", line 117, in inner
    res = func(req)
  File "/app/argus_final/venv/lib/python2.7/site-packages/pyzabbix/api.py", line 126, in urlopen
    return urllib2.urlopen(*args, **kwargs)
  File "/usr/lib64/python2.7/urllib2.py", line 154, in urlopen
    return opener.open(url, data, timeout)
  File "/usr/lib64/python2.7/urllib2.py", line 431, in open
    response = self._open(req, data)
  File "/usr/lib64/python2.7/urllib2.py", line 449, in _open
    '_open', req)
  File "/usr/lib64/python2.7/urllib2.py", line 409, in _call_chain
    result = func(*args)
  File "/usr/lib64/python2.7/urllib2.py", line 1244, in http_open
    return self.do_open(httplib.HTTPConnection, req)
  File "/usr/lib64/python2.7/urllib2.py", line 1214, in do_open
    raise URLError(err)
URLError: <urlopen error [Errno 110] Connection timed out>
2020-07-24 14:13:05,349 ERROR - Internal Server Error: /monitoring/
Traceback (most recent call last):
  File "/app/argus_final/venv/lib/python2.7/site-packages/django/core/handlers/exception.py", line 41, in inner
    response = get_response(request)
  File "/app/argus_final/venv/lib/python2.7/site-packages/django/core/handlers/base.py", line 187, in _get_response
    response = self.process_exception_by_middleware(e, request)
  File "/app/argus_final/venv/lib/python2.7/site-packages/django/core/handlers/base.py", line 185, in _get_response
    response = wrapped_callback(request, *callback_args, **callback_kwargs)
  File "/app/argus_final/venv/lib/python2.7/site-packages/django/contrib/auth/decorators.py", line 23, in _wrapped_view
    return view_func(request, *args, **kwargs)
  File "/app/argus_final/venv/lib/python2.7/site-packages/django/views/generic/base.py", line 68, in view
    return self.dispatch(request, *args, **kwargs)
  File "/app/argus_final/app/argus/argus/mixins.py", line 14, in dispatch
    return super(GENERIC_PERMISSION_MIXIN, self).dispatch(request, *args, **kwargs)
  File "/app/argus_final/venv/lib/python2.7/site-packages/django/views/generic/base.py", line 88, in dispatch
    return handler(request, *args, **kwargs)
  File "/app/argus_final/app/argus/monitoring/views.py", line 30, in get
    context['data'] = ZABBIX.getAllTriggeredTriggers()
  File "/app/argus_final/app/argus/global_objects/zabbix_api.py", line 80, in getAllTriggeredTriggers
    triggers = self.zapi.do_request('trigger.get',req)
  File "/app/argus_final/venv/lib/python2.7/site-packages/pyzabbix/api.py", line 251, in do_request
    res = urlopen(req)
  File "/app/argus_final/venv/lib/python2.7/site-packages/pyzabbix/api.py", line 117, in inner
    res = func(req)
  File "/app/argus_final/venv/lib/python2.7/site-packages/pyzabbix/api.py", line 126, in urlopen
    return urllib2.urlopen(*args, **kwargs)
  File "/usr/lib64/python2.7/urllib2.py", line 154, in urlopen
    return opener.open(url, data, timeout)
  File "/usr/lib64/python2.7/urllib2.py", line 431, in open
    response = self._open(req, data)
  File "/usr/lib64/python2.7/urllib2.py", line 449, in _open
    '_open', req)
  File "/usr/lib64/python2.7/urllib2.py", line 409, in _call_chain
    result = func(*args)
  File "/usr/lib64/python2.7/urllib2.py", line 1244, in http_open
    return self.do_open(httplib.HTTPConnection, req)
  File "/usr/lib64/python2.7/urllib2.py", line 1214, in do_open
    raise URLError(err)
URLError: <urlopen error [Errno 110] Connection timed out>
2020-07-24 14:13:05,657 ERROR - Internal Server Error: /monitoring/
Traceback (most recent call last):
  File "/app/argus_final/venv/lib/python2.7/site-packages/django/core/handlers/exception.py", line 41, in inner
    response = get_response(request)
  File "/app/argus_final/venv/lib/python2.7/site-packages/django/core/handlers/base.py", line 187, in _get_response
    response = self.process_exception_by_middleware(e, request)
  File "/app/argus_final/venv/lib/python2.7/site-packages/django/core/handlers/base.py", line 185, in _get_response
    response = wrapped_callback(request, *callback_args, **callback_kwargs)
  File "/app/argus_final/venv/lib/python2.7/site-packages/django/contrib/auth/decorators.py", line 23, in _wrapped_view
    return view_func(request, *args, **kwargs)
  File "/app/argus_final/venv/lib/python2.7/site-packages/django/views/generic/base.py", line 68, in view
    return self.dispatch(request, *args, **kwargs)
  File "/app/argus_final/app/argus/argus/mixins.py", line 14, in dispatch
    return super(GENERIC_PERMISSION_MIXIN, self).dispatch(request, *args, **kwargs)
  File "/app/argus_final/venv/lib/python2.7/site-packages/django/views/generic/base.py", line 88, in dispatch
    return handler(request, *args, **kwargs)
  File "/app/argus_final/app/argus/monitoring/views.py", line 30, in get
    context['data'] = ZABBIX.getAllTriggeredTriggers()
  File "/app/argus_final/app/argus/global_objects/zabbix_api.py", line 80, in getAllTriggeredTriggers
    triggers = self.zapi.do_request('trigger.get',req)
  File "/app/argus_final/venv/lib/python2.7/site-packages/pyzabbix/api.py", line 251, in do_request
    res = urlopen(req)
  File "/app/argus_final/venv/lib/python2.7/site-packages/pyzabbix/api.py", line 117, in inner
    res = func(req)
  File "/app/argus_final/venv/lib/python2.7/site-packages/pyzabbix/api.py", line 126, in urlopen
    return urllib2.urlopen(*args, **kwargs)
  File "/usr/lib64/python2.7/urllib2.py", line 154, in urlopen
    return opener.open(url, data, timeout)
  File "/usr/lib64/python2.7/urllib2.py", line 431, in open
    response = self._open(req, data)
  File "/usr/lib64/python2.7/urllib2.py", line 449, in _open
    '_open', req)
  File "/usr/lib64/python2.7/urllib2.py", line 409, in _call_chain
    result = func(*args)
  File "/usr/lib64/python2.7/urllib2.py", line 1244, in http_open
    return self.do_open(httplib.HTTPConnection, req)
  File "/usr/lib64/python2.7/urllib2.py", line 1214, in do_open
    raise URLError(err)
URLError: <urlopen error [Errno 110] Connection timed out>
2020-07-24 14:13:08,417 ERROR - Internal Server Error: /monitoring/
Traceback (most recent call last):
  File "/app/argus_final/venv/lib/python2.7/site-packages/django/core/handlers/exception.py", line 41, in inner
    response = get_response(request)
  File "/app/argus_final/venv/lib/python2.7/site-packages/django/core/handlers/base.py", line 187, in _get_response
    response = self.process_exception_by_middleware(e, request)
  File "/app/argus_final/venv/lib/python2.7/site-packages/django/core/handlers/base.py", line 185, in _get_response
    response = wrapped_callback(request, *callback_args, **callback_kwargs)
  File "/app/argus_final/venv/lib/python2.7/site-packages/django/contrib/auth/decorators.py", line 23, in _wrapped_view
    return view_func(request, *args, **kwargs)
  File "/app/argus_final/venv/lib/python2.7/site-packages/django/views/generic/base.py", line 68, in view
    return self.dispatch(request, *args, **kwargs)
  File "/app/argus_final/app/argus/argus/mixins.py", line 14, in dispatch
    return super(GENERIC_PERMISSION_MIXIN, self).dispatch(request, *args, **kwargs)
  File "/app/argus_final/venv/lib/python2.7/site-packages/django/views/generic/base.py", line 88, in dispatch
    return handler(request, *args, **kwargs)
  File "/app/argus_final/app/argus/monitoring/views.py", line 40, in get
    context['data'] = ZABBIX.getAllEvents(daysfromnow=period)[-limit:]
  File "/app/argus_final/app/argus/global_objects/zabbix_api.py", line 121, in getAllEvents
    events = self.zapi.do_request('event.get',req)
  File "/app/argus_final/venv/lib/python2.7/site-packages/pyzabbix/api.py", line 251, in do_request
    res = urlopen(req)
  File "/app/argus_final/venv/lib/python2.7/site-packages/pyzabbix/api.py", line 117, in inner
    res = func(req)
  File "/app/argus_final/venv/lib/python2.7/site-packages/pyzabbix/api.py", line 126, in urlopen
    return urllib2.urlopen(*args, **kwargs)
  File "/usr/lib64/python2.7/urllib2.py", line 154, in urlopen
    return opener.open(url, data, timeout)
  File "/usr/lib64/python2.7/urllib2.py", line 431, in open
    response = self._open(req, data)
  File "/usr/lib64/python2.7/urllib2.py", line 449, in _open
    '_open', req)
  File "/usr/lib64/python2.7/urllib2.py", line 409, in _call_chain
    result = func(*args)
  File "/usr/lib64/python2.7/urllib2.py", line 1244, in http_open
    return self.do_open(httplib.HTTPConnection, req)
  File "/usr/lib64/python2.7/urllib2.py", line 1214, in do_open
    raise URLError(err)
URLError: <urlopen error [Errno 110] Connection timed out>
2020-07-24 14:13:28,425 ERROR - Internal Server Error: /monitoring/
Traceback (most recent call last):
  File "/app/argus_final/venv/lib/python2.7/site-packages/django/core/handlers/exception.py", line 41, in inner
    response = get_response(request)
  File "/app/argus_final/venv/lib/python2.7/site-packages/django/core/handlers/base.py", line 187, in _get_response
    response = self.process_exception_by_middleware(e, request)
  File "/app/argus_final/venv/lib/python2.7/site-packages/django/core/handlers/base.py", line 185, in _get_response
    response = wrapped_callback(request, *callback_args, **callback_kwargs)
  File "/app/argus_final/venv/lib/python2.7/site-packages/django/contrib/auth/decorators.py", line 23, in _wrapped_view
    return view_func(request, *args, **kwargs)
  File "/app/argus_final/venv/lib/python2.7/site-packages/django/views/generic/base.py", line 68, in view
    return self.dispatch(request, *args, **kwargs)
  File "/app/argus_final/app/argus/argus/mixins.py", line 14, in dispatch
    return super(GENERIC_PERMISSION_MIXIN, self).dispatch(request, *args, **kwargs)
  File "/app/argus_final/venv/lib/python2.7/site-packages/django/views/generic/base.py", line 88, in dispatch
    return handler(request, *args, **kwargs)
  File "/app/argus_final/app/argus/monitoring/views.py", line 40, in get
    context['data'] = ZABBIX.getAllEvents(daysfromnow=period)[-limit:]
  File "/app/argus_final/app/argus/global_objects/zabbix_api.py", line 121, in getAllEvents
    events = self.zapi.do_request('event.get',req)
  File "/app/argus_final/venv/lib/python2.7/site-packages/pyzabbix/api.py", line 251, in do_request
    res = urlopen(req)
  File "/app/argus_final/venv/lib/python2.7/site-packages/pyzabbix/api.py", line 117, in inner
    res = func(req)
  File "/app/argus_final/venv/lib/python2.7/site-packages/pyzabbix/api.py", line 126, in urlopen
    return urllib2.urlopen(*args, **kwargs)
  File "/usr/lib64/python2.7/urllib2.py", line 154, in urlopen
    return opener.open(url, data, timeout)
  File "/usr/lib64/python2.7/urllib2.py", line 431, in open
    response = self._open(req, data)
  File "/usr/lib64/python2.7/urllib2.py", line 449, in _open
    '_open', req)
  File "/usr/lib64/python2.7/urllib2.py", line 409, in _call_chain
    result = func(*args)
  File "/usr/lib64/python2.7/urllib2.py", line 1244, in http_open
    return self.do_open(httplib.HTTPConnection, req)
  File "/usr/lib64/python2.7/urllib2.py", line 1214, in do_open
    raise URLError(err)
URLError: <urlopen error [Errno 110] Connection timed out>
2020-07-24 14:13:41,913 ERROR - Internal Server Error: /monitoring/
Traceback (most recent call last):
  File "/app/argus_final/venv/lib/python2.7/site-packages/django/core/handlers/exception.py", line 41, in inner
    response = get_response(request)
  File "/app/argus_final/venv/lib/python2.7/site-packages/django/core/handlers/base.py", line 187, in _get_response
    response = self.process_exception_by_middleware(e, request)
  File "/app/argus_final/venv/lib/python2.7/site-packages/django/core/handlers/base.py", line 185, in _get_response
    response = wrapped_callback(request, *callback_args, **callback_kwargs)
  File "/app/argus_final/venv/lib/python2.7/site-packages/django/contrib/auth/decorators.py", line 23, in _wrapped_view
    return view_func(request, *args, **kwargs)
  File "/app/argus_final/venv/lib/python2.7/site-packages/django/views/generic/base.py", line 68, in view
    return self.dispatch(request, *args, **kwargs)
  File "/app/argus_final/app/argus/argus/mixins.py", line 14, in dispatch
    return super(GENERIC_PERMISSION_MIXIN, self).dispatch(request, *args, **kwargs)
  File "/app/argus_final/venv/lib/python2.7/site-packages/django/views/generic/base.py", line 88, in dispatch
    return handler(request, *args, **kwargs)
  File "/app/argus_final/app/argus/monitoring/views.py", line 30, in get
    context['data'] = ZABBIX.getAllTriggeredTriggers()
  File "/app/argus_final/app/argus/global_objects/zabbix_api.py", line 80, in getAllTriggeredTriggers
    triggers = self.zapi.do_request('trigger.get',req)
  File "/app/argus_final/venv/lib/python2.7/site-packages/pyzabbix/api.py", line 251, in do_request
    res = urlopen(req)
  File "/app/argus_final/venv/lib/python2.7/site-packages/pyzabbix/api.py", line 117, in inner
    res = func(req)
  File "/app/argus_final/venv/lib/python2.7/site-packages/pyzabbix/api.py", line 126, in urlopen
    return urllib2.urlopen(*args, **kwargs)
  File "/usr/lib64/python2.7/urllib2.py", line 154, in urlopen
    return opener.open(url, data, timeout)
  File "/usr/lib64/python2.7/urllib2.py", line 431, in open
    response = self._open(req, data)
  File "/usr/lib64/python2.7/urllib2.py", line 449, in _open
    '_open', req)
  File "/usr/lib64/python2.7/urllib2.py", line 409, in _call_chain
    result = func(*args)
  File "/usr/lib64/python2.7/urllib2.py", line 1244, in http_open
    return self.do_open(httplib.HTTPConnection, req)
  File "/usr/lib64/python2.7/urllib2.py", line 1214, in do_open
    raise URLError(err)
URLError: <urlopen error [Errno 110] Connection timed out>
2020-07-24 14:13:45,037 ERROR - Internal Server Error: /monitoring/
Traceback (most recent call last):
  File "/app/argus_final/venv/lib/python2.7/site-packages/django/core/handlers/exception.py", line 41, in inner
    response = get_response(request)
  File "/app/argus_final/venv/lib/python2.7/site-packages/django/core/handlers/base.py", line 187, in _get_response
    response = self.process_exception_by_middleware(e, request)
  File "/app/argus_final/venv/lib/python2.7/site-packages/django/core/handlers/base.py", line 185, in _get_response
    response = wrapped_callback(request, *callback_args, **callback_kwargs)
  File "/app/argus_final/venv/lib/python2.7/site-packages/django/contrib/auth/decorators.py", line 23, in _wrapped_view
    return view_func(request, *args, **kwargs)
  File "/app/argus_final/venv/lib/python2.7/site-packages/django/views/generic/base.py", line 68, in view
    return self.dispatch(request, *args, **kwargs)
  File "/app/argus_final/app/argus/argus/mixins.py", line 14, in dispatch
    return super(GENERIC_PERMISSION_MIXIN, self).dispatch(request, *args, **kwargs)
  File "/app/argus_final/venv/lib/python2.7/site-packages/django/views/generic/base.py", line 88, in dispatch
    return handler(request, *args, **kwargs)
  File "/app/argus_final/app/argus/monitoring/views.py", line 40, in get
    context['data'] = ZABBIX.getAllEvents(daysfromnow=period)[-limit:]
  File "/app/argus_final/app/argus/global_objects/zabbix_api.py", line 121, in getAllEvents
    events = self.zapi.do_request('event.get',req)
  File "/app/argus_final/venv/lib/python2.7/site-packages/pyzabbix/api.py", line 251, in do_request
    res = urlopen(req)
  File "/app/argus_final/venv/lib/python2.7/site-packages/pyzabbix/api.py", line 117, in inner
    res = func(req)
  File "/app/argus_final/venv/lib/python2.7/site-packages/pyzabbix/api.py", line 126, in urlopen
    return urllib2.urlopen(*args, **kwargs)
  File "/usr/lib64/python2.7/urllib2.py", line 154, in urlopen
    return opener.open(url, data, timeout)
  File "/usr/lib64/python2.7/urllib2.py", line 431, in open
    response = self._open(req, data)
  File "/usr/lib64/python2.7/urllib2.py", line 449, in _open
    '_open', req)
  File "/usr/lib64/python2.7/urllib2.py", line 409, in _call_chain
    result = func(*args)
  File "/usr/lib64/python2.7/urllib2.py", line 1244, in http_open
    return self.do_open(httplib.HTTPConnection, req)
  File "/usr/lib64/python2.7/urllib2.py", line 1214, in do_open
    raise URLError(err)
URLError: <urlopen error [Errno 110] Connection timed out>
2020-07-24 14:13:45,421 ERROR - Internal Server Error: /monitoring/
Traceback (most recent call last):
  File "/app/argus_final/venv/lib/python2.7/site-packages/django/core/handlers/exception.py", line 41, in inner
    response = get_response(request)
  File "/app/argus_final/venv/lib/python2.7/site-packages/django/core/handlers/base.py", line 187, in _get_response
    response = self.process_exception_by_middleware(e, request)
  File "/app/argus_final/venv/lib/python2.7/site-packages/django/core/handlers/base.py", line 185, in _get_response
    response = wrapped_callback(request, *callback_args, **callback_kwargs)
  File "/app/argus_final/venv/lib/python2.7/site-packages/django/contrib/auth/decorators.py", line 23, in _wrapped_view
    return view_func(request, *args, **kwargs)
  File "/app/argus_final/venv/lib/python2.7/site-packages/django/views/generic/base.py", line 68, in view
    return self.dispatch(request, *args, **kwargs)
  File "/app/argus_final/app/argus/argus/mixins.py", line 14, in dispatch
    return super(GENERIC_PERMISSION_MIXIN, self).dispatch(request, *args, **kwargs)
  File "/app/argus_final/venv/lib/python2.7/site-packages/django/views/generic/base.py", line 88, in dispatch
    return handler(request, *args, **kwargs)
  File "/app/argus_final/app/argus/monitoring/views.py", line 40, in get
    context['data'] = ZABBIX.getAllEvents(daysfromnow=period)[-limit:]
  File "/app/argus_final/app/argus/global_objects/zabbix_api.py", line 121, in getAllEvents
    events = self.zapi.do_request('event.get',req)
  File "/app/argus_final/venv/lib/python2.7/site-packages/pyzabbix/api.py", line 251, in do_request
    res = urlopen(req)
  File "/app/argus_final/venv/lib/python2.7/site-packages/pyzabbix/api.py", line 117, in inner
    res = func(req)
  File "/app/argus_final/venv/lib/python2.7/site-packages/pyzabbix/api.py", line 126, in urlopen
    return urllib2.urlopen(*args, **kwargs)
  File "/usr/lib64/python2.7/urllib2.py", line 154, in urlopen
    return opener.open(url, data, timeout)
  File "/usr/lib64/python2.7/urllib2.py", line 431, in open
    response = self._open(req, data)
  File "/usr/lib64/python2.7/urllib2.py", line 449, in _open
    '_open', req)
  File "/usr/lib64/python2.7/urllib2.py", line 409, in _call_chain
    result = func(*args)
  File "/usr/lib64/python2.7/urllib2.py", line 1244, in http_open
    return self.do_open(httplib.HTTPConnection, req)
  File "/usr/lib64/python2.7/urllib2.py", line 1214, in do_open
    raise URLError(err)
URLError: <urlopen error [Errno 110] Connection timed out>
2020-07-24 14:14:01,501 ERROR - Internal Server Error: /monitoring/
Traceback (most recent call last):
  File "/app/argus_final/venv/lib/python2.7/site-packages/django/core/handlers/exception.py", line 41, in inner
    response = get_response(request)
  File "/app/argus_final/venv/lib/python2.7/site-packages/django/core/handlers/base.py", line 187, in _get_response
    response = self.process_exception_by_middleware(e, request)
  File "/app/argus_final/venv/lib/python2.7/site-packages/django/core/handlers/base.py", line 185, in _get_response
    response = wrapped_callback(request, *callback_args, **callback_kwargs)
  File "/app/argus_final/venv/lib/python2.7/site-packages/django/contrib/auth/decorators.py", line 23, in _wrapped_view
    return view_func(request, *args, **kwargs)
  File "/app/argus_final/venv/lib/python2.7/site-packages/django/views/generic/base.py", line 68, in view
    return self.dispatch(request, *args, **kwargs)
  File "/app/argus_final/app/argus/argus/mixins.py", line 14, in dispatch
    return super(GENERIC_PERMISSION_MIXIN, self).dispatch(request, *args, **kwargs)
  File "/app/argus_final/venv/lib/python2.7/site-packages/django/views/generic/base.py", line 88, in dispatch
    return handler(request, *args, **kwargs)
  File "/app/argus_final/app/argus/monitoring/views.py", line 30, in get
    context['data'] = ZABBIX.getAllTriggeredTriggers()
  File "/app/argus_final/app/argus/global_objects/zabbix_api.py", line 80, in getAllTriggeredTriggers
    triggers = self.zapi.do_request('trigger.get',req)
  File "/app/argus_final/venv/lib/python2.7/site-packages/pyzabbix/api.py", line 251, in do_request
    res = urlopen(req)
  File "/app/argus_final/venv/lib/python2.7/site-packages/pyzabbix/api.py", line 117, in inner
    res = func(req)
  File "/app/argus_final/venv/lib/python2.7/site-packages/pyzabbix/api.py", line 126, in urlopen
    return urllib2.urlopen(*args, **kwargs)
  File "/usr/lib64/python2.7/urllib2.py", line 154, in urlopen
    return opener.open(url, data, timeout)
  File "/usr/lib64/python2.7/urllib2.py", line 431, in open
    response = self._open(req, data)
  File "/usr/lib64/python2.7/urllib2.py", line 449, in _open
    '_open', req)
  File "/usr/lib64/python2.7/urllib2.py", line 409, in _call_chain
    result = func(*args)
  File "/usr/lib64/python2.7/urllib2.py", line 1244, in http_open
    return self.do_open(httplib.HTTPConnection, req)
  File "/usr/lib64/python2.7/urllib2.py", line 1214, in do_open
    raise URLError(err)
URLError: <urlopen error [Errno 110] Connection timed out>
2020-07-24 14:14:04,577 ERROR - Internal Server Error: /monitoring/
Traceback (most recent call last):
  File "/app/argus_final/venv/lib/python2.7/site-packages/django/core/handlers/exception.py", line 41, in inner
    response = get_response(request)
  File "/app/argus_final/venv/lib/python2.7/site-packages/django/core/handlers/base.py", line 187, in _get_response
    response = self.process_exception_by_middleware(e, request)
  File "/app/argus_final/venv/lib/python2.7/site-packages/django/core/handlers/base.py", line 185, in _get_response
    response = wrapped_callback(request, *callback_args, **callback_kwargs)
  File "/app/argus_final/venv/lib/python2.7/site-packages/django/contrib/auth/decorators.py", line 23, in _wrapped_view
    return view_func(request, *args, **kwargs)
  File "/app/argus_final/venv/lib/python2.7/site-packages/django/views/generic/base.py", line 68, in view
    return self.dispatch(request, *args, **kwargs)
  File "/app/argus_final/app/argus/argus/mixins.py", line 14, in dispatch
    return super(GENERIC_PERMISSION_MIXIN, self).dispatch(request, *args, **kwargs)
  File "/app/argus_final/venv/lib/python2.7/site-packages/django/views/generic/base.py", line 88, in dispatch
    return handler(request, *args, **kwargs)
  File "/app/argus_final/app/argus/monitoring/views.py", line 40, in get
    context['data'] = ZABBIX.getAllEvents(daysfromnow=period)[-limit:]
  File "/app/argus_final/app/argus/global_objects/zabbix_api.py", line 121, in getAllEvents
    events = self.zapi.do_request('event.get',req)
  File "/app/argus_final/venv/lib/python2.7/site-packages/pyzabbix/api.py", line 251, in do_request
    res = urlopen(req)
  File "/app/argus_final/venv/lib/python2.7/site-packages/pyzabbix/api.py", line 117, in inner
    res = func(req)
  File "/app/argus_final/venv/lib/python2.7/site-packages/pyzabbix/api.py", line 126, in urlopen
    return urllib2.urlopen(*args, **kwargs)
  File "/usr/lib64/python2.7/urllib2.py", line 154, in urlopen
    return opener.open(url, data, timeout)
  File "/usr/lib64/python2.7/urllib2.py", line 431, in open
    response = self._open(req, data)
  File "/usr/lib64/python2.7/urllib2.py", line 449, in _open
    '_open', req)
  File "/usr/lib64/python2.7/urllib2.py", line 409, in _call_chain
    result = func(*args)
  File "/usr/lib64/python2.7/urllib2.py", line 1244, in http_open
    return self.do_open(httplib.HTTPConnection, req)
  File "/usr/lib64/python2.7/urllib2.py", line 1214, in do_open
    raise URLError(err)
URLError: <urlopen error [Errno 110] Connection timed out>
2020-07-24 14:14:22,417 ERROR - Internal Server Error: /monitoring/
Traceback (most recent call last):
  File "/app/argus_final/venv/lib/python2.7/site-packages/django/core/handlers/exception.py", line 41, in inner
    response = get_response(request)
  File "/app/argus_final/venv/lib/python2.7/site-packages/django/core/handlers/base.py", line 187, in _get_response
    response = self.process_exception_by_middleware(e, request)
  File "/app/argus_final/venv/lib/python2.7/site-packages/django/core/handlers/base.py", line 185, in _get_response
    response = wrapped_callback(request, *callback_args, **callback_kwargs)
  File "/app/argus_final/venv/lib/python2.7/site-packages/django/contrib/auth/decorators.py", line 23, in _wrapped_view
    return view_func(request, *args, **kwargs)
  File "/app/argus_final/venv/lib/python2.7/site-packages/django/views/generic/base.py", line 68, in view
    return self.dispatch(request, *args, **kwargs)
  File "/app/argus_final/app/argus/argus/mixins.py", line 14, in dispatch
    return super(GENERIC_PERMISSION_MIXIN, self).dispatch(request, *args, **kwargs)
  File "/app/argus_final/venv/lib/python2.7/site-packages/django/views/generic/base.py", line 88, in dispatch
    return handler(request, *args, **kwargs)
  File "/app/argus_final/app/argus/monitoring/views.py", line 40, in get
    context['data'] = ZABBIX.getAllEvents(daysfromnow=period)[-limit:]
  File "/app/argus_final/app/argus/global_objects/zabbix_api.py", line 121, in getAllEvents
    events = self.zapi.do_request('event.get',req)
  File "/app/argus_final/venv/lib/python2.7/site-packages/pyzabbix/api.py", line 251, in do_request
    res = urlopen(req)
  File "/app/argus_final/venv/lib/python2.7/site-packages/pyzabbix/api.py", line 117, in inner
    res = func(req)
  File "/app/argus_final/venv/lib/python2.7/site-packages/pyzabbix/api.py", line 126, in urlopen
    return urllib2.urlopen(*args, **kwargs)
  File "/usr/lib64/python2.7/urllib2.py", line 154, in urlopen
    return opener.open(url, data, timeout)
  File "/usr/lib64/python2.7/urllib2.py", line 431, in open
    response = self._open(req, data)
  File "/usr/lib64/python2.7/urllib2.py", line 449, in _open
    '_open', req)
  File "/usr/lib64/python2.7/urllib2.py", line 409, in _call_chain
    result = func(*args)
  File "/usr/lib64/python2.7/urllib2.py", line 1244, in http_open
    return self.do_open(httplib.HTTPConnection, req)
  File "/usr/lib64/python2.7/urllib2.py", line 1214, in do_open
    raise URLError(err)
URLError: <urlopen error [Errno 110] Connection timed out>
2020-07-24 14:14:31,693 ERROR - Internal Server Error: /monitoring/
Traceback (most recent call last):
  File "/app/argus_final/venv/lib/python2.7/site-packages/django/core/handlers/exception.py", line 41, in inner
    response = get_response(request)
  File "/app/argus_final/venv/lib/python2.7/site-packages/django/core/handlers/base.py", line 187, in _get_response
    response = self.process_exception_by_middleware(e, request)
  File "/app/argus_final/venv/lib/python2.7/site-packages/django/core/handlers/base.py", line 185, in _get_response
    response = wrapped_callback(request, *callback_args, **callback_kwargs)
  File "/app/argus_final/venv/lib/python2.7/site-packages/django/contrib/auth/decorators.py", line 23, in _wrapped_view
    return view_func(request, *args, **kwargs)
  File "/app/argus_final/venv/lib/python2.7/site-packages/django/views/generic/base.py", line 68, in view
    return self.dispatch(request, *args, **kwargs)
  File "/app/argus_final/app/argus/argus/mixins.py", line 14, in dispatch
    return super(GENERIC_PERMISSION_MIXIN, self).dispatch(request, *args, **kwargs)
  File "/app/argus_final/venv/lib/python2.7/site-packages/django/views/generic/base.py", line 88, in dispatch
    return handler(request, *args, **kwargs)
  File "/app/argus_final/app/argus/monitoring/views.py", line 40, in get
    context['data'] = ZABBIX.getAllEvents(daysfromnow=period)[-limit:]
  File "/app/argus_final/app/argus/global_objects/zabbix_api.py", line 121, in getAllEvents
    events = self.zapi.do_request('event.get',req)
  File "/app/argus_final/venv/lib/python2.7/site-packages/pyzabbix/api.py", line 251, in do_request
    res = urlopen(req)
  File "/app/argus_final/venv/lib/python2.7/site-packages/pyzabbix/api.py", line 117, in inner
    res = func(req)
  File "/app/argus_final/venv/lib/python2.7/site-packages/pyzabbix/api.py", line 126, in urlopen
    return urllib2.urlopen(*args, **kwargs)
  File "/usr/lib64/python2.7/urllib2.py", line 154, in urlopen
    return opener.open(url, data, timeout)
  File "/usr/lib64/python2.7/urllib2.py", line 431, in open
    response = self._open(req, data)
  File "/usr/lib64/python2.7/urllib2.py", line 449, in _open
    '_open', req)
  File "/usr/lib64/python2.7/urllib2.py", line 409, in _call_chain
    result = func(*args)
  File "/usr/lib64/python2.7/urllib2.py", line 1244, in http_open
    return self.do_open(httplib.HTTPConnection, req)
  File "/usr/lib64/python2.7/urllib2.py", line 1214, in do_open
    raise URLError(err)
URLError: <urlopen error [Errno 110] Connection timed out>
2020-07-24 14:14:37,649 ERROR - Internal Server Error: /monitoring/
Traceback (most recent call last):
  File "/app/argus_final/venv/lib/python2.7/site-packages/django/core/handlers/exception.py", line 41, in inner
    response = get_response(request)
  File "/app/argus_final/venv/lib/python2.7/site-packages/django/core/handlers/base.py", line 187, in _get_response
    response = self.process_exception_by_middleware(e, request)
  File "/app/argus_final/venv/lib/python2.7/site-packages/django/core/handlers/base.py", line 185, in _get_response
    response = wrapped_callback(request, *callback_args, **callback_kwargs)
  File "/app/argus_final/venv/lib/python2.7/site-packages/django/contrib/auth/decorators.py", line 23, in _wrapped_view
    return view_func(request, *args, **kwargs)
  File "/app/argus_final/venv/lib/python2.7/site-packages/django/views/generic/base.py", line 68, in view
    return self.dispatch(request, *args, **kwargs)
  File "/app/argus_final/app/argus/argus/mixins.py", line 14, in dispatch
    return super(GENERIC_PERMISSION_MIXIN, self).dispatch(request, *args, **kwargs)
  File "/app/argus_final/venv/lib/python2.7/site-packages/django/views/generic/base.py", line 88, in dispatch
    return handler(request, *args, **kwargs)
  File "/app/argus_final/app/argus/monitoring/views.py", line 30, in get
    context['data'] = ZABBIX.getAllTriggeredTriggers()
  File "/app/argus_final/app/argus/global_objects/zabbix_api.py", line 80, in getAllTriggeredTriggers
    triggers = self.zapi.do_request('trigger.get',req)
  File "/app/argus_final/venv/lib/python2.7/site-packages/pyzabbix/api.py", line 251, in do_request
    res = urlopen(req)
  File "/app/argus_final/venv/lib/python2.7/site-packages/pyzabbix/api.py", line 117, in inner
    res = func(req)
  File "/app/argus_final/venv/lib/python2.7/site-packages/pyzabbix/api.py", line 126, in urlopen
    return urllib2.urlopen(*args, **kwargs)
  File "/usr/lib64/python2.7/urllib2.py", line 154, in urlopen
    return opener.open(url, data, timeout)
  File "/usr/lib64/python2.7/urllib2.py", line 431, in open
    response = self._open(req, data)
  File "/usr/lib64/python2.7/urllib2.py", line 449, in _open
    '_open', req)
  File "/usr/lib64/python2.7/urllib2.py", line 409, in _call_chain
    result = func(*args)
  File "/usr/lib64/python2.7/urllib2.py", line 1244, in http_open
    return self.do_open(httplib.HTTPConnection, req)
  File "/usr/lib64/python2.7/urllib2.py", line 1214, in do_open
    raise URLError(err)
URLError: <urlopen error [Errno 110] Connection timed out>
2020-07-24 14:14:40,717 ERROR - Internal Server Error: /monitoring/
Traceback (most recent call last):
  File "/app/argus_final/venv/lib/python2.7/site-packages/django/core/handlers/exception.py", line 41, in inner
    response = get_response(request)
  File "/app/argus_final/venv/lib/python2.7/site-packages/django/core/handlers/base.py", line 187, in _get_response
    response = self.process_exception_by_middleware(e, request)
  File "/app/argus_final/venv/lib/python2.7/site-packages/django/core/handlers/base.py", line 185, in _get_response
    response = wrapped_callback(request, *callback_args, **callback_kwargs)
  File "/app/argus_final/venv/lib/python2.7/site-packages/django/contrib/auth/decorators.py", line 23, in _wrapped_view
    return view_func(request, *args, **kwargs)
  File "/app/argus_final/venv/lib/python2.7/site-packages/django/views/generic/base.py", line 68, in view
    return self.dispatch(request, *args, **kwargs)
  File "/app/argus_final/app/argus/argus/mixins.py", line 14, in dispatch
    return super(GENERIC_PERMISSION_MIXIN, self).dispatch(request, *args, **kwargs)
  File "/app/argus_final/venv/lib/python2.7/site-packages/django/views/generic/base.py", line 88, in dispatch
    return handler(request, *args, **kwargs)
  File "/app/argus_final/app/argus/monitoring/views.py", line 40, in get
    context['data'] = ZABBIX.getAllEvents(daysfromnow=period)[-limit:]
  File "/app/argus_final/app/argus/global_objects/zabbix_api.py", line 121, in getAllEvents
    events = self.zapi.do_request('event.get',req)
  File "/app/argus_final/venv/lib/python2.7/site-packages/pyzabbix/api.py", line 251, in do_request
    res = urlopen(req)
  File "/app/argus_final/venv/lib/python2.7/site-packages/pyzabbix/api.py", line 117, in inner
    res = func(req)
  File "/app/argus_final/venv/lib/python2.7/site-packages/pyzabbix/api.py", line 126, in urlopen
    return urllib2.urlopen(*args, **kwargs)
  File "/usr/lib64/python2.7/urllib2.py", line 154, in urlopen
    return opener.open(url, data, timeout)
  File "/usr/lib64/python2.7/urllib2.py", line 431, in open
    response = self._open(req, data)
  File "/usr/lib64/python2.7/urllib2.py", line 449, in _open
    '_open', req)
  File "/usr/lib64/python2.7/urllib2.py", line 409, in _call_chain
    result = func(*args)
  File "/usr/lib64/python2.7/urllib2.py", line 1244, in http_open
    return self.do_open(httplib.HTTPConnection, req)
  File "/usr/lib64/python2.7/urllib2.py", line 1214, in do_open
    raise URLError(err)
URLError: <urlopen error [Errno 110] Connection timed out>
2020-07-24 14:14:56,369 ERROR - Internal Server Error: /monitoring/
Traceback (most recent call last):
  File "/app/argus_final/venv/lib/python2.7/site-packages/django/core/handlers/exception.py", line 41, in inner
    response = get_response(request)
  File "/app/argus_final/venv/lib/python2.7/site-packages/django/core/handlers/base.py", line 187, in _get_response
    response = self.process_exception_by_middleware(e, request)
  File "/app/argus_final/venv/lib/python2.7/site-packages/django/core/handlers/base.py", line 185, in _get_response
    response = wrapped_callback(request, *callback_args, **callback_kwargs)
  File "/app/argus_final/venv/lib/python2.7/site-packages/django/contrib/auth/decorators.py", line 23, in _wrapped_view
    return view_func(request, *args, **kwargs)
  File "/app/argus_final/venv/lib/python2.7/site-packages/django/views/generic/base.py", line 68, in view
    return self.dispatch(request, *args, **kwargs)
  File "/app/argus_final/app/argus/argus/mixins.py", line 14, in dispatch
    return super(GENERIC_PERMISSION_MIXIN, self).dispatch(request, *args, **kwargs)
  File "/app/argus_final/venv/lib/python2.7/site-packages/django/views/generic/base.py", line 88, in dispatch
    return handler(request, *args, **kwargs)
  File "/app/argus_final/app/argus/monitoring/views.py", line 30, in get
    context['data'] = ZABBIX.getAllTriggeredTriggers()
  File "/app/argus_final/app/argus/global_objects/zabbix_api.py", line 80, in getAllTriggeredTriggers
    triggers = self.zapi.do_request('trigger.get',req)
  File "/app/argus_final/venv/lib/python2.7/site-packages/pyzabbix/api.py", line 251, in do_request
    res = urlopen(req)
  File "/app/argus_final/venv/lib/python2.7/site-packages/pyzabbix/api.py", line 117, in inner
    res = func(req)
  File "/app/argus_final/venv/lib/python2.7/site-packages/pyzabbix/api.py", line 126, in urlopen
    return urllib2.urlopen(*args, **kwargs)
  File "/usr/lib64/python2.7/urllib2.py", line 154, in urlopen
    return opener.open(url, data, timeout)
  File "/usr/lib64/python2.7/urllib2.py", line 431, in open
    response = self._open(req, data)
  File "/usr/lib64/python2.7/urllib2.py", line 449, in _open
    '_open', req)
  File "/usr/lib64/python2.7/urllib2.py", line 409, in _call_chain
    result = func(*args)
  File "/usr/lib64/python2.7/urllib2.py", line 1244, in http_open
    return self.do_open(httplib.HTTPConnection, req)
  File "/usr/lib64/python2.7/urllib2.py", line 1214, in do_open
    raise URLError(err)
URLError: <urlopen error [Errno 110] Connection timed out>
2020-07-24 14:14:59,441 ERROR - Internal Server Error: /monitoring/
Traceback (most recent call last):
  File "/app/argus_final/venv/lib/python2.7/site-packages/django/core/handlers/exception.py", line 41, in inner
    response = get_response(request)
  File "/app/argus_final/venv/lib/python2.7/site-packages/django/core/handlers/base.py", line 187, in _get_response
    response = self.process_exception_by_middleware(e, request)
  File "/app/argus_final/venv/lib/python2.7/site-packages/django/core/handlers/base.py", line 185, in _get_response
    response = wrapped_callback(request, *callback_args, **callback_kwargs)
  File "/app/argus_final/venv/lib/python2.7/site-packages/django/contrib/auth/decorators.py", line 23, in _wrapped_view
    return view_func(request, *args, **kwargs)
  File "/app/argus_final/venv/lib/python2.7/site-packages/django/views/generic/base.py", line 68, in view
    return self.dispatch(request, *args, **kwargs)
  File "/app/argus_final/app/argus/argus/mixins.py", line 14, in dispatch
    return super(GENERIC_PERMISSION_MIXIN, self).dispatch(request, *args, **kwargs)
  File "/app/argus_final/venv/lib/python2.7/site-packages/django/views/generic/base.py", line 88, in dispatch
    return handler(request, *args, **kwargs)
  File "/app/argus_final/app/argus/monitoring/views.py", line 40, in get
    context['data'] = ZABBIX.getAllEvents(daysfromnow=period)[-limit:]
  File "/app/argus_final/app/argus/global_objects/zabbix_api.py", line 121, in getAllEvents
    events = self.zapi.do_request('event.get',req)
  File "/app/argus_final/venv/lib/python2.7/site-packages/pyzabbix/api.py", line 251, in do_request
    res = urlopen(req)
  File "/app/argus_final/venv/lib/python2.7/site-packages/pyzabbix/api.py", line 117, in inner
    res = func(req)
  File "/app/argus_final/venv/lib/python2.7/site-packages/pyzabbix/api.py", line 126, in urlopen
    return urllib2.urlopen(*args, **kwargs)
  File "/usr/lib64/python2.7/urllib2.py", line 154, in urlopen
    return opener.open(url, data, timeout)
  File "/usr/lib64/python2.7/urllib2.py", line 431, in open
    response = self._open(req, data)
  File "/usr/lib64/python2.7/urllib2.py", line 449, in _open
    '_open', req)
  File "/usr/lib64/python2.7/urllib2.py", line 409, in _call_chain
    result = func(*args)
  File "/usr/lib64/python2.7/urllib2.py", line 1244, in http_open
    return self.do_open(httplib.HTTPConnection, req)
  File "/usr/lib64/python2.7/urllib2.py", line 1214, in do_open
    raise URLError(err)
URLError: <urlopen error [Errno 110] Connection timed out>
2020-07-24 14:15:05,413 ERROR - Internal Server Error: /monitoring/
Traceback (most recent call last):
  File "/app/argus_final/venv/lib/python2.7/site-packages/django/core/handlers/exception.py", line 41, in inner
    response = get_response(request)
  File "/app/argus_final/venv/lib/python2.7/site-packages/django/core/handlers/base.py", line 187, in _get_response
    response = self.process_exception_by_middleware(e, request)
  File "/app/argus_final/venv/lib/python2.7/site-packages/django/core/handlers/base.py", line 185, in _get_response
    response = wrapped_callback(request, *callback_args, **callback_kwargs)
  File "/app/argus_final/venv/lib/python2.7/site-packages/django/contrib/auth/decorators.py", line 23, in _wrapped_view
    return view_func(request, *args, **kwargs)
  File "/app/argus_final/venv/lib/python2.7/site-packages/django/views/generic/base.py", line 68, in view
    return self.dispatch(request, *args, **kwargs)
  File "/app/argus_final/app/argus/argus/mixins.py", line 14, in dispatch
    return super(GENERIC_PERMISSION_MIXIN, self).dispatch(request, *args, **kwargs)
  File "/app/argus_final/venv/lib/python2.7/site-packages/django/views/generic/base.py", line 88, in dispatch
    return handler(request, *args, **kwargs)
  File "/app/argus_final/app/argus/monitoring/views.py", line 30, in get
    context['data'] = ZABBIX.getAllTriggeredTriggers()
  File "/app/argus_final/app/argus/global_objects/zabbix_api.py", line 80, in getAllTriggeredTriggers
    triggers = self.zapi.do_request('trigger.get',req)
  File "/app/argus_final/venv/lib/python2.7/site-packages/pyzabbix/api.py", line 251, in do_request
    res = urlopen(req)
  File "/app/argus_final/venv/lib/python2.7/site-packages/pyzabbix/api.py", line 117, in inner
    res = func(req)
  File "/app/argus_final/venv/lib/python2.7/site-packages/pyzabbix/api.py", line 126, in urlopen
    return urllib2.urlopen(*args, **kwargs)
  File "/usr/lib64/python2.7/urllib2.py", line 154, in urlopen
    return opener.open(url, data, timeout)
  File "/usr/lib64/python2.7/urllib2.py", line 431, in open
    response = self._open(req, data)
  File "/usr/lib64/python2.7/urllib2.py", line 449, in _open
    '_open', req)
  File "/usr/lib64/python2.7/urllib2.py", line 409, in _call_chain
    result = func(*args)
  File "/usr/lib64/python2.7/urllib2.py", line 1244, in http_open
    return self.do_open(httplib.HTTPConnection, req)
  File "/usr/lib64/python2.7/urllib2.py", line 1214, in do_open
    raise URLError(err)
URLError: <urlopen error [Errno 110] Connection timed out>
2020-07-24 14:15:16,869 ERROR - Internal Server Error: /monitoring/
Traceback (most recent call last):
  File "/app/argus_final/venv/lib/python2.7/site-packages/django/core/handlers/exception.py", line 41, in inner
    response = get_response(request)
  File "/app/argus_final/venv/lib/python2.7/site-packages/django/core/handlers/base.py", line 187, in _get_response
    response = self.process_exception_by_middleware(e, request)
  File "/app/argus_final/venv/lib/python2.7/site-packages/django/core/handlers/base.py", line 185, in _get_response
    response = wrapped_callback(request, *callback_args, **callback_kwargs)
  File "/app/argus_final/venv/lib/python2.7/site-packages/django/contrib/auth/decorators.py", line 23, in _wrapped_view
    return view_func(request, *args, **kwargs)
  File "/app/argus_final/venv/lib/python2.7/site-packages/django/views/generic/base.py", line 68, in view
    return self.dispatch(request, *args, **kwargs)
  File "/app/argus_final/app/argus/argus/mixins.py", line 14, in dispatch
    return super(GENERIC_PERMISSION_MIXIN, self).dispatch(request, *args, **kwargs)
  File "/app/argus_final/venv/lib/python2.7/site-packages/django/views/generic/base.py", line 88, in dispatch
    return handler(request, *args, **kwargs)
  File "/app/argus_final/app/argus/monitoring/views.py", line 40, in get
    context['data'] = ZABBIX.getAllEvents(daysfromnow=period)[-limit:]
  File "/app/argus_final/app/argus/global_objects/zabbix_api.py", line 121, in getAllEvents
    events = self.zapi.do_request('event.get',req)
  File "/app/argus_final/venv/lib/python2.7/site-packages/pyzabbix/api.py", line 251, in do_request
    res = urlopen(req)
  File "/app/argus_final/venv/lib/python2.7/site-packages/pyzabbix/api.py", line 117, in inner
    res = func(req)
  File "/app/argus_final/venv/lib/python2.7/site-packages/pyzabbix/api.py", line 126, in urlopen
    return urllib2.urlopen(*args, **kwargs)
  File "/usr/lib64/python2.7/urllib2.py", line 154, in urlopen
    return opener.open(url, data, timeout)
  File "/usr/lib64/python2.7/urllib2.py", line 431, in open
    response = self._open(req, data)
  File "/usr/lib64/python2.7/urllib2.py", line 449, in _open
    '_open', req)
  File "/usr/lib64/python2.7/urllib2.py", line 409, in _call_chain
    result = func(*args)
  File "/usr/lib64/python2.7/urllib2.py", line 1244, in http_open
    return self.do_open(httplib.HTTPConnection, req)
  File "/usr/lib64/python2.7/urllib2.py", line 1214, in do_open
    raise URLError(err)
URLError: <urlopen error [Errno 110] Connection timed out>
2020-07-24 14:15:33,349 ERROR - Internal Server Error: /monitoring/
Traceback (most recent call last):
  File "/app/argus_final/venv/lib/python2.7/site-packages/django/core/handlers/exception.py", line 41, in inner
    response = get_response(request)
  File "/app/argus_final/venv/lib/python2.7/site-packages/django/core/handlers/base.py", line 187, in _get_response
    response = self.process_exception_by_middleware(e, request)
  File "/app/argus_final/venv/lib/python2.7/site-packages/django/core/handlers/base.py", line 185, in _get_response
    response = wrapped_callback(request, *callback_args, **callback_kwargs)
  File "/app/argus_final/venv/lib/python2.7/site-packages/django/contrib/auth/decorators.py", line 23, in _wrapped_view
    return view_func(request, *args, **kwargs)
  File "/app/argus_final/venv/lib/python2.7/site-packages/django/views/generic/base.py", line 68, in view
    return self.dispatch(request, *args, **kwargs)
  File "/app/argus_final/app/argus/argus/mixins.py", line 14, in dispatch
    return super(GENERIC_PERMISSION_MIXIN, self).dispatch(request, *args, **kwargs)
  File "/app/argus_final/venv/lib/python2.7/site-packages/django/views/generic/base.py", line 88, in dispatch
    return handler(request, *args, **kwargs)
  File "/app/argus_final/app/argus/monitoring/views.py", line 30, in get
    context['data'] = ZABBIX.getAllTriggeredTriggers()
  File "/app/argus_final/app/argus/global_objects/zabbix_api.py", line 80, in getAllTriggeredTriggers
    triggers = self.zapi.do_request('trigger.get',req)
  File "/app/argus_final/venv/lib/python2.7/site-packages/pyzabbix/api.py", line 251, in do_request
    res = urlopen(req)
  File "/app/argus_final/venv/lib/python2.7/site-packages/pyzabbix/api.py", line 117, in inner
    res = func(req)
  File "/app/argus_final/venv/lib/python2.7/site-packages/pyzabbix/api.py", line 126, in urlopen
    return urllib2.urlopen(*args, **kwargs)
  File "/usr/lib64/python2.7/urllib2.py", line 154, in urlopen
    return opener.open(url, data, timeout)
  File "/usr/lib64/python2.7/urllib2.py", line 431, in open
    response = self._open(req, data)
  File "/usr/lib64/python2.7/urllib2.py", line 449, in _open
    '_open', req)
  File "/usr/lib64/python2.7/urllib2.py", line 409, in _call_chain
    result = func(*args)
  File "/usr/lib64/python2.7/urllib2.py", line 1244, in http_open
    return self.do_open(httplib.HTTPConnection, req)
  File "/usr/lib64/python2.7/urllib2.py", line 1214, in do_open
    raise URLError(err)
URLError: <urlopen error [Errno 110] Connection timed out>
2020-07-24 14:15:36,417 ERROR - Internal Server Error: /monitoring/
Traceback (most recent call last):
  File "/app/argus_final/venv/lib/python2.7/site-packages/django/core/handlers/exception.py", line 41, in inner
    response = get_response(request)
  File "/app/argus_final/venv/lib/python2.7/site-packages/django/core/handlers/base.py", line 187, in _get_response
    response = self.process_exception_by_middleware(e, request)
  File "/app/argus_final/venv/lib/python2.7/site-packages/django/core/handlers/base.py", line 185, in _get_response
    response = wrapped_callback(request, *callback_args, **callback_kwargs)
  File "/app/argus_final/venv/lib/python2.7/site-packages/django/contrib/auth/decorators.py", line 23, in _wrapped_view
    return view_func(request, *args, **kwargs)
  File "/app/argus_final/venv/lib/python2.7/site-packages/django/views/generic/base.py", line 68, in view
    return self.dispatch(request, *args, **kwargs)
  File "/app/argus_final/app/argus/argus/mixins.py", line 14, in dispatch
    return super(GENERIC_PERMISSION_MIXIN, self).dispatch(request, *args, **kwargs)
  File "/app/argus_final/venv/lib/python2.7/site-packages/django/views/generic/base.py", line 88, in dispatch
    return handler(request, *args, **kwargs)
  File "/app/argus_final/app/argus/monitoring/views.py", line 40, in get
    context['data'] = ZABBIX.getAllEvents(daysfromnow=period)[-limit:]
  File "/app/argus_final/app/argus/global_objects/zabbix_api.py", line 121, in getAllEvents
    events = self.zapi.do_request('event.get',req)
  File "/app/argus_final/venv/lib/python2.7/site-packages/pyzabbix/api.py", line 251, in do_request
    res = urlopen(req)
  File "/app/argus_final/venv/lib/python2.7/site-packages/pyzabbix/api.py", line 117, in inner
    res = func(req)
  File "/app/argus_final/venv/lib/python2.7/site-packages/pyzabbix/api.py", line 126, in urlopen
    return urllib2.urlopen(*args, **kwargs)
  File "/usr/lib64/python2.7/urllib2.py", line 154, in urlopen
    return opener.open(url, data, timeout)
  File "/usr/lib64/python2.7/urllib2.py", line 431, in open
    response = self._open(req, data)
  File "/usr/lib64/python2.7/urllib2.py", line 449, in _open
    '_open', req)
  File "/usr/lib64/python2.7/urllib2.py", line 409, in _call_chain
    result = func(*args)
  File "/usr/lib64/python2.7/urllib2.py", line 1244, in http_open
    return self.do_open(httplib.HTTPConnection, req)
  File "/usr/lib64/python2.7/urllib2.py", line 1214, in do_open
    raise URLError(err)
URLError: <urlopen error [Errno 110] Connection timed out>
2020-07-24 14:15:41,281 ERROR - Internal Server Error: /monitoring/
Traceback (most recent call last):
  File "/app/argus_final/venv/lib/python2.7/site-packages/django/core/handlers/exception.py", line 41, in inner
    response = get_response(request)
  File "/app/argus_final/venv/lib/python2.7/site-packages/django/core/handlers/base.py", line 187, in _get_response
    response = self.process_exception_by_middleware(e, request)
  File "/app/argus_final/venv/lib/python2.7/site-packages/django/core/handlers/base.py", line 185, in _get_response
    response = wrapped_callback(request, *callback_args, **callback_kwargs)
  File "/app/argus_final/venv/lib/python2.7/site-packages/django/contrib/auth/decorators.py", line 23, in _wrapped_view
    return view_func(request, *args, **kwargs)
  File "/app/argus_final/venv/lib/python2.7/site-packages/django/views/generic/base.py", line 68, in view
    return self.dispatch(request, *args, **kwargs)
  File "/app/argus_final/app/argus/argus/mixins.py", line 14, in dispatch
    return super(GENERIC_PERMISSION_MIXIN, self).dispatch(request, *args, **kwargs)
  File "/app/argus_final/venv/lib/python2.7/site-packages/django/views/generic/base.py", line 88, in dispatch
    return handler(request, *args, **kwargs)
  File "/app/argus_final/app/argus/monitoring/views.py", line 43, in get
    context['data'] = ZABBIX.getScreenGraphs('Network')
  File "/app/argus_final/app/argus/global_objects/zabbix_api.py", line 223, in getScreenGraphs
    'name':screenName
  File "/app/argus_final/venv/lib/python2.7/site-packages/pyzabbix/api.py", line 251, in do_request
    res = urlopen(req)
  File "/app/argus_final/venv/lib/python2.7/site-packages/pyzabbix/api.py", line 117, in inner
    res = func(req)
  File "/app/argus_final/venv/lib/python2.7/site-packages/pyzabbix/api.py", line 126, in urlopen
    return urllib2.urlopen(*args, **kwargs)
  File "/usr/lib64/python2.7/urllib2.py", line 154, in urlopen
    return opener.open(url, data, timeout)
  File "/usr/lib64/python2.7/urllib2.py", line 431, in open
    response = self._open(req, data)
  File "/usr/lib64/python2.7/urllib2.py", line 449, in _open
    '_open', req)
  File "/usr/lib64/python2.7/urllib2.py", line 409, in _call_chain
    result = func(*args)
  File "/usr/lib64/python2.7/urllib2.py", line 1244, in http_open
    return self.do_open(httplib.HTTPConnection, req)
  File "/usr/lib64/python2.7/urllib2.py", line 1214, in do_open
    raise URLError(err)
URLError: <urlopen error [Errno 110] Connection timed out>
2020-07-24 14:15:52,437 ERROR - Internal Server Error: /monitoring/
Traceback (most recent call last):
  File "/app/argus_final/venv/lib/python2.7/site-packages/django/core/handlers/exception.py", line 41, in inner
    response = get_response(request)
  File "/app/argus_final/venv/lib/python2.7/site-packages/django/core/handlers/base.py", line 187, in _get_response
    response = self.process_exception_by_middleware(e, request)
  File "/app/argus_final/venv/lib/python2.7/site-packages/django/core/handlers/base.py", line 185, in _get_response
    response = wrapped_callback(request, *callback_args, **callback_kwargs)
  File "/app/argus_final/venv/lib/python2.7/site-packages/django/contrib/auth/decorators.py", line 23, in _wrapped_view
    return view_func(request, *args, **kwargs)
  File "/app/argus_final/venv/lib/python2.7/site-packages/django/views/generic/base.py", line 68, in view
    return self.dispatch(request, *args, **kwargs)
  File "/app/argus_final/app/argus/argus/mixins.py", line 14, in dispatch
    return super(GENERIC_PERMISSION_MIXIN, self).dispatch(request, *args, **kwargs)
  File "/app/argus_final/venv/lib/python2.7/site-packages/django/views/generic/base.py", line 88, in dispatch
    return handler(request, *args, **kwargs)
  File "/app/argus_final/app/argus/monitoring/views.py", line 40, in get
    context['data'] = ZABBIX.getAllEvents(daysfromnow=period)[-limit:]
  File "/app/argus_final/app/argus/global_objects/zabbix_api.py", line 121, in getAllEvents
    events = self.zapi.do_request('event.get',req)
  File "/app/argus_final/venv/lib/python2.7/site-packages/pyzabbix/api.py", line 251, in do_request
    res = urlopen(req)
  File "/app/argus_final/venv/lib/python2.7/site-packages/pyzabbix/api.py", line 117, in inner
    res = func(req)
  File "/app/argus_final/venv/lib/python2.7/site-packages/pyzabbix/api.py", line 126, in urlopen
    return urllib2.urlopen(*args, **kwargs)
  File "/usr/lib64/python2.7/urllib2.py", line 154, in urlopen
    return opener.open(url, data, timeout)
  File "/usr/lib64/python2.7/urllib2.py", line 431, in open
    response = self._open(req, data)
  File "/usr/lib64/python2.7/urllib2.py", line 449, in _open
    '_open', req)
  File "/usr/lib64/python2.7/urllib2.py", line 409, in _call_chain
    result = func(*args)
  File "/usr/lib64/python2.7/urllib2.py", line 1244, in http_open
    return self.do_open(httplib.HTTPConnection, req)
  File "/usr/lib64/python2.7/urllib2.py", line 1214, in do_open
    raise URLError(err)
URLError: <urlopen error [Errno 110] Connection timed out>
2020-07-24 14:15:53,021 ERROR - Internal Server Error: /monitoring/
Traceback (most recent call last):
  File "/app/argus_final/venv/lib/python2.7/site-packages/django/core/handlers/exception.py", line 41, in inner
    response = get_response(request)
  File "/app/argus_final/venv/lib/python2.7/site-packages/django/core/handlers/base.py", line 187, in _get_response
    response = self.process_exception_by_middleware(e, request)
  File "/app/argus_final/venv/lib/python2.7/site-packages/django/core/handlers/base.py", line 185, in _get_response
    response = wrapped_callback(request, *callback_args, **callback_kwargs)
  File "/app/argus_final/venv/lib/python2.7/site-packages/django/contrib/auth/decorators.py", line 23, in _wrapped_view
    return view_func(request, *args, **kwargs)
  File "/app/argus_final/venv/lib/python2.7/site-packages/django/views/generic/base.py", line 68, in view
    return self.dispatch(request, *args, **kwargs)
  File "/app/argus_final/app/argus/argus/mixins.py", line 14, in dispatch
    return super(GENERIC_PERMISSION_MIXIN, self).dispatch(request, *args, **kwargs)
  File "/app/argus_final/venv/lib/python2.7/site-packages/django/views/generic/base.py", line 88, in dispatch
    return handler(request, *args, **kwargs)
  File "/app/argus_final/app/argus/monitoring/views.py", line 40, in get
    context['data'] = ZABBIX.getAllEvents(daysfromnow=period)[-limit:]
  File "/app/argus_final/app/argus/global_objects/zabbix_api.py", line 121, in getAllEvents
    events = self.zapi.do_request('event.get',req)
  File "/app/argus_final/venv/lib/python2.7/site-packages/pyzabbix/api.py", line 251, in do_request
    res = urlopen(req)
  File "/app/argus_final/venv/lib/python2.7/site-packages/pyzabbix/api.py", line 117, in inner
    res = func(req)
  File "/app/argus_final/venv/lib/python2.7/site-packages/pyzabbix/api.py", line 126, in urlopen
    return urllib2.urlopen(*args, **kwargs)
  File "/usr/lib64/python2.7/urllib2.py", line 154, in urlopen
    return opener.open(url, data, timeout)
  File "/usr/lib64/python2.7/urllib2.py", line 431, in open
    response = self._open(req, data)
  File "/usr/lib64/python2.7/urllib2.py", line 449, in _open
    '_open', req)
  File "/usr/lib64/python2.7/urllib2.py", line 409, in _call_chain
    result = func(*args)
  File "/usr/lib64/python2.7/urllib2.py", line 1244, in http_open
    return self.do_open(httplib.HTTPConnection, req)
  File "/usr/lib64/python2.7/urllib2.py", line 1214, in do_open
    raise URLError(err)
URLError: <urlopen error [Errno 110] Connection timed out>
2020-07-24 14:16:10,349 ERROR - Internal Server Error: /monitoring/
Traceback (most recent call last):
  File "/app/argus_final/venv/lib/python2.7/site-packages/django/core/handlers/exception.py", line 41, in inner
    response = get_response(request)
  File "/app/argus_final/venv/lib/python2.7/site-packages/django/core/handlers/base.py", line 187, in _get_response
    response = self.process_exception_by_middleware(e, request)
  File "/app/argus_final/venv/lib/python2.7/site-packages/django/core/handlers/base.py", line 185, in _get_response
    response = wrapped_callback(request, *callback_args, **callback_kwargs)
  File "/app/argus_final/venv/lib/python2.7/site-packages/django/contrib/auth/decorators.py", line 23, in _wrapped_view
    return view_func(request, *args, **kwargs)
  File "/app/argus_final/venv/lib/python2.7/site-packages/django/views/generic/base.py", line 68, in view
    return self.dispatch(request, *args, **kwargs)
  File "/app/argus_final/app/argus/argus/mixins.py", line 14, in dispatch
    return super(GENERIC_PERMISSION_MIXIN, self).dispatch(request, *args, **kwargs)
  File "/app/argus_final/venv/lib/python2.7/site-packages/django/views/generic/base.py", line 88, in dispatch
    return handler(request, *args, **kwargs)
  File "/app/argus_final/app/argus/monitoring/views.py", line 30, in get
    context['data'] = ZABBIX.getAllTriggeredTriggers()
  File "/app/argus_final/app/argus/global_objects/zabbix_api.py", line 80, in getAllTriggeredTriggers
    triggers = self.zapi.do_request('trigger.get',req)
  File "/app/argus_final/venv/lib/python2.7/site-packages/pyzabbix/api.py", line 251, in do_request
    res = urlopen(req)
  File "/app/argus_final/venv/lib/python2.7/site-packages/pyzabbix/api.py", line 117, in inner
    res = func(req)
  File "/app/argus_final/venv/lib/python2.7/site-packages/pyzabbix/api.py", line 126, in urlopen
    return urllib2.urlopen(*args, **kwargs)
  File "/usr/lib64/python2.7/urllib2.py", line 154, in urlopen
    return opener.open(url, data, timeout)
  File "/usr/lib64/python2.7/urllib2.py", line 431, in open
    response = self._open(req, data)
  File "/usr/lib64/python2.7/urllib2.py", line 449, in _open
    '_open', req)
  File "/usr/lib64/python2.7/urllib2.py", line 409, in _call_chain
    result = func(*args)
  File "/usr/lib64/python2.7/urllib2.py", line 1244, in http_open
    return self.do_open(httplib.HTTPConnection, req)
  File "/usr/lib64/python2.7/urllib2.py", line 1214, in do_open
    raise URLError(err)
URLError: <urlopen error [Errno 110] Connection timed out>
2020-07-24 14:16:13,417 ERROR - Internal Server Error: /monitoring/
Traceback (most recent call last):
  File "/app/argus_final/venv/lib/python2.7/site-packages/django/core/handlers/exception.py", line 41, in inner
    response = get_response(request)
  File "/app/argus_final/venv/lib/python2.7/site-packages/django/core/handlers/base.py", line 187, in _get_response
    response = self.process_exception_by_middleware(e, request)
  File "/app/argus_final/venv/lib/python2.7/site-packages/django/core/handlers/base.py", line 185, in _get_response
    response = wrapped_callback(request, *callback_args, **callback_kwargs)
  File "/app/argus_final/venv/lib/python2.7/site-packages/django/contrib/auth/decorators.py", line 23, in _wrapped_view
    return view_func(request, *args, **kwargs)
  File "/app/argus_final/venv/lib/python2.7/site-packages/django/views/generic/base.py", line 68, in view
    return self.dispatch(request, *args, **kwargs)
  File "/app/argus_final/app/argus/argus/mixins.py", line 14, in dispatch
    return super(GENERIC_PERMISSION_MIXIN, self).dispatch(request, *args, **kwargs)
  File "/app/argus_final/venv/lib/python2.7/site-packages/django/views/generic/base.py", line 88, in dispatch
    return handler(request, *args, **kwargs)
  File "/app/argus_final/app/argus/monitoring/views.py", line 40, in get
    context['data'] = ZABBIX.getAllEvents(daysfromnow=period)[-limit:]
  File "/app/argus_final/app/argus/global_objects/zabbix_api.py", line 121, in getAllEvents
    events = self.zapi.do_request('event.get',req)
  File "/app/argus_final/venv/lib/python2.7/site-packages/pyzabbix/api.py", line 251, in do_request
    res = urlopen(req)
  File "/app/argus_final/venv/lib/python2.7/site-packages/pyzabbix/api.py", line 117, in inner
    res = func(req)
  File "/app/argus_final/venv/lib/python2.7/site-packages/pyzabbix/api.py", line 126, in urlopen
    return urllib2.urlopen(*args, **kwargs)
  File "/usr/lib64/python2.7/urllib2.py", line 154, in urlopen
    return opener.open(url, data, timeout)
  File "/usr/lib64/python2.7/urllib2.py", line 431, in open
    response = self._open(req, data)
  File "/usr/lib64/python2.7/urllib2.py", line 449, in _open
    '_open', req)
  File "/usr/lib64/python2.7/urllib2.py", line 409, in _call_chain
    result = func(*args)
  File "/usr/lib64/python2.7/urllib2.py", line 1244, in http_open
    return self.do_open(httplib.HTTPConnection, req)
  File "/usr/lib64/python2.7/urllib2.py", line 1214, in do_open
    raise URLError(err)
URLError: <urlopen error [Errno 110] Connection timed out>
