2020-09-23 11:20:29,191 DEBUG - (yroll.macalino) - Successfully loaded and updated table
2020-09-23 11:39:32,647 ERROR - Internal Server Error: /esync/acc-midpay_nginx/generate/
Traceback (most recent call last):
  File "/app/argus_final/venv/lib/python2.7/site-packages/django/core/handlers/exception.py", line 41, in inner
    response = get_response(request)
  File "/app/argus_final/venv/lib/python2.7/site-packages/django/core/handlers/base.py", line 187, in _get_response
    response = self.process_exception_by_middleware(e, request)
  File "/app/argus_final/venv/lib/python2.7/site-packages/django/core/handlers/base.py", line 185, in _get_response
    response = wrapped_callback(request, *callback_args, **callback_kwargs)
  File "/app/argus_final/venv/lib/python2.7/site-packages/django/contrib/auth/decorators.py", line 23, in _wrapped_view
    return view_func(request, *args, **kwargs)
  File "/app/argus_final/venv/lib/python2.7/site-packages/django/views/generic/base.py", line 68, in view
    return self.dispatch(request, *args, **kwargs)
  File "/app/argus_final/venv/lib/python2.7/site-packages/django/utils/decorators.py", line 67, in _wrapper
    return bound_func(*args, **kwargs)
  File "/app/argus_final/venv/lib/python2.7/site-packages/django/views/decorators/csrf.py", line 58, in wrapped_view
    return view_func(*args, **kwargs)
  File "/app/argus_final/venv/lib/python2.7/site-packages/django/utils/decorators.py", line 63, in bound_func
    return func.__get__(self, type(self))(*args2, **kwargs2)
  File "/app/argus_final/app/argus/argus/mixins.py", line 14, in dispatch
    return super(GENERIC_PERMISSION_MIXIN, self).dispatch(request, *args, **kwargs)
  File "/app/argus_final/venv/lib/python2.7/site-packages/django/views/generic/base.py", line 88, in dispatch
    return handler(request, *args, **kwargs)
  File "/app/argus_final/app/argus/esync/views.py", line 287, in post
    nonstandard_esync_log(hostgroup, request.user.username, [result[1]],activity_type='CREATE')
  File "/app/argus_final/app/argus/esync/lib/esync_logger.py", line 20, in nonstandard_esync_log
    f.write(i)
UnicodeEncodeError: 'ascii' codec can't encode characters in position 286-287: ordinal not in range(128)
2020-09-23 12:07:19,733 ERROR - Internal Server Error: /fwdcontrol/test-public-nginx/
Traceback (most recent call last):
  File "/app/argus_final/venv/lib/python2.7/site-packages/django/core/handlers/exception.py", line 41, in inner
    response = get_response(request)
  File "/app/argus_final/venv/lib/python2.7/site-packages/django/core/handlers/base.py", line 187, in _get_response
    response = self.process_exception_by_middleware(e, request)
  File "/app/argus_final/venv/lib/python2.7/site-packages/django/core/handlers/base.py", line 185, in _get_response
    response = wrapped_callback(request, *callback_args, **callback_kwargs)
  File "/app/argus_final/venv/lib/python2.7/site-packages/django/contrib/auth/decorators.py", line 23, in _wrapped_view
    return view_func(request, *args, **kwargs)
  File "/app/argus_final/venv/lib/python2.7/site-packages/django/views/generic/base.py", line 68, in view
    return self.dispatch(request, *args, **kwargs)
  File "/app/argus_final/venv/lib/python2.7/site-packages/django/utils/decorators.py", line 67, in _wrapper
    return bound_func(*args, **kwargs)
  File "/app/argus_final/venv/lib/python2.7/site-packages/django/views/decorators/csrf.py", line 58, in wrapped_view
    return view_func(*args, **kwargs)
  File "/app/argus_final/venv/lib/python2.7/site-packages/django/utils/decorators.py", line 63, in bound_func
    return func.__get__(self, type(self))(*args2, **kwargs2)
  File "/app/argus_final/app/argus/argus/mixins.py", line 14, in dispatch
    return super(GENERIC_PERMISSION_MIXIN, self).dispatch(request, *args, **kwargs)
  File "/app/argus_final/venv/lib/python2.7/site-packages/django/views/generic/base.py", line 88, in dispatch
    return handler(request, *args, **kwargs)
  File "/app/argus_final/app/argus/fwdcontrol/views.py", line 46, in get
    context['content'] = result.get()
  File "/app/argus_final/venv/lib/python2.7/site-packages/celery/result.py", line 224, in get
    on_message=on_message,
  File "/app/argus_final/venv/lib/python2.7/site-packages/celery/backends/async.py", line 190, in wait_for_pending
    return result.maybe_throw(callback=callback, propagate=propagate)
  File "/app/argus_final/venv/lib/python2.7/site-packages/celery/result.py", line 329, in maybe_throw
    self.throw(value, self._to_remote_traceback(tb))
  File "/app/argus_final/venv/lib/python2.7/site-packages/celery/result.py", line 322, in throw
    self.on_ready.throw(*args, **kwargs)
  File "/app/argus_final/venv/lib/python2.7/site-packages/vine/promises.py", line 217, in throw
    reraise(type(exc), exc, tb)
  File "<string>", line 1, in reraise
IOError: (u'[', u'E', u'r', u'r', u'n', u'o', u' ', u'2', u'1', u']', u' ', u'I', u's', u' ', u'a', u' ', u'd', u'i', u'r', u'e', u'c', u't', u'o', u'r', u'y', u':', u' ', u'u', u"'", u'/', u's', u'r', u'v', u'/', u't', u'e', u's', u't', u'-', u'p', u'u', u'b', u'l', u'i', u'c', u'-', u'n', u'g', u'i', u'n', u'x', u'/', u'c', u'o', u'n', u'f', u'.', u'd', u'/', u'c', u'a', u"'")
2020-09-23 13:10:17,355 DEBUG - starting thread (client mode): 0x9ef714d0L
2020-09-23 13:10:17,355 DEBUG - Local version/idstring: SSH-2.0-paramiko_2.6.0
2020-09-23 13:10:17,375 DEBUG - Remote version/idstring: SSH-2.0-OpenSSH_7.4
2020-09-23 13:10:17,375 INFO - Connected (version 2.0, client OpenSSH_7.4)
2020-09-23 13:10:17,379 DEBUG - kex algos:[u'curve25519-sha256', u'curve25519-sha256@libssh.org', u'ecdh-sha2-nistp256', u'ecdh-sha2-nistp384', u'ecdh-sha2-nistp521', u'diffie-hellman-group-exchange-sha256', u'diffie-hellman-group16-sha512', u'diffie-hellman-group18-sha512', u'diffie-hellman-group-exchange-sha1', u'diffie-hellman-group14-sha256', u'diffie-hellman-group14-sha1', u'diffie-hellman-group1-sha1'] server key:[u'ssh-rsa', u'rsa-sha2-512', u'rsa-sha2-256', u'ecdsa-sha2-nistp256', u'ssh-ed25519'] client encrypt:[u'chacha20-poly1305@openssh.com', u'aes128-ctr', u'aes192-ctr', u'aes256-ctr', u'aes128-gcm@openssh.com', u'aes256-gcm@openssh.com', u'aes128-cbc', u'aes192-cbc', u'aes256-cbc', u'blowfish-cbc', u'cast128-cbc', u'3des-cbc'] server encrypt:[u'chacha20-poly1305@openssh.com', u'aes128-ctr', u'aes192-ctr', u'aes256-ctr', u'aes128-gcm@openssh.com', u'aes256-gcm@openssh.com', u'aes128-cbc', u'aes192-cbc', u'aes256-cbc', u'blowfish-cbc', u'cast128-cbc', u'3des-cbc'] client mac:[u'umac-64-etm@openssh.com', u'umac-128-etm@openssh.com', u'hmac-sha2-256-etm@openssh.com', u'hmac-sha2-512-etm@openssh.com', u'hmac-sha1-etm@openssh.com', u'umac-64@openssh.com', u'umac-128@openssh.com', u'hmac-sha2-256', u'hmac-sha2-512', u'hmac-sha1'] server mac:[u'umac-64-etm@openssh.com', u'umac-128-etm@openssh.com', u'hmac-sha2-256-etm@openssh.com', u'hmac-sha2-512-etm@openssh.com', u'hmac-sha1-etm@openssh.com', u'umac-64@openssh.com', u'umac-128@openssh.com', u'hmac-sha2-256', u'hmac-sha2-512', u'hmac-sha1'] client compress:[u'none', u'zlib@openssh.com'] server compress:[u'none', u'zlib@openssh.com'] client lang:[u''] server lang:[u''] kex follows?False
2020-09-23 13:10:17,380 DEBUG - Kex agreed: curve25519-sha256@libssh.org
2020-09-23 13:10:17,380 DEBUG - HostKey agreed: ssh-ed25519
2020-09-23 13:10:17,380 DEBUG - Cipher agreed: aes128-ctr
2020-09-23 13:10:17,380 DEBUG - MAC agreed: hmac-sha2-256
2020-09-23 13:10:17,380 DEBUG - Compression agreed: none
2020-09-23 13:10:17,391 DEBUG - kex engine KexCurve25519 specified hash_algo <built-in function openssl_sha256>
2020-09-23 13:10:17,392 DEBUG - Switch to new keys ...
2020-09-23 13:10:17,421 DEBUG - Adding ssh-ed25519 host key for [59.188.138.152]:28032: 649bfb2ade50b259183468bcc4a641be
2020-09-23 13:10:17,423 DEBUG - Trying discovered key f1e2a20412f7e99b7abdb041b22f15e1 in /root/.ssh/id_rsa
2020-09-23 13:10:17,433 DEBUG - userauth is OK
2020-09-23 13:10:22,497 INFO - Authentication (publickey) successful!
2020-09-23 13:10:22,529 DEBUG - [chan 0] Max packet in: 32768 bytes
2020-09-23 13:10:22,724 DEBUG - Received global request "hostkeys-00@openssh.com"
2020-09-23 13:10:22,724 DEBUG - Rejecting "hostkeys-00@openssh.com" global request from server.
2020-09-23 13:10:22,724 DEBUG - Debug msg: Adding to environment: NAME=argus
2020-09-23 13:10:22,764 DEBUG - [chan 0] Max packet out: 32768 bytes
2020-09-23 13:10:22,764 DEBUG - Secsh channel 0 opened.
2020-09-23 13:10:22,802 DEBUG - [chan 0] Sesch channel 0 request ok
2020-09-23 13:10:22,809 DEBUG - [chan 0] Sesch channel 0 request ok
2020-09-23 13:10:22,810 DEBUG - [chan 1] Max packet in: 32768 bytes
2020-09-23 13:10:22,812 DEBUG - [chan 1] Max packet out: 32768 bytes
2020-09-23 13:10:22,812 DEBUG - Secsh channel 1 opened.
2020-09-23 13:10:22,821 DEBUG - [chan 1] Sesch channel 1 request ok
2020-09-23 13:10:33,810 DEBUG - [chan 2] Max packet in: 32768 bytes
2020-09-23 13:10:33,813 DEBUG - [chan 1] EOF received (1)
2020-09-23 13:10:33,813 DEBUG - [chan 1] EOF sent (1)
2020-09-23 13:10:33,814 DEBUG - [chan 2] Max packet out: 32768 bytes
2020-09-23 13:10:33,814 DEBUG - Secsh channel 2 opened.
2020-09-23 13:10:33,858 DEBUG - [chan 2] Sesch channel 2 request ok
2020-09-23 13:10:33,881 DEBUG - [chan 2] EOF received (2)
2020-09-23 13:10:33,882 DEBUG - [chan 2] EOF sent (2)
2020-09-23 13:10:33,883 DEBUG - EOF in transport thread
2020-09-23 14:33:41,826 DEBUG - starting thread (client mode): 0x9e962b90L
2020-09-23 14:33:41,827 DEBUG - Local version/idstring: SSH-2.0-paramiko_2.6.0
2020-09-23 14:33:41,838 DEBUG - Remote version/idstring: SSH-2.0-OpenSSH_7.4
2020-09-23 14:33:41,838 INFO - Connected (version 2.0, client OpenSSH_7.4)
2020-09-23 14:33:41,839 DEBUG - kex algos:[u'curve25519-sha256', u'curve25519-sha256@libssh.org', u'ecdh-sha2-nistp256', u'ecdh-sha2-nistp384', u'ecdh-sha2-nistp521', u'diffie-hellman-group-exchange-sha256', u'diffie-hellman-group16-sha512', u'diffie-hellman-group18-sha512', u'diffie-hellman-group-exchange-sha1', u'diffie-hellman-group14-sha256', u'diffie-hellman-group14-sha1', u'diffie-hellman-group1-sha1'] server key:[u'ssh-rsa', u'rsa-sha2-512', u'rsa-sha2-256', u'ecdsa-sha2-nistp256', u'ssh-ed25519'] client encrypt:[u'chacha20-poly1305@openssh.com', u'aes128-ctr', u'aes192-ctr', u'aes256-ctr', u'aes128-gcm@openssh.com', u'aes256-gcm@openssh.com', u'aes128-cbc', u'aes192-cbc', u'aes256-cbc', u'blowfish-cbc', u'cast128-cbc', u'3des-cbc'] server encrypt:[u'chacha20-poly1305@openssh.com', u'aes128-ctr', u'aes192-ctr', u'aes256-ctr', u'aes128-gcm@openssh.com', u'aes256-gcm@openssh.com', u'aes128-cbc', u'aes192-cbc', u'aes256-cbc', u'blowfish-cbc', u'cast128-cbc', u'3des-cbc'] client mac:[u'umac-64-etm@openssh.com', u'umac-128-etm@openssh.com', u'hmac-sha2-256-etm@openssh.com', u'hmac-sha2-512-etm@openssh.com', u'hmac-sha1-etm@openssh.com', u'umac-64@openssh.com', u'umac-128@openssh.com', u'hmac-sha2-256', u'hmac-sha2-512', u'hmac-sha1'] server mac:[u'umac-64-etm@openssh.com', u'umac-128-etm@openssh.com', u'hmac-sha2-256-etm@openssh.com', u'hmac-sha2-512-etm@openssh.com', u'hmac-sha1-etm@openssh.com', u'umac-64@openssh.com', u'umac-128@openssh.com', u'hmac-sha2-256', u'hmac-sha2-512', u'hmac-sha1'] client compress:[u'none', u'zlib@openssh.com'] server compress:[u'none', u'zlib@openssh.com'] client lang:[u''] server lang:[u''] kex follows?False
2020-09-23 14:33:41,840 DEBUG - Kex agreed: curve25519-sha256@libssh.org
2020-09-23 14:33:41,840 DEBUG - HostKey agreed: ssh-ed25519
2020-09-23 14:33:41,840 DEBUG - Cipher agreed: aes128-ctr
2020-09-23 14:33:41,840 DEBUG - MAC agreed: hmac-sha2-256
2020-09-23 14:33:41,840 DEBUG - Compression agreed: none
2020-09-23 14:33:41,891 DEBUG - kex engine KexCurve25519 specified hash_algo <built-in function openssl_sha256>
2020-09-23 14:33:41,892 DEBUG - Switch to new keys ...
2020-09-23 14:33:41,905 DEBUG - Adding ssh-ed25519 host key for [58.64.167.48]:28032: 649bfb2ade50b259183468bcc4a641be
2020-09-23 14:33:41,906 DEBUG - Trying discovered key f1e2a20412f7e99b7abdb041b22f15e1 in /root/.ssh/id_rsa
2020-09-23 14:33:41,943 DEBUG - userauth is OK
2020-09-23 14:33:46,999 INFO - Authentication (publickey) successful!
2020-09-23 14:33:47,028 DEBUG - [chan 0] Max packet in: 32768 bytes
2020-09-23 14:33:47,043 DEBUG - Received global request "hostkeys-00@openssh.com"
2020-09-23 14:33:47,043 DEBUG - Rejecting "hostkeys-00@openssh.com" global request from server.
2020-09-23 14:33:47,043 DEBUG - Debug msg: Adding to environment: NAME=argus
2020-09-23 14:33:47,069 DEBUG - [chan 0] Max packet out: 32768 bytes
2020-09-23 14:33:47,070 DEBUG - Secsh channel 0 opened.
2020-09-23 14:33:47,094 DEBUG - [chan 0] Sesch channel 0 request ok
2020-09-23 14:33:47,107 DEBUG - [chan 0] Sesch channel 0 request ok
2020-09-23 14:33:47,108 DEBUG - [chan 1] Max packet in: 32768 bytes
2020-09-23 14:33:47,119 DEBUG - [chan 1] Max packet out: 32768 bytes
2020-09-23 14:33:47,120 DEBUG - Secsh channel 1 opened.
2020-09-23 14:33:47,145 DEBUG - [chan 1] Sesch channel 1 request ok
2020-09-23 14:33:52,686 DEBUG - [chan 2] Max packet in: 32768 bytes
2020-09-23 14:33:52,701 DEBUG - [chan 1] EOF received (1)
2020-09-23 14:33:52,701 DEBUG - [chan 1] EOF sent (1)
2020-09-23 14:33:52,702 DEBUG - [chan 2] Max packet out: 32768 bytes
2020-09-23 14:33:52,702 DEBUG - Secsh channel 2 opened.
2020-09-23 14:33:52,755 DEBUG - [chan 2] Sesch channel 2 request ok
2020-09-23 14:33:52,780 DEBUG - [chan 2] EOF received (2)
2020-09-23 14:33:52,780 DEBUG - [chan 2] EOF sent (2)
2020-09-23 14:33:52,781 DEBUG - EOF in transport thread
2020-09-23 15:55:28,002 ERROR - Internal Server Error: /esync/om-test_nginx/
Traceback (most recent call last):
  File "/app/argus_final/venv/lib/python2.7/site-packages/django/core/handlers/exception.py", line 41, in inner
    response = get_response(request)
  File "/app/argus_final/venv/lib/python2.7/site-packages/django/core/handlers/base.py", line 187, in _get_response
    response = self.process_exception_by_middleware(e, request)
  File "/app/argus_final/venv/lib/python2.7/site-packages/django/core/handlers/base.py", line 185, in _get_response
    response = wrapped_callback(request, *callback_args, **callback_kwargs)
  File "/app/argus_final/venv/lib/python2.7/site-packages/django/contrib/auth/decorators.py", line 23, in _wrapped_view
    return view_func(request, *args, **kwargs)
  File "/app/argus_final/venv/lib/python2.7/site-packages/django/views/generic/base.py", line 68, in view
    return self.dispatch(request, *args, **kwargs)
  File "/app/argus_final/app/argus/argus/mixins.py", line 14, in dispatch
    return super(GENERIC_PERMISSION_MIXIN, self).dispatch(request, *args, **kwargs)
  File "/app/argus_final/venv/lib/python2.7/site-packages/django/views/generic/base.py", line 88, in dispatch
    return handler(request, *args, **kwargs)
  File "/app/argus_final/app/argus/esync/views.py", line 169, in get
    context['keys'] = parse_standard_config(context['content'])
  File "/app/argus_final/app/argus/esync/lib/nginx_processor.py", line 11, in parse_standard_config
    rConfig = nginx.loads(config).as_dict
  File "/app/argus_final/venv/lib/python2.7/site-packages/nginx.py", line 402, in loads
    m = re.compile(r'^\s*events\s*{', re.S).search(data[index:])
TypeError: 'bool' object has no attribute '__getitem__'
2020-09-23 20:57:47,278 ERROR - Internal Server Error: /monitoring/
Traceback (most recent call last):
  File "/app/argus_final/venv/lib/python2.7/site-packages/django/core/handlers/exception.py", line 41, in inner
    response = get_response(request)
  File "/app/argus_final/venv/lib/python2.7/site-packages/django/core/handlers/base.py", line 187, in _get_response
    response = self.process_exception_by_middleware(e, request)
  File "/app/argus_final/venv/lib/python2.7/site-packages/django/core/handlers/base.py", line 185, in _get_response
    response = wrapped_callback(request, *callback_args, **callback_kwargs)
  File "/app/argus_final/venv/lib/python2.7/site-packages/django/contrib/auth/decorators.py", line 23, in _wrapped_view
    return view_func(request, *args, **kwargs)
  File "/app/argus_final/venv/lib/python2.7/site-packages/django/views/generic/base.py", line 68, in view
    return self.dispatch(request, *args, **kwargs)
  File "/app/argus_final/app/argus/argus/mixins.py", line 14, in dispatch
    return super(GENERIC_PERMISSION_MIXIN, self).dispatch(request, *args, **kwargs)
  File "/app/argus_final/venv/lib/python2.7/site-packages/django/views/generic/base.py", line 88, in dispatch
    return handler(request, *args, **kwargs)
  File "/app/argus_final/app/argus/monitoring/views.py", line 30, in get
    context['data'] = ZABBIX.getAllTriggeredTriggers()
  File "/app/argus_final/app/argus/global_objects/zabbix_api.py", line 80, in getAllTriggeredTriggers
    triggers = self.zapi.do_request('trigger.get',req)
  File "/app/argus_final/venv/lib/python2.7/site-packages/pyzabbix/api.py", line 251, in do_request
    res = urlopen(req)
  File "/app/argus_final/venv/lib/python2.7/site-packages/pyzabbix/api.py", line 117, in inner
    res = func(req)
  File "/app/argus_final/venv/lib/python2.7/site-packages/pyzabbix/api.py", line 126, in urlopen
    return urllib2.urlopen(*args, **kwargs)
  File "/usr/lib64/python2.7/urllib2.py", line 154, in urlopen
    return opener.open(url, data, timeout)
  File "/usr/lib64/python2.7/urllib2.py", line 437, in open
    response = meth(req, response)
  File "/usr/lib64/python2.7/urllib2.py", line 550, in http_response
    'http', request, response, code, msg, hdrs)
  File "/usr/lib64/python2.7/urllib2.py", line 475, in error
    return self._call_chain(*args)
  File "/usr/lib64/python2.7/urllib2.py", line 409, in _call_chain
    result = func(*args)
  File "/usr/lib64/python2.7/urllib2.py", line 558, in http_error_default
    raise HTTPError(req.get_full_url(), code, msg, hdrs, fp)
HTTPError: HTTP Error 504: Gateway Time-out
2020-09-23 20:57:52,006 ERROR - Internal Server Error: /monitoring/
Traceback (most recent call last):
  File "/app/argus_final/venv/lib/python2.7/site-packages/django/core/handlers/exception.py", line 41, in inner
    response = get_response(request)
  File "/app/argus_final/venv/lib/python2.7/site-packages/django/core/handlers/base.py", line 187, in _get_response
    response = self.process_exception_by_middleware(e, request)
  File "/app/argus_final/venv/lib/python2.7/site-packages/django/core/handlers/base.py", line 185, in _get_response
    response = wrapped_callback(request, *callback_args, **callback_kwargs)
  File "/app/argus_final/venv/lib/python2.7/site-packages/django/contrib/auth/decorators.py", line 23, in _wrapped_view
    return view_func(request, *args, **kwargs)
  File "/app/argus_final/venv/lib/python2.7/site-packages/django/views/generic/base.py", line 68, in view
    return self.dispatch(request, *args, **kwargs)
  File "/app/argus_final/app/argus/argus/mixins.py", line 14, in dispatch
    return super(GENERIC_PERMISSION_MIXIN, self).dispatch(request, *args, **kwargs)
  File "/app/argus_final/venv/lib/python2.7/site-packages/django/views/generic/base.py", line 88, in dispatch
    return handler(request, *args, **kwargs)
  File "/app/argus_final/app/argus/monitoring/views.py", line 30, in get
    context['data'] = ZABBIX.getAllTriggeredTriggers()
  File "/app/argus_final/app/argus/global_objects/zabbix_api.py", line 80, in getAllTriggeredTriggers
    triggers = self.zapi.do_request('trigger.get',req)
  File "/app/argus_final/venv/lib/python2.7/site-packages/pyzabbix/api.py", line 251, in do_request
    res = urlopen(req)
  File "/app/argus_final/venv/lib/python2.7/site-packages/pyzabbix/api.py", line 117, in inner
    res = func(req)
  File "/app/argus_final/venv/lib/python2.7/site-packages/pyzabbix/api.py", line 126, in urlopen
    return urllib2.urlopen(*args, **kwargs)
  File "/usr/lib64/python2.7/urllib2.py", line 154, in urlopen
    return opener.open(url, data, timeout)
  File "/usr/lib64/python2.7/urllib2.py", line 437, in open
    response = meth(req, response)
  File "/usr/lib64/python2.7/urllib2.py", line 550, in http_response
    'http', request, response, code, msg, hdrs)
  File "/usr/lib64/python2.7/urllib2.py", line 475, in error
    return self._call_chain(*args)
  File "/usr/lib64/python2.7/urllib2.py", line 409, in _call_chain
    result = func(*args)
  File "/usr/lib64/python2.7/urllib2.py", line 558, in http_error_default
    raise HTTPError(req.get_full_url(), code, msg, hdrs, fp)
HTTPError: HTTP Error 504: Gateway Time-out
