2020-09-02 08:06:38,966 DEBUG - (geeann.badillo) - Successfully loaded and updated table
2020-09-02 13:18:57,419 ERROR - Internal Server Error: /monitoring/
Traceback (most recent call last):
  File "/app/argus_final/venv/lib/python2.7/site-packages/django/core/handlers/exception.py", line 41, in inner
    response = get_response(request)
  File "/app/argus_final/venv/lib/python2.7/site-packages/django/core/handlers/base.py", line 187, in _get_response
    response = self.process_exception_by_middleware(e, request)
  File "/app/argus_final/venv/lib/python2.7/site-packages/django/core/handlers/base.py", line 185, in _get_response
    response = wrapped_callback(request, *callback_args, **callback_kwargs)
  File "/app/argus_final/venv/lib/python2.7/site-packages/django/contrib/auth/decorators.py", line 23, in _wrapped_view
    return view_func(request, *args, **kwargs)
  File "/app/argus_final/venv/lib/python2.7/site-packages/django/views/generic/base.py", line 68, in view
    return self.dispatch(request, *args, **kwargs)
  File "/app/argus_final/app/argus/argus/mixins.py", line 14, in dispatch
    return super(GENERIC_PERMISSION_MIXIN, self).dispatch(request, *args, **kwargs)
  File "/app/argus_final/venv/lib/python2.7/site-packages/django/views/generic/base.py", line 88, in dispatch
    return handler(request, *args, **kwargs)
  File "/app/argus_final/app/argus/monitoring/views.py", line 30, in get
    context['data'] = ZABBIX.getAllTriggeredTriggers()
  File "/app/argus_final/app/argus/global_objects/zabbix_api.py", line 80, in getAllTriggeredTriggers
    triggers = self.zapi.do_request('trigger.get',req)
  File "/app/argus_final/venv/lib/python2.7/site-packages/pyzabbix/api.py", line 251, in do_request
    res = urlopen(req)
  File "/app/argus_final/venv/lib/python2.7/site-packages/pyzabbix/api.py", line 117, in inner
    res = func(req)
  File "/app/argus_final/venv/lib/python2.7/site-packages/pyzabbix/api.py", line 126, in urlopen
    return urllib2.urlopen(*args, **kwargs)
  File "/usr/lib64/python2.7/urllib2.py", line 154, in urlopen
    return opener.open(url, data, timeout)
  File "/usr/lib64/python2.7/urllib2.py", line 437, in open
    response = meth(req, response)
  File "/usr/lib64/python2.7/urllib2.py", line 550, in http_response
    'http', request, response, code, msg, hdrs)
  File "/usr/lib64/python2.7/urllib2.py", line 475, in error
    return self._call_chain(*args)
  File "/usr/lib64/python2.7/urllib2.py", line 409, in _call_chain
    result = func(*args)
  File "/usr/lib64/python2.7/urllib2.py", line 558, in http_error_default
    raise HTTPError(req.get_full_url(), code, msg, hdrs, fp)
HTTPError: HTTP Error 504: Gateway Time-out
2020-09-02 14:01:40,405 ERROR - Internal Server Error: /esync/om-fpms_pms_nginx/generate/
Traceback (most recent call last):
  File "/app/argus_final/venv/lib/python2.7/site-packages/django/core/handlers/exception.py", line 41, in inner
    response = get_response(request)
  File "/app/argus_final/venv/lib/python2.7/site-packages/django/core/handlers/base.py", line 187, in _get_response
    response = self.process_exception_by_middleware(e, request)
  File "/app/argus_final/venv/lib/python2.7/site-packages/django/core/handlers/base.py", line 185, in _get_response
    response = wrapped_callback(request, *callback_args, **callback_kwargs)
  File "/app/argus_final/venv/lib/python2.7/site-packages/django/contrib/auth/decorators.py", line 23, in _wrapped_view
    return view_func(request, *args, **kwargs)
  File "/app/argus_final/venv/lib/python2.7/site-packages/django/views/generic/base.py", line 68, in view
    return self.dispatch(request, *args, **kwargs)
  File "/app/argus_final/venv/lib/python2.7/site-packages/django/utils/decorators.py", line 67, in _wrapper
    return bound_func(*args, **kwargs)
  File "/app/argus_final/venv/lib/python2.7/site-packages/django/views/decorators/csrf.py", line 58, in wrapped_view
    return view_func(*args, **kwargs)
  File "/app/argus_final/venv/lib/python2.7/site-packages/django/utils/decorators.py", line 63, in bound_func
    return func.__get__(self, type(self))(*args2, **kwargs2)
  File "/app/argus_final/app/argus/argus/mixins.py", line 14, in dispatch
    return super(GENERIC_PERMISSION_MIXIN, self).dispatch(request, *args, **kwargs)
  File "/app/argus_final/venv/lib/python2.7/site-packages/django/views/generic/base.py", line 88, in dispatch
    return handler(request, *args, **kwargs)
  File "/app/argus_final/app/argus/esync/views.py", line 287, in post
    nonstandard_esync_log(hostgroup, request.user.username, [result[1]],activity_type='CREATE')
  File "/app/argus_final/app/argus/esync/lib/esync_logger.py", line 20, in nonstandard_esync_log
    f.write(i)
UnicodeEncodeError: 'ascii' codec can't encode characters in position 246-248: ordinal not in range(128)
