2021-03-09 08:35:29,487 DEBUG - (lyden.reyes) - Successfully loaded and updated table
2021-03-09 08:53:34,453 DEBUG - (jonas.nicanor) - Successfully loaded and updated table
2021-03-09 09:20:31,512 ERROR - Internal Server Error: /esync/om-weixin_nginx/
Traceback (most recent call last):
  File "/app/argus_final/venv/lib/python2.7/site-packages/django/core/handlers/exception.py", line 41, in inner
    response = get_response(request)
  File "/app/argus_final/venv/lib/python2.7/site-packages/django/core/handlers/base.py", line 187, in _get_response
    response = self.process_exception_by_middleware(e, request)
  File "/app/argus_final/venv/lib/python2.7/site-packages/django/core/handlers/base.py", line 185, in _get_response
    response = wrapped_callback(request, *callback_args, **callback_kwargs)
  File "/app/argus_final/venv/lib/python2.7/site-packages/django/contrib/auth/decorators.py", line 23, in _wrapped_view
    return view_func(request, *args, **kwargs)
  File "/app/argus_final/venv/lib/python2.7/site-packages/django/views/generic/base.py", line 68, in view
    return self.dispatch(request, *args, **kwargs)
  File "/app/argus_final/app/argus/argus/mixins.py", line 14, in dispatch
    return super(GENERIC_PERMISSION_MIXIN, self).dispatch(request, *args, **kwargs)
  File "/app/argus_final/venv/lib/python2.7/site-packages/django/views/generic/base.py", line 88, in dispatch
    return handler(request, *args, **kwargs)
  File "/app/argus_final/app/argus/esync/views.py", line 169, in get
    context['keys'] = parse_standard_config(context['content'])
  File "/app/argus_final/app/argus/esync/lib/nginx_processor.py", line 11, in parse_standard_config
    rConfig = nginx.loads(config).as_dict
  File "/app/argus_final/venv/lib/python2.7/site-packages/nginx.py", line 402, in loads
    m = re.compile(r'^\s*events\s*{', re.S).search(data[index:])
TypeError: 'bool' object has no attribute '__getitem__'
2021-03-09 09:33:03,024 ERROR - Internal Server Error: /esync/om-weixin_nginx/
Traceback (most recent call last):
  File "/app/argus_final/venv/lib/python2.7/site-packages/django/core/handlers/exception.py", line 41, in inner
    response = get_response(request)
  File "/app/argus_final/venv/lib/python2.7/site-packages/django/core/handlers/base.py", line 187, in _get_response
    response = self.process_exception_by_middleware(e, request)
  File "/app/argus_final/venv/lib/python2.7/site-packages/django/core/handlers/base.py", line 185, in _get_response
    response = wrapped_callback(request, *callback_args, **callback_kwargs)
  File "/app/argus_final/venv/lib/python2.7/site-packages/django/contrib/auth/decorators.py", line 23, in _wrapped_view
    return view_func(request, *args, **kwargs)
  File "/app/argus_final/venv/lib/python2.7/site-packages/django/views/generic/base.py", line 68, in view
    return self.dispatch(request, *args, **kwargs)
  File "/app/argus_final/app/argus/argus/mixins.py", line 14, in dispatch
    return super(GENERIC_PERMISSION_MIXIN, self).dispatch(request, *args, **kwargs)
  File "/app/argus_final/venv/lib/python2.7/site-packages/django/views/generic/base.py", line 88, in dispatch
    return handler(request, *args, **kwargs)
  File "/app/argus_final/app/argus/esync/views.py", line 169, in get
    context['keys'] = parse_standard_config(context['content'])
  File "/app/argus_final/app/argus/esync/lib/nginx_processor.py", line 11, in parse_standard_config
    rConfig = nginx.loads(config).as_dict
  File "/app/argus_final/venv/lib/python2.7/site-packages/nginx.py", line 402, in loads
    m = re.compile(r'^\s*events\s*{', re.S).search(data[index:])
TypeError: 'bool' object has no attribute '__getitem__'
2021-03-09 11:08:49,040 ERROR - Internal Server Error: /esync/om-test_nginx/
Traceback (most recent call last):
  File "/app/argus_final/venv/lib/python2.7/site-packages/django/core/handlers/exception.py", line 41, in inner
    response = get_response(request)
  File "/app/argus_final/venv/lib/python2.7/site-packages/django/core/handlers/base.py", line 187, in _get_response
    response = self.process_exception_by_middleware(e, request)
  File "/app/argus_final/venv/lib/python2.7/site-packages/django/core/handlers/base.py", line 185, in _get_response
    response = wrapped_callback(request, *callback_args, **callback_kwargs)
  File "/app/argus_final/venv/lib/python2.7/site-packages/django/contrib/auth/decorators.py", line 23, in _wrapped_view
    return view_func(request, *args, **kwargs)
  File "/app/argus_final/venv/lib/python2.7/site-packages/django/views/generic/base.py", line 68, in view
    return self.dispatch(request, *args, **kwargs)
  File "/app/argus_final/app/argus/argus/mixins.py", line 14, in dispatch
    return super(GENERIC_PERMISSION_MIXIN, self).dispatch(request, *args, **kwargs)
  File "/app/argus_final/venv/lib/python2.7/site-packages/django/views/generic/base.py", line 88, in dispatch
    return handler(request, *args, **kwargs)
  File "/app/argus_final/app/argus/esync/views.py", line 169, in get
    context['keys'] = parse_standard_config(context['content'])
  File "/app/argus_final/app/argus/esync/lib/nginx_processor.py", line 11, in parse_standard_config
    rConfig = nginx.loads(config).as_dict
  File "/app/argus_final/venv/lib/python2.7/site-packages/nginx.py", line 402, in loads
    m = re.compile(r'^\s*events\s*{', re.S).search(data[index:])
TypeError: 'bool' object has no attribute '__getitem__'
2021-03-09 12:36:00,559 DEBUG - (jonas.nicanor) - Successfully loaded and updated table
2021-03-09 14:05:27,789 ERROR - Internal Server Error: /esync/om-fpms_pms_nginx/
Traceback (most recent call last):
  File "/app/argus_final/venv/lib/python2.7/site-packages/django/core/handlers/exception.py", line 41, in inner
    response = get_response(request)
  File "/app/argus_final/venv/lib/python2.7/site-packages/django/core/handlers/base.py", line 187, in _get_response
    response = self.process_exception_by_middleware(e, request)
  File "/app/argus_final/venv/lib/python2.7/site-packages/django/core/handlers/base.py", line 185, in _get_response
    response = wrapped_callback(request, *callback_args, **callback_kwargs)
  File "/app/argus_final/venv/lib/python2.7/site-packages/django/contrib/auth/decorators.py", line 23, in _wrapped_view
    return view_func(request, *args, **kwargs)
  File "/app/argus_final/venv/lib/python2.7/site-packages/django/views/generic/base.py", line 68, in view
    return self.dispatch(request, *args, **kwargs)
  File "/app/argus_final/app/argus/argus/mixins.py", line 14, in dispatch
    return super(GENERIC_PERMISSION_MIXIN, self).dispatch(request, *args, **kwargs)
  File "/app/argus_final/venv/lib/python2.7/site-packages/django/views/generic/base.py", line 88, in dispatch
    return handler(request, *args, **kwargs)
  File "/app/argus_final/app/argus/esync/views.py", line 169, in get
    context['keys'] = parse_standard_config(context['content'])
  File "/app/argus_final/app/argus/esync/lib/nginx_processor.py", line 11, in parse_standard_config
    rConfig = nginx.loads(config).as_dict
  File "/app/argus_final/venv/lib/python2.7/site-packages/nginx.py", line 402, in loads
    m = re.compile(r'^\s*events\s*{', re.S).search(data[index:])
TypeError: 'bool' object has no attribute '__getitem__'
2021-03-09 14:05:37,709 ERROR - Internal Server Error: /esync/om-fpms_pms_nginx/
Traceback (most recent call last):
  File "/app/argus_final/venv/lib/python2.7/site-packages/django/core/handlers/exception.py", line 41, in inner
    response = get_response(request)
  File "/app/argus_final/venv/lib/python2.7/site-packages/django/core/handlers/base.py", line 187, in _get_response
    response = self.process_exception_by_middleware(e, request)
  File "/app/argus_final/venv/lib/python2.7/site-packages/django/core/handlers/base.py", line 185, in _get_response
    response = wrapped_callback(request, *callback_args, **callback_kwargs)
  File "/app/argus_final/venv/lib/python2.7/site-packages/django/contrib/auth/decorators.py", line 23, in _wrapped_view
    return view_func(request, *args, **kwargs)
  File "/app/argus_final/venv/lib/python2.7/site-packages/django/views/generic/base.py", line 68, in view
    return self.dispatch(request, *args, **kwargs)
  File "/app/argus_final/app/argus/argus/mixins.py", line 14, in dispatch
    return super(GENERIC_PERMISSION_MIXIN, self).dispatch(request, *args, **kwargs)
  File "/app/argus_final/venv/lib/python2.7/site-packages/django/views/generic/base.py", line 88, in dispatch
    return handler(request, *args, **kwargs)
  File "/app/argus_final/app/argus/esync/views.py", line 169, in get
    context['keys'] = parse_standard_config(context['content'])
  File "/app/argus_final/app/argus/esync/lib/nginx_processor.py", line 11, in parse_standard_config
    rConfig = nginx.loads(config).as_dict
  File "/app/argus_final/venv/lib/python2.7/site-packages/nginx.py", line 402, in loads
    m = re.compile(r'^\s*events\s*{', re.S).search(data[index:])
TypeError: 'bool' object has no attribute '__getitem__'
2021-03-09 15:27:30,459 DEBUG - (jonas.nicanor) - Successfully loaded and updated table
2021-03-09 16:56:31,276 ERROR - Internal Server Error: /esync/om-fpms_pms_nginx/generate/
Traceback (most recent call last):
  File "/app/argus_final/venv/lib/python2.7/site-packages/django/core/handlers/exception.py", line 41, in inner
    response = get_response(request)
  File "/app/argus_final/venv/lib/python2.7/site-packages/django/core/handlers/base.py", line 187, in _get_response
    response = self.process_exception_by_middleware(e, request)
  File "/app/argus_final/venv/lib/python2.7/site-packages/django/core/handlers/base.py", line 185, in _get_response
    response = wrapped_callback(request, *callback_args, **callback_kwargs)
  File "/app/argus_final/venv/lib/python2.7/site-packages/django/contrib/auth/decorators.py", line 23, in _wrapped_view
    return view_func(request, *args, **kwargs)
  File "/app/argus_final/venv/lib/python2.7/site-packages/django/views/generic/base.py", line 68, in view
    return self.dispatch(request, *args, **kwargs)
  File "/app/argus_final/venv/lib/python2.7/site-packages/django/utils/decorators.py", line 67, in _wrapper
    return bound_func(*args, **kwargs)
  File "/app/argus_final/venv/lib/python2.7/site-packages/django/views/decorators/csrf.py", line 58, in wrapped_view
    return view_func(*args, **kwargs)
  File "/app/argus_final/venv/lib/python2.7/site-packages/django/utils/decorators.py", line 63, in bound_func
    return func.__get__(self, type(self))(*args2, **kwargs2)
  File "/app/argus_final/app/argus/argus/mixins.py", line 14, in dispatch
    return super(GENERIC_PERMISSION_MIXIN, self).dispatch(request, *args, **kwargs)
  File "/app/argus_final/venv/lib/python2.7/site-packages/django/views/generic/base.py", line 88, in dispatch
    return handler(request, *args, **kwargs)
  File "/app/argus_final/app/argus/esync/views.py", line 287, in post
    nonstandard_esync_log(hostgroup, request.user.username, [result[1]],activity_type='CREATE')
  File "/app/argus_final/app/argus/esync/lib/esync_logger.py", line 20, in nonstandard_esync_log
    f.write(i)
UnicodeEncodeError: 'ascii' codec can't encode characters in position 331-332: ordinal not in range(128)
2021-03-10 00:20:30,725 DEBUG - starting thread (client mode): 0xc472a690L
2021-03-10 00:20:30,725 DEBUG - Local version/idstring: SSH-2.0-paramiko_2.6.0
2021-03-10 00:20:30,792 DEBUG - Remote version/idstring: SSH-2.0-OpenSSH_7.4
2021-03-10 00:20:30,792 INFO - Connected (version 2.0, client OpenSSH_7.4)
2021-03-10 00:20:30,797 DEBUG - kex algos:[u'curve25519-sha256', u'curve25519-sha256@libssh.org', u'ecdh-sha2-nistp256', u'ecdh-sha2-nistp384', u'ecdh-sha2-nistp521', u'diffie-hellman-group-exchange-sha256', u'diffie-hellman-group16-sha512', u'diffie-hellman-group18-sha512', u'diffie-hellman-group-exchange-sha1', u'diffie-hellman-group14-sha256', u'diffie-hellman-group14-sha1', u'diffie-hellman-group1-sha1'] server key:[u'ssh-rsa', u'rsa-sha2-512', u'rsa-sha2-256', u'ecdsa-sha2-nistp256', u'ssh-ed25519'] client encrypt:[u'chacha20-poly1305@openssh.com', u'aes128-ctr', u'aes192-ctr', u'aes256-ctr', u'aes128-gcm@openssh.com', u'aes256-gcm@openssh.com', u'aes128-cbc', u'aes192-cbc', u'aes256-cbc', u'blowfish-cbc', u'cast128-cbc', u'3des-cbc'] server encrypt:[u'chacha20-poly1305@openssh.com', u'aes128-ctr', u'aes192-ctr', u'aes256-ctr', u'aes128-gcm@openssh.com', u'aes256-gcm@openssh.com', u'aes128-cbc', u'aes192-cbc', u'aes256-cbc', u'blowfish-cbc', u'cast128-cbc', u'3des-cbc'] client mac:[u'umac-64-etm@openssh.com', u'umac-128-etm@openssh.com', u'hmac-sha2-256-etm@openssh.com', u'hmac-sha2-512-etm@openssh.com', u'hmac-sha1-etm@openssh.com', u'umac-64@openssh.com', u'umac-128@openssh.com', u'hmac-sha2-256', u'hmac-sha2-512', u'hmac-sha1'] server mac:[u'umac-64-etm@openssh.com', u'umac-128-etm@openssh.com', u'hmac-sha2-256-etm@openssh.com', u'hmac-sha2-512-etm@openssh.com', u'hmac-sha1-etm@openssh.com', u'umac-64@openssh.com', u'umac-128@openssh.com', u'hmac-sha2-256', u'hmac-sha2-512', u'hmac-sha1'] client compress:[u'none', u'zlib@openssh.com'] server compress:[u'none', u'zlib@openssh.com'] client lang:[u''] server lang:[u''] kex follows?False
2021-03-10 00:20:30,797 DEBUG - Kex agreed: curve25519-sha256@libssh.org
2021-03-10 00:20:30,798 DEBUG - HostKey agreed: ssh-ed25519
2021-03-10 00:20:30,798 DEBUG - Cipher agreed: aes128-ctr
2021-03-10 00:20:30,798 DEBUG - MAC agreed: hmac-sha2-256
2021-03-10 00:20:30,798 DEBUG - Compression agreed: none
2021-03-10 00:20:30,823 DEBUG - kex engine KexCurve25519 specified hash_algo <built-in function openssl_sha256>
2021-03-10 00:20:30,825 DEBUG - Switch to new keys ...
2021-03-10 00:20:30,826 DEBUG - Adding ssh-ed25519 host key for [154.196.146.172]:28032: 0b30820b90de90f667c9e6d6bf94d51b
2021-03-10 00:20:30,828 DEBUG - Trying discovered key f1e2a20412f7e99b7abdb041b22f15e1 in /root/.ssh/id_rsa
2021-03-10 00:20:30,873 DEBUG - userauth is OK
2021-03-10 00:20:35,922 INFO - Authentication (publickey) successful!
2021-03-10 00:20:35,934 DEBUG - [chan 0] Max packet in: 32768 bytes
2021-03-10 00:20:35,965 DEBUG - Received global request "hostkeys-00@openssh.com"
2021-03-10 00:20:35,965 DEBUG - Rejecting "hostkeys-00@openssh.com" global request from server.
2021-03-10 00:20:35,965 DEBUG - Debug msg: Adding to environment: NAME=argus
2021-03-10 00:20:36,007 DEBUG - [chan 0] Max packet out: 32768 bytes
2021-03-10 00:20:36,007 DEBUG - Secsh channel 0 opened.
2021-03-10 00:20:36,043 DEBUG - [chan 0] Sesch channel 0 request ok
2021-03-10 00:20:36,051 DEBUG - [chan 0] Sesch channel 0 request ok
2021-03-10 00:20:36,052 DEBUG - [chan 1] Max packet in: 32768 bytes
2021-03-10 00:20:36,057 DEBUG - [chan 1] Max packet out: 32768 bytes
2021-03-10 00:20:36,057 DEBUG - Secsh channel 1 opened.
2021-03-10 00:20:36,068 DEBUG - [chan 1] Sesch channel 1 request ok
2021-03-10 00:20:48,810 DEBUG - [chan 2] Max packet in: 32768 bytes
2021-03-10 00:20:48,812 DEBUG - [chan 1] EOF received (1)
2021-03-10 00:20:48,812 DEBUG - [chan 1] EOF sent (1)
2021-03-10 00:20:48,816 DEBUG - [chan 2] Max packet out: 32768 bytes
2021-03-10 00:20:48,816 DEBUG - Secsh channel 2 opened.
2021-03-10 00:20:48,866 DEBUG - [chan 2] Sesch channel 2 request ok
2021-03-10 00:20:48,915 DEBUG - [chan 2] EOF received (2)
2021-03-10 00:20:48,916 DEBUG - [chan 2] EOF sent (2)
2021-03-10 00:20:48,917 DEBUG - EOF in transport thread
2021-03-10 07:24:12,669 ERROR - Internal Server Error: /esync/om-fpms_pms_nginx/
Traceback (most recent call last):
  File "/app/argus_final/venv/lib/python2.7/site-packages/django/core/handlers/exception.py", line 41, in inner
    response = get_response(request)
  File "/app/argus_final/venv/lib/python2.7/site-packages/django/core/handlers/base.py", line 187, in _get_response
    response = self.process_exception_by_middleware(e, request)
  File "/app/argus_final/venv/lib/python2.7/site-packages/django/core/handlers/base.py", line 185, in _get_response
    response = wrapped_callback(request, *callback_args, **callback_kwargs)
  File "/app/argus_final/venv/lib/python2.7/site-packages/django/contrib/auth/decorators.py", line 23, in _wrapped_view
    return view_func(request, *args, **kwargs)
  File "/app/argus_final/venv/lib/python2.7/site-packages/django/views/generic/base.py", line 68, in view
    return self.dispatch(request, *args, **kwargs)
  File "/app/argus_final/app/argus/argus/mixins.py", line 14, in dispatch
    return super(GENERIC_PERMISSION_MIXIN, self).dispatch(request, *args, **kwargs)
  File "/app/argus_final/venv/lib/python2.7/site-packages/django/views/generic/base.py", line 88, in dispatch
    return handler(request, *args, **kwargs)
  File "/app/argus_final/app/argus/esync/views.py", line 169, in get
    context['keys'] = parse_standard_config(context['content'])
  File "/app/argus_final/app/argus/esync/lib/nginx_processor.py", line 11, in parse_standard_config
    rConfig = nginx.loads(config).as_dict
  File "/app/argus_final/venv/lib/python2.7/site-packages/nginx.py", line 402, in loads
    m = re.compile(r'^\s*events\s*{', re.S).search(data[index:])
TypeError: 'bool' object has no attribute '__getitem__'
2021-03-10 07:24:18,890 ERROR - Internal Server Error: /esync/om-fpms_pms_nginx/
Traceback (most recent call last):
  File "/app/argus_final/venv/lib/python2.7/site-packages/django/core/handlers/exception.py", line 41, in inner
    response = get_response(request)
  File "/app/argus_final/venv/lib/python2.7/site-packages/django/core/handlers/base.py", line 187, in _get_response
    response = self.process_exception_by_middleware(e, request)
  File "/app/argus_final/venv/lib/python2.7/site-packages/django/core/handlers/base.py", line 185, in _get_response
    response = wrapped_callback(request, *callback_args, **callback_kwargs)
  File "/app/argus_final/venv/lib/python2.7/site-packages/django/contrib/auth/decorators.py", line 23, in _wrapped_view
    return view_func(request, *args, **kwargs)
  File "/app/argus_final/venv/lib/python2.7/site-packages/django/views/generic/base.py", line 68, in view
    return self.dispatch(request, *args, **kwargs)
  File "/app/argus_final/app/argus/argus/mixins.py", line 14, in dispatch
    return super(GENERIC_PERMISSION_MIXIN, self).dispatch(request, *args, **kwargs)
  File "/app/argus_final/venv/lib/python2.7/site-packages/django/views/generic/base.py", line 88, in dispatch
    return handler(request, *args, **kwargs)
  File "/app/argus_final/app/argus/esync/views.py", line 169, in get
    context['keys'] = parse_standard_config(context['content'])
  File "/app/argus_final/app/argus/esync/lib/nginx_processor.py", line 11, in parse_standard_config
    rConfig = nginx.loads(config).as_dict
  File "/app/argus_final/venv/lib/python2.7/site-packages/nginx.py", line 402, in loads
    m = re.compile(r'^\s*events\s*{', re.S).search(data[index:])
TypeError: 'bool' object has no attribute '__getitem__'
2021-03-10 07:24:28,564 ERROR - Internal Server Error: /esync/om-fpms_pms_nginx/
Traceback (most recent call last):
  File "/app/argus_final/venv/lib/python2.7/site-packages/django/core/handlers/exception.py", line 41, in inner
    response = get_response(request)
  File "/app/argus_final/venv/lib/python2.7/site-packages/django/core/handlers/base.py", line 187, in _get_response
    response = self.process_exception_by_middleware(e, request)
  File "/app/argus_final/venv/lib/python2.7/site-packages/django/core/handlers/base.py", line 185, in _get_response
    response = wrapped_callback(request, *callback_args, **callback_kwargs)
  File "/app/argus_final/venv/lib/python2.7/site-packages/django/contrib/auth/decorators.py", line 23, in _wrapped_view
    return view_func(request, *args, **kwargs)
  File "/app/argus_final/venv/lib/python2.7/site-packages/django/views/generic/base.py", line 68, in view
    return self.dispatch(request, *args, **kwargs)
  File "/app/argus_final/app/argus/argus/mixins.py", line 14, in dispatch
    return super(GENERIC_PERMISSION_MIXIN, self).dispatch(request, *args, **kwargs)
  File "/app/argus_final/venv/lib/python2.7/site-packages/django/views/generic/base.py", line 88, in dispatch
    return handler(request, *args, **kwargs)
  File "/app/argus_final/app/argus/esync/views.py", line 169, in get
    context['keys'] = parse_standard_config(context['content'])
  File "/app/argus_final/app/argus/esync/lib/nginx_processor.py", line 11, in parse_standard_config
    rConfig = nginx.loads(config).as_dict
  File "/app/argus_final/venv/lib/python2.7/site-packages/nginx.py", line 402, in loads
    m = re.compile(r'^\s*events\s*{', re.S).search(data[index:])
TypeError: 'bool' object has no attribute '__getitem__'
2021-03-10 07:24:29,906 ERROR - Internal Server Error: /esync/om-fpms_pms_nginx/
Traceback (most recent call last):
  File "/app/argus_final/venv/lib/python2.7/site-packages/django/core/handlers/exception.py", line 41, in inner
    response = get_response(request)
  File "/app/argus_final/venv/lib/python2.7/site-packages/django/core/handlers/base.py", line 187, in _get_response
    response = self.process_exception_by_middleware(e, request)
  File "/app/argus_final/venv/lib/python2.7/site-packages/django/core/handlers/base.py", line 185, in _get_response
    response = wrapped_callback(request, *callback_args, **callback_kwargs)
  File "/app/argus_final/venv/lib/python2.7/site-packages/django/contrib/auth/decorators.py", line 23, in _wrapped_view
    return view_func(request, *args, **kwargs)
  File "/app/argus_final/venv/lib/python2.7/site-packages/django/views/generic/base.py", line 68, in view
    return self.dispatch(request, *args, **kwargs)
  File "/app/argus_final/app/argus/argus/mixins.py", line 14, in dispatch
    return super(GENERIC_PERMISSION_MIXIN, self).dispatch(request, *args, **kwargs)
  File "/app/argus_final/venv/lib/python2.7/site-packages/django/views/generic/base.py", line 88, in dispatch
    return handler(request, *args, **kwargs)
  File "/app/argus_final/app/argus/esync/views.py", line 169, in get
    context['keys'] = parse_standard_config(context['content'])
  File "/app/argus_final/app/argus/esync/lib/nginx_processor.py", line 11, in parse_standard_config
    rConfig = nginx.loads(config).as_dict
  File "/app/argus_final/venv/lib/python2.7/site-packages/nginx.py", line 402, in loads
    m = re.compile(r'^\s*events\s*{', re.S).search(data[index:])
TypeError: 'bool' object has no attribute '__getitem__'
2021-03-10 07:24:39,945 ERROR - Internal Server Error: /esync/om-fpms_pms_nginx/
Traceback (most recent call last):
  File "/app/argus_final/venv/lib/python2.7/site-packages/django/core/handlers/exception.py", line 41, in inner
    response = get_response(request)
  File "/app/argus_final/venv/lib/python2.7/site-packages/django/core/handlers/base.py", line 187, in _get_response
    response = self.process_exception_by_middleware(e, request)
  File "/app/argus_final/venv/lib/python2.7/site-packages/django/core/handlers/base.py", line 185, in _get_response
    response = wrapped_callback(request, *callback_args, **callback_kwargs)
  File "/app/argus_final/venv/lib/python2.7/site-packages/django/contrib/auth/decorators.py", line 23, in _wrapped_view
    return view_func(request, *args, **kwargs)
  File "/app/argus_final/venv/lib/python2.7/site-packages/django/views/generic/base.py", line 68, in view
    return self.dispatch(request, *args, **kwargs)
  File "/app/argus_final/app/argus/argus/mixins.py", line 14, in dispatch
    return super(GENERIC_PERMISSION_MIXIN, self).dispatch(request, *args, **kwargs)
  File "/app/argus_final/venv/lib/python2.7/site-packages/django/views/generic/base.py", line 88, in dispatch
    return handler(request, *args, **kwargs)
  File "/app/argus_final/app/argus/esync/views.py", line 169, in get
    context['keys'] = parse_standard_config(context['content'])
  File "/app/argus_final/app/argus/esync/lib/nginx_processor.py", line 11, in parse_standard_config
    rConfig = nginx.loads(config).as_dict
  File "/app/argus_final/venv/lib/python2.7/site-packages/nginx.py", line 402, in loads
    m = re.compile(r'^\s*events\s*{', re.S).search(data[index:])
TypeError: 'bool' object has no attribute '__getitem__'
2021-03-10 07:24:46,368 ERROR - Internal Server Error: /esync/om-fpms_pms_nginx/
Traceback (most recent call last):
  File "/app/argus_final/venv/lib/python2.7/site-packages/django/core/handlers/exception.py", line 41, in inner
    response = get_response(request)
  File "/app/argus_final/venv/lib/python2.7/site-packages/django/core/handlers/base.py", line 187, in _get_response
    response = self.process_exception_by_middleware(e, request)
  File "/app/argus_final/venv/lib/python2.7/site-packages/django/core/handlers/base.py", line 185, in _get_response
    response = wrapped_callback(request, *callback_args, **callback_kwargs)
  File "/app/argus_final/venv/lib/python2.7/site-packages/django/contrib/auth/decorators.py", line 23, in _wrapped_view
    return view_func(request, *args, **kwargs)
  File "/app/argus_final/venv/lib/python2.7/site-packages/django/views/generic/base.py", line 68, in view
    return self.dispatch(request, *args, **kwargs)
  File "/app/argus_final/app/argus/argus/mixins.py", line 14, in dispatch
    return super(GENERIC_PERMISSION_MIXIN, self).dispatch(request, *args, **kwargs)
  File "/app/argus_final/venv/lib/python2.7/site-packages/django/views/generic/base.py", line 88, in dispatch
    return handler(request, *args, **kwargs)
  File "/app/argus_final/app/argus/esync/views.py", line 169, in get
    context['keys'] = parse_standard_config(context['content'])
  File "/app/argus_final/app/argus/esync/lib/nginx_processor.py", line 11, in parse_standard_config
    rConfig = nginx.loads(config).as_dict
  File "/app/argus_final/venv/lib/python2.7/site-packages/nginx.py", line 402, in loads
    m = re.compile(r'^\s*events\s*{', re.S).search(data[index:])
TypeError: 'bool' object has no attribute '__getitem__'
2021-03-10 07:24:50,853 ERROR - Internal Server Error: /esync/om-fpms_pms_nginx/
Traceback (most recent call last):
  File "/app/argus_final/venv/lib/python2.7/site-packages/django/core/handlers/exception.py", line 41, in inner
    response = get_response(request)
  File "/app/argus_final/venv/lib/python2.7/site-packages/django/core/handlers/base.py", line 187, in _get_response
    response = self.process_exception_by_middleware(e, request)
  File "/app/argus_final/venv/lib/python2.7/site-packages/django/core/handlers/base.py", line 185, in _get_response
    response = wrapped_callback(request, *callback_args, **callback_kwargs)
  File "/app/argus_final/venv/lib/python2.7/site-packages/django/contrib/auth/decorators.py", line 23, in _wrapped_view
    return view_func(request, *args, **kwargs)
  File "/app/argus_final/venv/lib/python2.7/site-packages/django/views/generic/base.py", line 68, in view
    return self.dispatch(request, *args, **kwargs)
  File "/app/argus_final/app/argus/argus/mixins.py", line 14, in dispatch
    return super(GENERIC_PERMISSION_MIXIN, self).dispatch(request, *args, **kwargs)
  File "/app/argus_final/venv/lib/python2.7/site-packages/django/views/generic/base.py", line 88, in dispatch
    return handler(request, *args, **kwargs)
  File "/app/argus_final/app/argus/esync/views.py", line 169, in get
    context['keys'] = parse_standard_config(context['content'])
  File "/app/argus_final/app/argus/esync/lib/nginx_processor.py", line 11, in parse_standard_config
    rConfig = nginx.loads(config).as_dict
  File "/app/argus_final/venv/lib/python2.7/site-packages/nginx.py", line 402, in loads
    m = re.compile(r'^\s*events\s*{', re.S).search(data[index:])
TypeError: 'bool' object has no attribute '__getitem__'
2021-03-10 07:26:57,025 ERROR - Internal Server Error: /esync/om-fpms_pms_nginx/
Traceback (most recent call last):
  File "/app/argus_final/venv/lib/python2.7/site-packages/django/core/handlers/exception.py", line 41, in inner
    response = get_response(request)
  File "/app/argus_final/venv/lib/python2.7/site-packages/django/core/handlers/base.py", line 187, in _get_response
    response = self.process_exception_by_middleware(e, request)
  File "/app/argus_final/venv/lib/python2.7/site-packages/django/core/handlers/base.py", line 185, in _get_response
    response = wrapped_callback(request, *callback_args, **callback_kwargs)
  File "/app/argus_final/venv/lib/python2.7/site-packages/django/contrib/auth/decorators.py", line 23, in _wrapped_view
    return view_func(request, *args, **kwargs)
  File "/app/argus_final/venv/lib/python2.7/site-packages/django/views/generic/base.py", line 68, in view
    return self.dispatch(request, *args, **kwargs)
  File "/app/argus_final/app/argus/argus/mixins.py", line 14, in dispatch
    return super(GENERIC_PERMISSION_MIXIN, self).dispatch(request, *args, **kwargs)
  File "/app/argus_final/venv/lib/python2.7/site-packages/django/views/generic/base.py", line 88, in dispatch
    return handler(request, *args, **kwargs)
  File "/app/argus_final/app/argus/esync/views.py", line 169, in get
    context['keys'] = parse_standard_config(context['content'])
  File "/app/argus_final/app/argus/esync/lib/nginx_processor.py", line 11, in parse_standard_config
    rConfig = nginx.loads(config).as_dict
  File "/app/argus_final/venv/lib/python2.7/site-packages/nginx.py", line 402, in loads
    m = re.compile(r'^\s*events\s*{', re.S).search(data[index:])
TypeError: 'bool' object has no attribute '__getitem__'
2021-03-10 07:27:19,654 ERROR - Internal Server Error: /esync/om-fpms_pms_nginx/
Traceback (most recent call last):
  File "/app/argus_final/venv/lib/python2.7/site-packages/django/core/handlers/exception.py", line 41, in inner
    response = get_response(request)
  File "/app/argus_final/venv/lib/python2.7/site-packages/django/core/handlers/base.py", line 187, in _get_response
    response = self.process_exception_by_middleware(e, request)
  File "/app/argus_final/venv/lib/python2.7/site-packages/django/core/handlers/base.py", line 185, in _get_response
    response = wrapped_callback(request, *callback_args, **callback_kwargs)
  File "/app/argus_final/venv/lib/python2.7/site-packages/django/contrib/auth/decorators.py", line 23, in _wrapped_view
    return view_func(request, *args, **kwargs)
  File "/app/argus_final/venv/lib/python2.7/site-packages/django/views/generic/base.py", line 68, in view
    return self.dispatch(request, *args, **kwargs)
  File "/app/argus_final/app/argus/argus/mixins.py", line 14, in dispatch
    return super(GENERIC_PERMISSION_MIXIN, self).dispatch(request, *args, **kwargs)
  File "/app/argus_final/venv/lib/python2.7/site-packages/django/views/generic/base.py", line 88, in dispatch
    return handler(request, *args, **kwargs)
  File "/app/argus_final/app/argus/esync/views.py", line 169, in get
    context['keys'] = parse_standard_config(context['content'])
  File "/app/argus_final/app/argus/esync/lib/nginx_processor.py", line 11, in parse_standard_config
    rConfig = nginx.loads(config).as_dict
  File "/app/argus_final/venv/lib/python2.7/site-packages/nginx.py", line 402, in loads
    m = re.compile(r'^\s*events\s*{', re.S).search(data[index:])
TypeError: 'bool' object has no attribute '__getitem__'
2021-03-10 07:27:24,338 ERROR - Internal Server Error: /esync/om-fpms_pms_nginx/
Traceback (most recent call last):
  File "/app/argus_final/venv/lib/python2.7/site-packages/django/core/handlers/exception.py", line 41, in inner
    response = get_response(request)
  File "/app/argus_final/venv/lib/python2.7/site-packages/django/core/handlers/base.py", line 187, in _get_response
    response = self.process_exception_by_middleware(e, request)
  File "/app/argus_final/venv/lib/python2.7/site-packages/django/core/handlers/base.py", line 185, in _get_response
    response = wrapped_callback(request, *callback_args, **callback_kwargs)
  File "/app/argus_final/venv/lib/python2.7/site-packages/django/contrib/auth/decorators.py", line 23, in _wrapped_view
    return view_func(request, *args, **kwargs)
  File "/app/argus_final/venv/lib/python2.7/site-packages/django/views/generic/base.py", line 68, in view
    return self.dispatch(request, *args, **kwargs)
  File "/app/argus_final/app/argus/argus/mixins.py", line 14, in dispatch
    return super(GENERIC_PERMISSION_MIXIN, self).dispatch(request, *args, **kwargs)
  File "/app/argus_final/venv/lib/python2.7/site-packages/django/views/generic/base.py", line 88, in dispatch
    return handler(request, *args, **kwargs)
  File "/app/argus_final/app/argus/esync/views.py", line 169, in get
    context['keys'] = parse_standard_config(context['content'])
  File "/app/argus_final/app/argus/esync/lib/nginx_processor.py", line 11, in parse_standard_config
    rConfig = nginx.loads(config).as_dict
  File "/app/argus_final/venv/lib/python2.7/site-packages/nginx.py", line 402, in loads
    m = re.compile(r'^\s*events\s*{', re.S).search(data[index:])
TypeError: 'bool' object has no attribute '__getitem__'
2021-03-10 07:33:24,973 ERROR - Internal Server Error: /esync/om-fpms_pms_nginx/
Traceback (most recent call last):
  File "/app/argus_final/venv/lib/python2.7/site-packages/django/core/handlers/exception.py", line 41, in inner
    response = get_response(request)
  File "/app/argus_final/venv/lib/python2.7/site-packages/django/core/handlers/base.py", line 187, in _get_response
    response = self.process_exception_by_middleware(e, request)
  File "/app/argus_final/venv/lib/python2.7/site-packages/django/core/handlers/base.py", line 185, in _get_response
    response = wrapped_callback(request, *callback_args, **callback_kwargs)
  File "/app/argus_final/venv/lib/python2.7/site-packages/django/contrib/auth/decorators.py", line 23, in _wrapped_view
    return view_func(request, *args, **kwargs)
  File "/app/argus_final/venv/lib/python2.7/site-packages/django/views/generic/base.py", line 68, in view
    return self.dispatch(request, *args, **kwargs)
  File "/app/argus_final/app/argus/argus/mixins.py", line 14, in dispatch
    return super(GENERIC_PERMISSION_MIXIN, self).dispatch(request, *args, **kwargs)
  File "/app/argus_final/venv/lib/python2.7/site-packages/django/views/generic/base.py", line 88, in dispatch
    return handler(request, *args, **kwargs)
  File "/app/argus_final/app/argus/esync/views.py", line 169, in get
    context['keys'] = parse_standard_config(context['content'])
  File "/app/argus_final/app/argus/esync/lib/nginx_processor.py", line 11, in parse_standard_config
    rConfig = nginx.loads(config).as_dict
  File "/app/argus_final/venv/lib/python2.7/site-packages/nginx.py", line 402, in loads
    m = re.compile(r'^\s*events\s*{', re.S).search(data[index:])
TypeError: 'bool' object has no attribute '__getitem__'
2021-03-10 07:39:20,357 ERROR - Internal Server Error: /esync/om-fpms_pms_nginx/
Traceback (most recent call last):
  File "/app/argus_final/venv/lib/python2.7/site-packages/django/core/handlers/exception.py", line 41, in inner
    response = get_response(request)
  File "/app/argus_final/venv/lib/python2.7/site-packages/django/core/handlers/base.py", line 187, in _get_response
    response = self.process_exception_by_middleware(e, request)
  File "/app/argus_final/venv/lib/python2.7/site-packages/django/core/handlers/base.py", line 185, in _get_response
    response = wrapped_callback(request, *callback_args, **callback_kwargs)
  File "/app/argus_final/venv/lib/python2.7/site-packages/django/contrib/auth/decorators.py", line 23, in _wrapped_view
    return view_func(request, *args, **kwargs)
  File "/app/argus_final/venv/lib/python2.7/site-packages/django/views/generic/base.py", line 68, in view
    return self.dispatch(request, *args, **kwargs)
  File "/app/argus_final/app/argus/argus/mixins.py", line 14, in dispatch
    return super(GENERIC_PERMISSION_MIXIN, self).dispatch(request, *args, **kwargs)
  File "/app/argus_final/venv/lib/python2.7/site-packages/django/views/generic/base.py", line 88, in dispatch
    return handler(request, *args, **kwargs)
  File "/app/argus_final/app/argus/esync/views.py", line 169, in get
    context['keys'] = parse_standard_config(context['content'])
  File "/app/argus_final/app/argus/esync/lib/nginx_processor.py", line 11, in parse_standard_config
    rConfig = nginx.loads(config).as_dict
  File "/app/argus_final/venv/lib/python2.7/site-packages/nginx.py", line 402, in loads
    m = re.compile(r'^\s*events\s*{', re.S).search(data[index:])
TypeError: 'bool' object has no attribute '__getitem__'
2021-03-10 07:39:26,399 ERROR - Internal Server Error: /esync/om-fpms_pms_nginx/
Traceback (most recent call last):
  File "/app/argus_final/venv/lib/python2.7/site-packages/django/core/handlers/exception.py", line 41, in inner
    response = get_response(request)
  File "/app/argus_final/venv/lib/python2.7/site-packages/django/core/handlers/base.py", line 187, in _get_response
    response = self.process_exception_by_middleware(e, request)
  File "/app/argus_final/venv/lib/python2.7/site-packages/django/core/handlers/base.py", line 185, in _get_response
    response = wrapped_callback(request, *callback_args, **callback_kwargs)
  File "/app/argus_final/venv/lib/python2.7/site-packages/django/contrib/auth/decorators.py", line 23, in _wrapped_view
    return view_func(request, *args, **kwargs)
  File "/app/argus_final/venv/lib/python2.7/site-packages/django/views/generic/base.py", line 68, in view
    return self.dispatch(request, *args, **kwargs)
  File "/app/argus_final/app/argus/argus/mixins.py", line 14, in dispatch
    return super(GENERIC_PERMISSION_MIXIN, self).dispatch(request, *args, **kwargs)
  File "/app/argus_final/venv/lib/python2.7/site-packages/django/views/generic/base.py", line 88, in dispatch
    return handler(request, *args, **kwargs)
  File "/app/argus_final/app/argus/esync/views.py", line 169, in get
    context['keys'] = parse_standard_config(context['content'])
  File "/app/argus_final/app/argus/esync/lib/nginx_processor.py", line 11, in parse_standard_config
    rConfig = nginx.loads(config).as_dict
  File "/app/argus_final/venv/lib/python2.7/site-packages/nginx.py", line 402, in loads
    m = re.compile(r'^\s*events\s*{', re.S).search(data[index:])
TypeError: 'bool' object has no attribute '__getitem__'
2021-03-10 07:39:30,565 ERROR - Internal Server Error: /esync/om-fpms_pms_nginx/
Traceback (most recent call last):
  File "/app/argus_final/venv/lib/python2.7/site-packages/django/core/handlers/exception.py", line 41, in inner
    response = get_response(request)
  File "/app/argus_final/venv/lib/python2.7/site-packages/django/core/handlers/base.py", line 187, in _get_response
    response = self.process_exception_by_middleware(e, request)
  File "/app/argus_final/venv/lib/python2.7/site-packages/django/core/handlers/base.py", line 185, in _get_response
    response = wrapped_callback(request, *callback_args, **callback_kwargs)
  File "/app/argus_final/venv/lib/python2.7/site-packages/django/contrib/auth/decorators.py", line 23, in _wrapped_view
    return view_func(request, *args, **kwargs)
  File "/app/argus_final/venv/lib/python2.7/site-packages/django/views/generic/base.py", line 68, in view
    return self.dispatch(request, *args, **kwargs)
  File "/app/argus_final/app/argus/argus/mixins.py", line 14, in dispatch
    return super(GENERIC_PERMISSION_MIXIN, self).dispatch(request, *args, **kwargs)
  File "/app/argus_final/venv/lib/python2.7/site-packages/django/views/generic/base.py", line 88, in dispatch
    return handler(request, *args, **kwargs)
  File "/app/argus_final/app/argus/esync/views.py", line 169, in get
    context['keys'] = parse_standard_config(context['content'])
  File "/app/argus_final/app/argus/esync/lib/nginx_processor.py", line 11, in parse_standard_config
    rConfig = nginx.loads(config).as_dict
  File "/app/argus_final/venv/lib/python2.7/site-packages/nginx.py", line 402, in loads
    m = re.compile(r'^\s*events\s*{', re.S).search(data[index:])
TypeError: 'bool' object has no attribute '__getitem__'
2021-03-10 10:30:19,722 ERROR - Internal Server Error: /esync/om-fpms_pms_nginx/
Traceback (most recent call last):
  File "/app/argus_final/venv/lib/python2.7/site-packages/django/core/handlers/exception.py", line 41, in inner
    response = get_response(request)
  File "/app/argus_final/venv/lib/python2.7/site-packages/django/core/handlers/base.py", line 187, in _get_response
    response = self.process_exception_by_middleware(e, request)
  File "/app/argus_final/venv/lib/python2.7/site-packages/django/core/handlers/base.py", line 185, in _get_response
    response = wrapped_callback(request, *callback_args, **callback_kwargs)
  File "/app/argus_final/venv/lib/python2.7/site-packages/django/contrib/auth/decorators.py", line 23, in _wrapped_view
    return view_func(request, *args, **kwargs)
  File "/app/argus_final/venv/lib/python2.7/site-packages/django/views/generic/base.py", line 68, in view
    return self.dispatch(request, *args, **kwargs)
  File "/app/argus_final/app/argus/argus/mixins.py", line 14, in dispatch
    return super(GENERIC_PERMISSION_MIXIN, self).dispatch(request, *args, **kwargs)
  File "/app/argus_final/venv/lib/python2.7/site-packages/django/views/generic/base.py", line 88, in dispatch
    return handler(request, *args, **kwargs)
  File "/app/argus_final/app/argus/esync/views.py", line 169, in get
    context['keys'] = parse_standard_config(context['content'])
  File "/app/argus_final/app/argus/esync/lib/nginx_processor.py", line 11, in parse_standard_config
    rConfig = nginx.loads(config).as_dict
  File "/app/argus_final/venv/lib/python2.7/site-packages/nginx.py", line 402, in loads
    m = re.compile(r'^\s*events\s*{', re.S).search(data[index:])
TypeError: 'bool' object has no attribute '__getitem__'
2021-03-10 17:50:42,178 ERROR - Internal Server Error: /fwdcontrol/test-public-nginx/
Traceback (most recent call last):
  File "/app/argus_final/venv/lib/python2.7/site-packages/django/core/handlers/exception.py", line 41, in inner
    response = get_response(request)
  File "/app/argus_final/venv/lib/python2.7/site-packages/django/core/handlers/base.py", line 187, in _get_response
    response = self.process_exception_by_middleware(e, request)
  File "/app/argus_final/venv/lib/python2.7/site-packages/django/core/handlers/base.py", line 185, in _get_response
    response = wrapped_callback(request, *callback_args, **callback_kwargs)
  File "/app/argus_final/venv/lib/python2.7/site-packages/django/contrib/auth/decorators.py", line 23, in _wrapped_view
    return view_func(request, *args, **kwargs)
  File "/app/argus_final/venv/lib/python2.7/site-packages/django/views/generic/base.py", line 68, in view
    return self.dispatch(request, *args, **kwargs)
  File "/app/argus_final/venv/lib/python2.7/site-packages/django/utils/decorators.py", line 67, in _wrapper
    return bound_func(*args, **kwargs)
  File "/app/argus_final/venv/lib/python2.7/site-packages/django/views/decorators/csrf.py", line 58, in wrapped_view
    return view_func(*args, **kwargs)
  File "/app/argus_final/venv/lib/python2.7/site-packages/django/utils/decorators.py", line 63, in bound_func
    return func.__get__(self, type(self))(*args2, **kwargs2)
  File "/app/argus_final/app/argus/argus/mixins.py", line 14, in dispatch
    return super(GENERIC_PERMISSION_MIXIN, self).dispatch(request, *args, **kwargs)
  File "/app/argus_final/venv/lib/python2.7/site-packages/django/views/generic/base.py", line 88, in dispatch
    return handler(request, *args, **kwargs)
  File "/app/argus_final/app/argus/fwdcontrol/views.py", line 46, in get
    context['content'] = result.get()
  File "/app/argus_final/venv/lib/python2.7/site-packages/celery/result.py", line 224, in get
    on_message=on_message,
  File "/app/argus_final/venv/lib/python2.7/site-packages/celery/backends/async.py", line 190, in wait_for_pending
    return result.maybe_throw(callback=callback, propagate=propagate)
  File "/app/argus_final/venv/lib/python2.7/site-packages/celery/result.py", line 329, in maybe_throw
    self.throw(value, self._to_remote_traceback(tb))
  File "/app/argus_final/venv/lib/python2.7/site-packages/celery/result.py", line 322, in throw
    self.on_ready.throw(*args, **kwargs)
  File "/app/argus_final/venv/lib/python2.7/site-packages/vine/promises.py", line 217, in throw
    reraise(type(exc), exc, tb)
  File "<string>", line 1, in reraise
IOError: (u'[', u'E', u'r', u'r', u'n', u'o', u' ', u'2', u'1', u']', u' ', u'I', u's', u' ', u'a', u' ', u'd', u'i', u'r', u'e', u'c', u't', u'o', u'r', u'y', u':', u' ', u'u', u"'", u'/', u's', u'r', u'v', u'/', u't', u'e', u's', u't', u'-', u'p', u'u', u'b', u'l', u'i', u'c', u'-', u'n', u'g', u'i', u'n', u'x', u'/', u'c', u'o', u'n', u'f', u'.', u'd', u'/', u's', u's', u'l', u"'")
2021-03-10 17:50:55,399 ERROR - Internal Server Error: /fwdcontrol/test-public-nginx/
Traceback (most recent call last):
  File "/app/argus_final/venv/lib/python2.7/site-packages/django/core/handlers/exception.py", line 41, in inner
    response = get_response(request)
  File "/app/argus_final/venv/lib/python2.7/site-packages/django/core/handlers/base.py", line 187, in _get_response
    response = self.process_exception_by_middleware(e, request)
  File "/app/argus_final/venv/lib/python2.7/site-packages/django/core/handlers/base.py", line 185, in _get_response
    response = wrapped_callback(request, *callback_args, **callback_kwargs)
  File "/app/argus_final/venv/lib/python2.7/site-packages/django/contrib/auth/decorators.py", line 23, in _wrapped_view
    return view_func(request, *args, **kwargs)
  File "/app/argus_final/venv/lib/python2.7/site-packages/django/views/generic/base.py", line 68, in view
    return self.dispatch(request, *args, **kwargs)
  File "/app/argus_final/venv/lib/python2.7/site-packages/django/utils/decorators.py", line 67, in _wrapper
    return bound_func(*args, **kwargs)
  File "/app/argus_final/venv/lib/python2.7/site-packages/django/views/decorators/csrf.py", line 58, in wrapped_view
    return view_func(*args, **kwargs)
  File "/app/argus_final/venv/lib/python2.7/site-packages/django/utils/decorators.py", line 63, in bound_func
    return func.__get__(self, type(self))(*args2, **kwargs2)
  File "/app/argus_final/app/argus/argus/mixins.py", line 14, in dispatch
    return super(GENERIC_PERMISSION_MIXIN, self).dispatch(request, *args, **kwargs)
  File "/app/argus_final/venv/lib/python2.7/site-packages/django/views/generic/base.py", line 88, in dispatch
    return handler(request, *args, **kwargs)
  File "/app/argus_final/app/argus/fwdcontrol/views.py", line 46, in get
    context['content'] = result.get()
  File "/app/argus_final/venv/lib/python2.7/site-packages/celery/result.py", line 224, in get
    on_message=on_message,
  File "/app/argus_final/venv/lib/python2.7/site-packages/celery/backends/async.py", line 190, in wait_for_pending
    return result.maybe_throw(callback=callback, propagate=propagate)
  File "/app/argus_final/venv/lib/python2.7/site-packages/celery/result.py", line 329, in maybe_throw
    self.throw(value, self._to_remote_traceback(tb))
  File "/app/argus_final/venv/lib/python2.7/site-packages/celery/result.py", line 322, in throw
    self.on_ready.throw(*args, **kwargs)
  File "/app/argus_final/venv/lib/python2.7/site-packages/vine/promises.py", line 217, in throw
    reraise(type(exc), exc, tb)
  File "<string>", line 1, in reraise
IOError: (u'[', u'E', u'r', u'r', u'n', u'o', u' ', u'2', u'1', u']', u' ', u'I', u's', u' ', u'a', u' ', u'd', u'i', u'r', u'e', u'c', u't', u'o', u'r', u'y', u':', u' ', u'u', u"'", u'/', u's', u'r', u'v', u'/', u't', u'e', u's', u't', u'-', u'p', u'u', u'b', u'l', u'i', u'c', u'-', u'n', u'g', u'i', u'n', u'x', u'/', u'c', u'o', u'n', u'f', u'.', u'd', u'/', u'l', u'e', u't', u's', u'e', u'n', u'c', u'r', u'y', u'p', u't', u'-', u's', u's', u'l', u"'")
2021-03-10 17:51:01,824 ERROR - Internal Server Error: /fwdcontrol/test-public-nginx/
Traceback (most recent call last):
  File "/app/argus_final/venv/lib/python2.7/site-packages/django/core/handlers/exception.py", line 41, in inner
    response = get_response(request)
  File "/app/argus_final/venv/lib/python2.7/site-packages/django/core/handlers/base.py", line 187, in _get_response
    response = self.process_exception_by_middleware(e, request)
  File "/app/argus_final/venv/lib/python2.7/site-packages/django/core/handlers/base.py", line 185, in _get_response
    response = wrapped_callback(request, *callback_args, **callback_kwargs)
  File "/app/argus_final/venv/lib/python2.7/site-packages/django/contrib/auth/decorators.py", line 23, in _wrapped_view
    return view_func(request, *args, **kwargs)
  File "/app/argus_final/venv/lib/python2.7/site-packages/django/views/generic/base.py", line 68, in view
    return self.dispatch(request, *args, **kwargs)
  File "/app/argus_final/venv/lib/python2.7/site-packages/django/utils/decorators.py", line 67, in _wrapper
    return bound_func(*args, **kwargs)
  File "/app/argus_final/venv/lib/python2.7/site-packages/django/views/decorators/csrf.py", line 58, in wrapped_view
    return view_func(*args, **kwargs)
  File "/app/argus_final/venv/lib/python2.7/site-packages/django/utils/decorators.py", line 63, in bound_func
    return func.__get__(self, type(self))(*args2, **kwargs2)
  File "/app/argus_final/app/argus/argus/mixins.py", line 14, in dispatch
    return super(GENERIC_PERMISSION_MIXIN, self).dispatch(request, *args, **kwargs)
  File "/app/argus_final/venv/lib/python2.7/site-packages/django/views/generic/base.py", line 88, in dispatch
    return handler(request, *args, **kwargs)
  File "/app/argus_final/app/argus/fwdcontrol/views.py", line 46, in get
    context['content'] = result.get()
  File "/app/argus_final/venv/lib/python2.7/site-packages/celery/result.py", line 224, in get
    on_message=on_message,
  File "/app/argus_final/venv/lib/python2.7/site-packages/celery/backends/async.py", line 190, in wait_for_pending
    return result.maybe_throw(callback=callback, propagate=propagate)
  File "/app/argus_final/venv/lib/python2.7/site-packages/celery/result.py", line 329, in maybe_throw
    self.throw(value, self._to_remote_traceback(tb))
  File "/app/argus_final/venv/lib/python2.7/site-packages/celery/result.py", line 322, in throw
    self.on_ready.throw(*args, **kwargs)
  File "/app/argus_final/venv/lib/python2.7/site-packages/vine/promises.py", line 217, in throw
    reraise(type(exc), exc, tb)
  File "<string>", line 1, in reraise
IOError: (u'[', u'E', u'r', u'r', u'n', u'o', u' ', u'2', u'1', u']', u' ', u'I', u's', u' ', u'a', u' ', u'd', u'i', u'r', u'e', u'c', u't', u'o', u'r', u'y', u':', u' ', u'u', u"'", u'/', u's', u'r', u'v', u'/', u't', u'e', u's', u't', u'-', u'p', u'u', u'b', u'l', u'i', u'c', u'-', u'n', u'g', u'i', u'n', u'x', u'/', u'c', u'o', u'n', u'f', u'.', u'd', u'/', u'l', u'e', u't', u's', u'e', u'n', u'c', u'r', u'y', u'p', u't', u'-', u's', u's', u'l', u"'")
2021-03-11 11:47:01,613 DEBUG - (lyden.reyes) - Successfully loaded and updated table
2021-03-11 12:02:49,438 DEBUG - (lyden.reyes) - Successfully loaded and updated table
2021-03-12 08:17:54,021 DEBUG - (jonas.nicanor) - Successfully loaded and updated table
2021-03-12 22:43:03,171 ERROR - Internal Server Error: /esync/om-fpms_pms_nginx/generate/
Traceback (most recent call last):
  File "/app/argus_final/venv/lib/python2.7/site-packages/django/core/handlers/exception.py", line 41, in inner
    response = get_response(request)
  File "/app/argus_final/venv/lib/python2.7/site-packages/django/core/handlers/base.py", line 187, in _get_response
    response = self.process_exception_by_middleware(e, request)
  File "/app/argus_final/venv/lib/python2.7/site-packages/django/core/handlers/base.py", line 185, in _get_response
    response = wrapped_callback(request, *callback_args, **callback_kwargs)
  File "/app/argus_final/venv/lib/python2.7/site-packages/django/contrib/auth/decorators.py", line 23, in _wrapped_view
    return view_func(request, *args, **kwargs)
  File "/app/argus_final/venv/lib/python2.7/site-packages/django/views/generic/base.py", line 68, in view
    return self.dispatch(request, *args, **kwargs)
  File "/app/argus_final/venv/lib/python2.7/site-packages/django/utils/decorators.py", line 67, in _wrapper
    return bound_func(*args, **kwargs)
  File "/app/argus_final/venv/lib/python2.7/site-packages/django/views/decorators/csrf.py", line 58, in wrapped_view
    return view_func(*args, **kwargs)
  File "/app/argus_final/venv/lib/python2.7/site-packages/django/utils/decorators.py", line 63, in bound_func
    return func.__get__(self, type(self))(*args2, **kwargs2)
  File "/app/argus_final/app/argus/argus/mixins.py", line 14, in dispatch
    return super(GENERIC_PERMISSION_MIXIN, self).dispatch(request, *args, **kwargs)
  File "/app/argus_final/venv/lib/python2.7/site-packages/django/views/generic/base.py", line 88, in dispatch
    return handler(request, *args, **kwargs)
  File "/app/argus_final/app/argus/esync/views.py", line 287, in post
    nonstandard_esync_log(hostgroup, request.user.username, [result[1]],activity_type='CREATE')
  File "/app/argus_final/app/argus/esync/lib/esync_logger.py", line 20, in nonstandard_esync_log
    f.write(i)
UnicodeEncodeError: 'ascii' codec can't encode characters in position 294-297: ordinal not in range(128)
2021-03-14 15:49:12,561 DEBUG - (nikko.aratan) - Successfully loaded and updated table
