2021-01-18 14:18:17,434 DEBUG - (jonas.nicanor) - Successfully loaded and updated table
2021-01-18 14:18:27,400 DEBUG - (jonas.nicanor) - Successfully loaded and updated table
2021-01-18 14:18:40,106 DEBUG - (jonas.nicanor) - Successfully loaded and updated table
2021-01-18 14:19:06,216 DEBUG - (jonas.nicanor) - Successfully loaded and updated table
2021-01-18 14:19:15,631 DEBUG - (jonas.nicanor) - Successfully loaded and updated table
2021-01-19 14:35:29,976 ERROR - Internal Server Error: /fwdcontrol/test-public-nginx/
Traceback (most recent call last):
  File "/app/argus_final/venv/lib/python2.7/site-packages/django/core/handlers/exception.py", line 41, in inner
    response = get_response(request)
  File "/app/argus_final/venv/lib/python2.7/site-packages/django/core/handlers/base.py", line 187, in _get_response
    response = self.process_exception_by_middleware(e, request)
  File "/app/argus_final/venv/lib/python2.7/site-packages/django/core/handlers/base.py", line 185, in _get_response
    response = wrapped_callback(request, *callback_args, **callback_kwargs)
  File "/app/argus_final/venv/lib/python2.7/site-packages/django/contrib/auth/decorators.py", line 23, in _wrapped_view
    return view_func(request, *args, **kwargs)
  File "/app/argus_final/venv/lib/python2.7/site-packages/django/views/generic/base.py", line 68, in view
    return self.dispatch(request, *args, **kwargs)
  File "/app/argus_final/venv/lib/python2.7/site-packages/django/utils/decorators.py", line 67, in _wrapper
    return bound_func(*args, **kwargs)
  File "/app/argus_final/venv/lib/python2.7/site-packages/django/views/decorators/csrf.py", line 58, in wrapped_view
    return view_func(*args, **kwargs)
  File "/app/argus_final/venv/lib/python2.7/site-packages/django/utils/decorators.py", line 63, in bound_func
    return func.__get__(self, type(self))(*args2, **kwargs2)
  File "/app/argus_final/app/argus/argus/mixins.py", line 14, in dispatch
    return super(GENERIC_PERMISSION_MIXIN, self).dispatch(request, *args, **kwargs)
  File "/app/argus_final/venv/lib/python2.7/site-packages/django/views/generic/base.py", line 88, in dispatch
    return handler(request, *args, **kwargs)
  File "/app/argus_final/app/argus/fwdcontrol/views.py", line 46, in get
    context['content'] = result.get()
  File "/app/argus_final/venv/lib/python2.7/site-packages/celery/result.py", line 224, in get
    on_message=on_message,
  File "/app/argus_final/venv/lib/python2.7/site-packages/celery/backends/async.py", line 190, in wait_for_pending
    return result.maybe_throw(callback=callback, propagate=propagate)
  File "/app/argus_final/venv/lib/python2.7/site-packages/celery/result.py", line 329, in maybe_throw
    self.throw(value, self._to_remote_traceback(tb))
  File "/app/argus_final/venv/lib/python2.7/site-packages/celery/result.py", line 322, in throw
    self.on_ready.throw(*args, **kwargs)
  File "/app/argus_final/venv/lib/python2.7/site-packages/vine/promises.py", line 217, in throw
    reraise(type(exc), exc, tb)
  File "<string>", line 1, in reraise
IOError: (u'[', u'E', u'r', u'r', u'n', u'o', u' ', u'2', u'1', u']', u' ', u'I', u's', u' ', u'a', u' ', u'd', u'i', u'r', u'e', u'c', u't', u'o', u'r', u'y', u':', u' ', u'u', u"'", u'/', u's', u'r', u'v', u'/', u't', u'e', u's', u't', u'-', u'p', u'u', u'b', u'l', u'i', u'c', u'-', u'n', u'g', u'i', u'n', u'x', u'/', u'c', u'o', u'n', u'f', u'.', u'd', u'/', u's', u's', u'l', u"'")
