2020-07-16 10:20:40,292 DEBUG - (terrytang) - Successfully loaded and updated table
2020-07-16 14:44:10,418 DEBUG - (carl.dasig) - Successfully loaded and updated table
2020-07-16 15:34:38,780 DEBUG - (AnonymousUser) - Successfully loaded and updated table
2020-07-16 17:14:42,035 ERROR - Internal Server Error: /esync/om-cdn_nginx/
Traceback (most recent call last):
  File "/app/argus_final/venv/lib/python2.7/site-packages/django/core/handlers/exception.py", line 41, in inner
    response = get_response(request)
  File "/app/argus_final/venv/lib/python2.7/site-packages/django/core/handlers/base.py", line 187, in _get_response
    response = self.process_exception_by_middleware(e, request)
  File "/app/argus_final/venv/lib/python2.7/site-packages/django/core/handlers/base.py", line 185, in _get_response
    response = wrapped_callback(request, *callback_args, **callback_kwargs)
  File "/app/argus_final/venv/lib/python2.7/site-packages/django/contrib/auth/decorators.py", line 23, in _wrapped_view
    return view_func(request, *args, **kwargs)
  File "/app/argus_final/venv/lib/python2.7/site-packages/django/views/generic/base.py", line 68, in view
    return self.dispatch(request, *args, **kwargs)
  File "/app/argus_final/app/argus/argus/mixins.py", line 14, in dispatch
    return super(GENERIC_PERMISSION_MIXIN, self).dispatch(request, *args, **kwargs)
  File "/app/argus_final/venv/lib/python2.7/site-packages/django/views/generic/base.py", line 88, in dispatch
    return handler(request, *args, **kwargs)
  File "/app/argus_final/app/argus/esync/views.py", line 172, in get
    queue='qesync_agent'
  File "/app/argus_final/venv/lib/python2.7/site-packages/celery/result.py", line 224, in get
    on_message=on_message,
  File "/app/argus_final/venv/lib/python2.7/site-packages/celery/backends/async.py", line 190, in wait_for_pending
    return result.maybe_throw(callback=callback, propagate=propagate)
  File "/app/argus_final/venv/lib/python2.7/site-packages/celery/result.py", line 329, in maybe_throw
    self.throw(value, self._to_remote_traceback(tb))
  File "/app/argus_final/venv/lib/python2.7/site-packages/celery/result.py", line 322, in throw
    self.on_ready.throw(*args, **kwargs)
  File "/app/argus_final/venv/lib/python2.7/site-packages/vine/promises.py", line 217, in throw
    reraise(type(exc), exc, tb)
  File "<string>", line 1, in reraise
UnicodeEncodeError: (u"'", u'a', u's', u'c', u'i', u'i', u"'", u' ', u'c', u'o', u'd', u'e', u'c', u' ', u'c', u'a', u'n', u"'", u't', u' ', u'e', u'n', u'c', u'o', u'd', u'e', u' ', u'c', u'h', u'a', u'r', u'a', u'c', u't', u'e', u'r', u's', u' ', u'i', u'n', u' ', u'p', u'o', u's', u'i', u't', u'i', u'o', u'n', u' ', u'0', u'-', u'1', u':', u' ', u'o', u'r', u'd', u'i', u'n', u'a', u'l', u' ', u'n', u'o', u't', u' ', u'i', u'n', u' ', u'r', u'a', u'n', u'g', u'e', u'(', u'1', u'2', u'8', u')')
2020-07-16 18:03:32,731 DEBUG - (rock.lim) - Successfully loaded and updated table
