2021-03-09 05:01:07,089 DEBUG - (nikko.aratan) - Successfully loaded and updated table
2021-03-09 05:01:19,876 DEBUG - (nikko.aratan) - Successfully loaded and updated table
2021-03-09 05:09:30,634 DEBUG - (nikko.aratan) - Successfully loaded and updated table
2021-03-09 05:41:23,121 DEBUG - (nikko.aratan) - Successfully loaded and updated table
2021-03-09 05:41:31,854 DEBUG - (nikko.aratan) - Successfully loaded and updated table
2021-03-09 08:53:43,072 DEBUG - (jonas.nicanor) - Successfully loaded and updated table
2021-03-09 08:53:56,429 DEBUG - (jonas.nicanor) - Successfully loaded and updated table
2021-03-09 10:22:13,737 DEBUG - (jonas.nicanor) - Successfully loaded and updated table
2021-03-09 10:44:45,026 ERROR - Internal Server Error: /esync/acc-midpay_nginx/generate/
Traceback (most recent call last):
  File "/app/argus_final/venv/lib/python2.7/site-packages/django/core/handlers/exception.py", line 41, in inner
    response = get_response(request)
  File "/app/argus_final/venv/lib/python2.7/site-packages/django/core/handlers/base.py", line 187, in _get_response
    response = self.process_exception_by_middleware(e, request)
  File "/app/argus_final/venv/lib/python2.7/site-packages/django/core/handlers/base.py", line 185, in _get_response
    response = wrapped_callback(request, *callback_args, **callback_kwargs)
  File "/app/argus_final/venv/lib/python2.7/site-packages/django/contrib/auth/decorators.py", line 23, in _wrapped_view
    return view_func(request, *args, **kwargs)
  File "/app/argus_final/venv/lib/python2.7/site-packages/django/views/generic/base.py", line 68, in view
    return self.dispatch(request, *args, **kwargs)
  File "/app/argus_final/venv/lib/python2.7/site-packages/django/utils/decorators.py", line 67, in _wrapper
    return bound_func(*args, **kwargs)
  File "/app/argus_final/venv/lib/python2.7/site-packages/django/views/decorators/csrf.py", line 58, in wrapped_view
    return view_func(*args, **kwargs)
  File "/app/argus_final/venv/lib/python2.7/site-packages/django/utils/decorators.py", line 63, in bound_func
    return func.__get__(self, type(self))(*args2, **kwargs2)
  File "/app/argus_final/app/argus/argus/mixins.py", line 14, in dispatch
    return super(GENERIC_PERMISSION_MIXIN, self).dispatch(request, *args, **kwargs)
  File "/app/argus_final/venv/lib/python2.7/site-packages/django/views/generic/base.py", line 88, in dispatch
    return handler(request, *args, **kwargs)
  File "/app/argus_final/app/argus/esync/views.py", line 287, in post
    nonstandard_esync_log(hostgroup, request.user.username, [result[1]],activity_type='CREATE')
  File "/app/argus_final/app/argus/esync/lib/esync_logger.py", line 20, in nonstandard_esync_log
    f.write(i)
UnicodeEncodeError: 'ascii' codec can't encode characters in position 198-201: ordinal not in range(128)
2021-03-09 10:45:53,386 ERROR - Internal Server Error: /esync/acc-midpay_nginx/generate/
Traceback (most recent call last):
  File "/app/argus_final/venv/lib/python2.7/site-packages/django/core/handlers/exception.py", line 41, in inner
    response = get_response(request)
  File "/app/argus_final/venv/lib/python2.7/site-packages/django/core/handlers/base.py", line 187, in _get_response
    response = self.process_exception_by_middleware(e, request)
  File "/app/argus_final/venv/lib/python2.7/site-packages/django/core/handlers/base.py", line 185, in _get_response
    response = wrapped_callback(request, *callback_args, **callback_kwargs)
  File "/app/argus_final/venv/lib/python2.7/site-packages/django/contrib/auth/decorators.py", line 23, in _wrapped_view
    return view_func(request, *args, **kwargs)
  File "/app/argus_final/venv/lib/python2.7/site-packages/django/views/generic/base.py", line 68, in view
    return self.dispatch(request, *args, **kwargs)
  File "/app/argus_final/venv/lib/python2.7/site-packages/django/utils/decorators.py", line 67, in _wrapper
    return bound_func(*args, **kwargs)
  File "/app/argus_final/venv/lib/python2.7/site-packages/django/views/decorators/csrf.py", line 58, in wrapped_view
    return view_func(*args, **kwargs)
  File "/app/argus_final/venv/lib/python2.7/site-packages/django/utils/decorators.py", line 63, in bound_func
    return func.__get__(self, type(self))(*args2, **kwargs2)
  File "/app/argus_final/app/argus/argus/mixins.py", line 14, in dispatch
    return super(GENERIC_PERMISSION_MIXIN, self).dispatch(request, *args, **kwargs)
  File "/app/argus_final/venv/lib/python2.7/site-packages/django/views/generic/base.py", line 88, in dispatch
    return handler(request, *args, **kwargs)
  File "/app/argus_final/app/argus/esync/views.py", line 287, in post
    nonstandard_esync_log(hostgroup, request.user.username, [result[1]],activity_type='CREATE')
  File "/app/argus_final/app/argus/esync/lib/esync_logger.py", line 20, in nonstandard_esync_log
    f.write(i)
UnicodeEncodeError: 'ascii' codec can't encode characters in position 203-206: ordinal not in range(128)
2021-03-09 10:58:12,484 ERROR - Internal Server Error: /esync/acc-midpay_nginx/generate/
Traceback (most recent call last):
  File "/app/argus_final/venv/lib/python2.7/site-packages/django/core/handlers/exception.py", line 41, in inner
    response = get_response(request)
  File "/app/argus_final/venv/lib/python2.7/site-packages/django/core/handlers/base.py", line 187, in _get_response
    response = self.process_exception_by_middleware(e, request)
  File "/app/argus_final/venv/lib/python2.7/site-packages/django/core/handlers/base.py", line 185, in _get_response
    response = wrapped_callback(request, *callback_args, **callback_kwargs)
  File "/app/argus_final/venv/lib/python2.7/site-packages/django/contrib/auth/decorators.py", line 23, in _wrapped_view
    return view_func(request, *args, **kwargs)
  File "/app/argus_final/venv/lib/python2.7/site-packages/django/views/generic/base.py", line 68, in view
    return self.dispatch(request, *args, **kwargs)
  File "/app/argus_final/venv/lib/python2.7/site-packages/django/utils/decorators.py", line 67, in _wrapper
    return bound_func(*args, **kwargs)
  File "/app/argus_final/venv/lib/python2.7/site-packages/django/views/decorators/csrf.py", line 58, in wrapped_view
    return view_func(*args, **kwargs)
  File "/app/argus_final/venv/lib/python2.7/site-packages/django/utils/decorators.py", line 63, in bound_func
    return func.__get__(self, type(self))(*args2, **kwargs2)
  File "/app/argus_final/app/argus/argus/mixins.py", line 14, in dispatch
    return super(GENERIC_PERMISSION_MIXIN, self).dispatch(request, *args, **kwargs)
  File "/app/argus_final/venv/lib/python2.7/site-packages/django/views/generic/base.py", line 88, in dispatch
    return handler(request, *args, **kwargs)
  File "/app/argus_final/app/argus/esync/views.py", line 287, in post
    nonstandard_esync_log(hostgroup, request.user.username, [result[1]],activity_type='CREATE')
  File "/app/argus_final/app/argus/esync/lib/esync_logger.py", line 20, in nonstandard_esync_log
    f.write(i)
UnicodeEncodeError: 'ascii' codec can't encode characters in position 297-303: ordinal not in range(128)
2021-03-09 10:59:14,813 ERROR - Internal Server Error: /esync/acc-midpay_nginx/generate/
Traceback (most recent call last):
  File "/app/argus_final/venv/lib/python2.7/site-packages/django/core/handlers/exception.py", line 41, in inner
    response = get_response(request)
  File "/app/argus_final/venv/lib/python2.7/site-packages/django/core/handlers/base.py", line 187, in _get_response
    response = self.process_exception_by_middleware(e, request)
  File "/app/argus_final/venv/lib/python2.7/site-packages/django/core/handlers/base.py", line 185, in _get_response
    response = wrapped_callback(request, *callback_args, **callback_kwargs)
  File "/app/argus_final/venv/lib/python2.7/site-packages/django/contrib/auth/decorators.py", line 23, in _wrapped_view
    return view_func(request, *args, **kwargs)
  File "/app/argus_final/venv/lib/python2.7/site-packages/django/views/generic/base.py", line 68, in view
    return self.dispatch(request, *args, **kwargs)
  File "/app/argus_final/venv/lib/python2.7/site-packages/django/utils/decorators.py", line 67, in _wrapper
    return bound_func(*args, **kwargs)
  File "/app/argus_final/venv/lib/python2.7/site-packages/django/views/decorators/csrf.py", line 58, in wrapped_view
    return view_func(*args, **kwargs)
  File "/app/argus_final/venv/lib/python2.7/site-packages/django/utils/decorators.py", line 63, in bound_func
    return func.__get__(self, type(self))(*args2, **kwargs2)
  File "/app/argus_final/app/argus/argus/mixins.py", line 14, in dispatch
    return super(GENERIC_PERMISSION_MIXIN, self).dispatch(request, *args, **kwargs)
  File "/app/argus_final/venv/lib/python2.7/site-packages/django/views/generic/base.py", line 88, in dispatch
    return handler(request, *args, **kwargs)
  File "/app/argus_final/app/argus/esync/views.py", line 287, in post
    nonstandard_esync_log(hostgroup, request.user.username, [result[1]],activity_type='CREATE')
  File "/app/argus_final/app/argus/esync/lib/esync_logger.py", line 20, in nonstandard_esync_log
    f.write(i)
UnicodeEncodeError: 'ascii' codec can't encode characters in position 322-328: ordinal not in range(128)
2021-03-09 12:36:12,167 DEBUG - (jonas.nicanor) - Successfully loaded and updated table
2021-03-09 12:36:22,660 DEBUG - (jonas.nicanor) - Successfully loaded and updated table
2021-03-09 12:36:30,618 DEBUG - (jonas.nicanor) - Successfully loaded and updated table
2021-03-09 14:05:21,550 ERROR - Internal Server Error: /esync/om-fpms_pms_nginx/
Traceback (most recent call last):
  File "/app/argus_final/venv/lib/python2.7/site-packages/django/core/handlers/exception.py", line 41, in inner
    response = get_response(request)
  File "/app/argus_final/venv/lib/python2.7/site-packages/django/core/handlers/base.py", line 187, in _get_response
    response = self.process_exception_by_middleware(e, request)
  File "/app/argus_final/venv/lib/python2.7/site-packages/django/core/handlers/base.py", line 185, in _get_response
    response = wrapped_callback(request, *callback_args, **callback_kwargs)
  File "/app/argus_final/venv/lib/python2.7/site-packages/django/contrib/auth/decorators.py", line 23, in _wrapped_view
    return view_func(request, *args, **kwargs)
  File "/app/argus_final/venv/lib/python2.7/site-packages/django/views/generic/base.py", line 68, in view
    return self.dispatch(request, *args, **kwargs)
  File "/app/argus_final/app/argus/argus/mixins.py", line 14, in dispatch
    return super(GENERIC_PERMISSION_MIXIN, self).dispatch(request, *args, **kwargs)
  File "/app/argus_final/venv/lib/python2.7/site-packages/django/views/generic/base.py", line 88, in dispatch
    return handler(request, *args, **kwargs)
  File "/app/argus_final/app/argus/esync/views.py", line 169, in get
    context['keys'] = parse_standard_config(context['content'])
  File "/app/argus_final/app/argus/esync/lib/nginx_processor.py", line 11, in parse_standard_config
    rConfig = nginx.loads(config).as_dict
  File "/app/argus_final/venv/lib/python2.7/site-packages/nginx.py", line 402, in loads
    m = re.compile(r'^\s*events\s*{', re.S).search(data[index:])
TypeError: 'bool' object has no attribute '__getitem__'
2021-03-09 14:05:33,095 ERROR - Internal Server Error: /esync/om-fpms_pms_nginx/
Traceback (most recent call last):
  File "/app/argus_final/venv/lib/python2.7/site-packages/django/core/handlers/exception.py", line 41, in inner
    response = get_response(request)
  File "/app/argus_final/venv/lib/python2.7/site-packages/django/core/handlers/base.py", line 187, in _get_response
    response = self.process_exception_by_middleware(e, request)
  File "/app/argus_final/venv/lib/python2.7/site-packages/django/core/handlers/base.py", line 185, in _get_response
    response = wrapped_callback(request, *callback_args, **callback_kwargs)
  File "/app/argus_final/venv/lib/python2.7/site-packages/django/contrib/auth/decorators.py", line 23, in _wrapped_view
    return view_func(request, *args, **kwargs)
  File "/app/argus_final/venv/lib/python2.7/site-packages/django/views/generic/base.py", line 68, in view
    return self.dispatch(request, *args, **kwargs)
  File "/app/argus_final/app/argus/argus/mixins.py", line 14, in dispatch
    return super(GENERIC_PERMISSION_MIXIN, self).dispatch(request, *args, **kwargs)
  File "/app/argus_final/venv/lib/python2.7/site-packages/django/views/generic/base.py", line 88, in dispatch
    return handler(request, *args, **kwargs)
  File "/app/argus_final/app/argus/esync/views.py", line 169, in get
    context['keys'] = parse_standard_config(context['content'])
  File "/app/argus_final/app/argus/esync/lib/nginx_processor.py", line 11, in parse_standard_config
    rConfig = nginx.loads(config).as_dict
  File "/app/argus_final/venv/lib/python2.7/site-packages/nginx.py", line 402, in loads
    m = re.compile(r'^\s*events\s*{', re.S).search(data[index:])
TypeError: 'bool' object has no attribute '__getitem__'
2021-03-09 15:20:02,310 ERROR - Internal Server Error: /esync/om-fpms_pms_nginx/generate/
Traceback (most recent call last):
  File "/app/argus_final/venv/lib/python2.7/site-packages/django/core/handlers/exception.py", line 41, in inner
    response = get_response(request)
  File "/app/argus_final/venv/lib/python2.7/site-packages/django/core/handlers/base.py", line 187, in _get_response
    response = self.process_exception_by_middleware(e, request)
  File "/app/argus_final/venv/lib/python2.7/site-packages/django/core/handlers/base.py", line 185, in _get_response
    response = wrapped_callback(request, *callback_args, **callback_kwargs)
  File "/app/argus_final/venv/lib/python2.7/site-packages/django/contrib/auth/decorators.py", line 23, in _wrapped_view
    return view_func(request, *args, **kwargs)
  File "/app/argus_final/venv/lib/python2.7/site-packages/django/views/generic/base.py", line 68, in view
    return self.dispatch(request, *args, **kwargs)
  File "/app/argus_final/venv/lib/python2.7/site-packages/django/utils/decorators.py", line 67, in _wrapper
    return bound_func(*args, **kwargs)
  File "/app/argus_final/venv/lib/python2.7/site-packages/django/views/decorators/csrf.py", line 58, in wrapped_view
    return view_func(*args, **kwargs)
  File "/app/argus_final/venv/lib/python2.7/site-packages/django/utils/decorators.py", line 63, in bound_func
    return func.__get__(self, type(self))(*args2, **kwargs2)
  File "/app/argus_final/app/argus/argus/mixins.py", line 14, in dispatch
    return super(GENERIC_PERMISSION_MIXIN, self).dispatch(request, *args, **kwargs)
  File "/app/argus_final/venv/lib/python2.7/site-packages/django/views/generic/base.py", line 88, in dispatch
    return handler(request, *args, **kwargs)
  File "/app/argus_final/app/argus/esync/views.py", line 287, in post
    nonstandard_esync_log(hostgroup, request.user.username, [result[1]],activity_type='CREATE')
  File "/app/argus_final/app/argus/esync/lib/esync_logger.py", line 20, in nonstandard_esync_log
    f.write(i)
UnicodeEncodeError: 'ascii' codec can't encode characters in position 307-308: ordinal not in range(128)
2021-03-09 15:27:20,036 DEBUG - (jonas.nicanor) - Successfully loaded and updated table
2021-03-09 15:27:41,898 DEBUG - (jonas.nicanor) - Successfully loaded and updated table
2021-03-09 17:10:51,915 ERROR - Internal Server Error: /esync/acc-midpay_nginx/generate/
Traceback (most recent call last):
  File "/app/argus_final/venv/lib/python2.7/site-packages/django/core/handlers/exception.py", line 41, in inner
    response = get_response(request)
  File "/app/argus_final/venv/lib/python2.7/site-packages/django/core/handlers/base.py", line 187, in _get_response
    response = self.process_exception_by_middleware(e, request)
  File "/app/argus_final/venv/lib/python2.7/site-packages/django/core/handlers/base.py", line 185, in _get_response
    response = wrapped_callback(request, *callback_args, **callback_kwargs)
  File "/app/argus_final/venv/lib/python2.7/site-packages/django/contrib/auth/decorators.py", line 23, in _wrapped_view
    return view_func(request, *args, **kwargs)
  File "/app/argus_final/venv/lib/python2.7/site-packages/django/views/generic/base.py", line 68, in view
    return self.dispatch(request, *args, **kwargs)
  File "/app/argus_final/venv/lib/python2.7/site-packages/django/utils/decorators.py", line 67, in _wrapper
    return bound_func(*args, **kwargs)
  File "/app/argus_final/venv/lib/python2.7/site-packages/django/views/decorators/csrf.py", line 58, in wrapped_view
    return view_func(*args, **kwargs)
  File "/app/argus_final/venv/lib/python2.7/site-packages/django/utils/decorators.py", line 63, in bound_func
    return func.__get__(self, type(self))(*args2, **kwargs2)
  File "/app/argus_final/app/argus/argus/mixins.py", line 14, in dispatch
    return super(GENERIC_PERMISSION_MIXIN, self).dispatch(request, *args, **kwargs)
  File "/app/argus_final/venv/lib/python2.7/site-packages/django/views/generic/base.py", line 88, in dispatch
    return handler(request, *args, **kwargs)
  File "/app/argus_final/app/argus/esync/views.py", line 287, in post
    nonstandard_esync_log(hostgroup, request.user.username, [result[1]],activity_type='CREATE')
  File "/app/argus_final/app/argus/esync/lib/esync_logger.py", line 20, in nonstandard_esync_log
    f.write(i)
UnicodeEncodeError: 'ascii' codec can't encode characters in position 297-303: ordinal not in range(128)
2021-03-09 17:12:04,113 ERROR - Internal Server Error: /esync/acc-midpay_nginx/generate/
Traceback (most recent call last):
  File "/app/argus_final/venv/lib/python2.7/site-packages/django/core/handlers/exception.py", line 41, in inner
    response = get_response(request)
  File "/app/argus_final/venv/lib/python2.7/site-packages/django/core/handlers/base.py", line 187, in _get_response
    response = self.process_exception_by_middleware(e, request)
  File "/app/argus_final/venv/lib/python2.7/site-packages/django/core/handlers/base.py", line 185, in _get_response
    response = wrapped_callback(request, *callback_args, **callback_kwargs)
  File "/app/argus_final/venv/lib/python2.7/site-packages/django/contrib/auth/decorators.py", line 23, in _wrapped_view
    return view_func(request, *args, **kwargs)
  File "/app/argus_final/venv/lib/python2.7/site-packages/django/views/generic/base.py", line 68, in view
    return self.dispatch(request, *args, **kwargs)
  File "/app/argus_final/venv/lib/python2.7/site-packages/django/utils/decorators.py", line 67, in _wrapper
    return bound_func(*args, **kwargs)
  File "/app/argus_final/venv/lib/python2.7/site-packages/django/views/decorators/csrf.py", line 58, in wrapped_view
    return view_func(*args, **kwargs)
  File "/app/argus_final/venv/lib/python2.7/site-packages/django/utils/decorators.py", line 63, in bound_func
    return func.__get__(self, type(self))(*args2, **kwargs2)
  File "/app/argus_final/app/argus/argus/mixins.py", line 14, in dispatch
    return super(GENERIC_PERMISSION_MIXIN, self).dispatch(request, *args, **kwargs)
  File "/app/argus_final/venv/lib/python2.7/site-packages/django/views/generic/base.py", line 88, in dispatch
    return handler(request, *args, **kwargs)
  File "/app/argus_final/app/argus/esync/views.py", line 287, in post
    nonstandard_esync_log(hostgroup, request.user.username, [result[1]],activity_type='CREATE')
  File "/app/argus_final/app/argus/esync/lib/esync_logger.py", line 20, in nonstandard_esync_log
    f.write(i)
UnicodeEncodeError: 'ascii' codec can't encode characters in position 287-293: ordinal not in range(128)
2021-03-10 01:01:40,533 DEBUG - starting thread (client mode): 0xc542efd0L
2021-03-10 01:01:40,533 DEBUG - Local version/idstring: SSH-2.0-paramiko_2.6.0
2021-03-10 01:01:40,548 DEBUG - Remote version/idstring: SSH-2.0-OpenSSH_7.4
2021-03-10 01:01:40,548 INFO - Connected (version 2.0, client OpenSSH_7.4)
2021-03-10 01:01:40,550 DEBUG - kex algos:[u'curve25519-sha256', u'curve25519-sha256@libssh.org', u'ecdh-sha2-nistp256', u'ecdh-sha2-nistp384', u'ecdh-sha2-nistp521', u'diffie-hellman-group-exchange-sha256', u'diffie-hellman-group16-sha512', u'diffie-hellman-group18-sha512', u'diffie-hellman-group-exchange-sha1', u'diffie-hellman-group14-sha256', u'diffie-hellman-group14-sha1', u'diffie-hellman-group1-sha1'] server key:[u'ssh-rsa', u'rsa-sha2-512', u'rsa-sha2-256', u'ecdsa-sha2-nistp256', u'ssh-ed25519'] client encrypt:[u'chacha20-poly1305@openssh.com', u'aes128-ctr', u'aes192-ctr', u'aes256-ctr', u'aes128-gcm@openssh.com', u'aes256-gcm@openssh.com', u'aes128-cbc', u'aes192-cbc', u'aes256-cbc', u'blowfish-cbc', u'cast128-cbc', u'3des-cbc'] server encrypt:[u'chacha20-poly1305@openssh.com', u'aes128-ctr', u'aes192-ctr', u'aes256-ctr', u'aes128-gcm@openssh.com', u'aes256-gcm@openssh.com', u'aes128-cbc', u'aes192-cbc', u'aes256-cbc', u'blowfish-cbc', u'cast128-cbc', u'3des-cbc'] client mac:[u'umac-64-etm@openssh.com', u'umac-128-etm@openssh.com', u'hmac-sha2-256-etm@openssh.com', u'hmac-sha2-512-etm@openssh.com', u'hmac-sha1-etm@openssh.com', u'umac-64@openssh.com', u'umac-128@openssh.com', u'hmac-sha2-256', u'hmac-sha2-512', u'hmac-sha1'] server mac:[u'umac-64-etm@openssh.com', u'umac-128-etm@openssh.com', u'hmac-sha2-256-etm@openssh.com', u'hmac-sha2-512-etm@openssh.com', u'hmac-sha1-etm@openssh.com', u'umac-64@openssh.com', u'umac-128@openssh.com', u'hmac-sha2-256', u'hmac-sha2-512', u'hmac-sha1'] client compress:[u'none', u'zlib@openssh.com'] server compress:[u'none', u'zlib@openssh.com'] client lang:[u''] server lang:[u''] kex follows?False
2021-03-10 01:01:40,551 DEBUG - Kex agreed: curve25519-sha256@libssh.org
2021-03-10 01:01:40,551 DEBUG - HostKey agreed: ssh-ed25519
2021-03-10 01:01:40,551 DEBUG - Cipher agreed: aes128-ctr
2021-03-10 01:01:40,551 DEBUG - MAC agreed: hmac-sha2-256
2021-03-10 01:01:40,551 DEBUG - Compression agreed: none
2021-03-10 01:01:40,561 DEBUG - kex engine KexCurve25519 specified hash_algo <built-in function openssl_sha256>
2021-03-10 01:01:40,562 DEBUG - Switch to new keys ...
2021-03-10 01:01:40,567 DEBUG - Adding ssh-ed25519 host key for [58.64.167.40]:28032: 649bfb2ade50b259183468bcc4a641be
2021-03-10 01:01:40,568 DEBUG - Trying discovered key f1e2a20412f7e99b7abdb041b22f15e1 in /root/.ssh/id_rsa
2021-03-10 01:01:40,602 DEBUG - userauth is OK
2021-03-10 01:01:45,629 INFO - Authentication (publickey) successful!
2021-03-10 01:01:45,638 DEBUG - [chan 0] Max packet in: 32768 bytes
2021-03-10 01:01:45,648 DEBUG - Received global request "hostkeys-00@openssh.com"
2021-03-10 01:01:45,648 DEBUG - Rejecting "hostkeys-00@openssh.com" global request from server.
2021-03-10 01:01:45,649 DEBUG - Debug msg: Adding to environment: NAME=argus
2021-03-10 01:01:45,689 DEBUG - [chan 0] Max packet out: 32768 bytes
2021-03-10 01:01:45,689 DEBUG - Secsh channel 0 opened.
2021-03-10 01:01:45,707 DEBUG - [chan 0] Sesch channel 0 request ok
2021-03-10 01:01:45,711 DEBUG - [chan 0] Sesch channel 0 request ok
2021-03-10 01:01:45,712 DEBUG - [chan 1] Max packet in: 32768 bytes
2021-03-10 01:01:45,713 DEBUG - [chan 1] Max packet out: 32768 bytes
2021-03-10 01:01:45,713 DEBUG - Secsh channel 1 opened.
2021-03-10 01:01:45,720 DEBUG - [chan 1] Sesch channel 1 request ok
2021-03-10 01:01:56,196 DEBUG - [chan 2] Max packet in: 32768 bytes
2021-03-10 01:01:56,198 DEBUG - [chan 1] EOF received (1)
2021-03-10 01:01:56,199 DEBUG - [chan 1] EOF sent (1)
2021-03-10 01:01:56,226 DEBUG - [chan 2] Max packet out: 32768 bytes
2021-03-10 01:01:56,226 DEBUG - Secsh channel 2 opened.
2021-03-10 01:01:56,281 DEBUG - [chan 2] Sesch channel 2 request ok
2021-03-10 01:01:56,330 DEBUG - [chan 2] EOF received (2)
2021-03-10 01:01:56,330 DEBUG - [chan 2] EOF sent (2)
2021-03-10 01:01:56,331 DEBUG - EOF in transport thread
2021-03-10 07:23:58,808 ERROR - Internal Server Error: /esync/om-fpms_pms_nginx/
Traceback (most recent call last):
  File "/app/argus_final/venv/lib/python2.7/site-packages/django/core/handlers/exception.py", line 41, in inner
    response = get_response(request)
  File "/app/argus_final/venv/lib/python2.7/site-packages/django/core/handlers/base.py", line 187, in _get_response
    response = self.process_exception_by_middleware(e, request)
  File "/app/argus_final/venv/lib/python2.7/site-packages/django/core/handlers/base.py", line 185, in _get_response
    response = wrapped_callback(request, *callback_args, **callback_kwargs)
  File "/app/argus_final/venv/lib/python2.7/site-packages/django/contrib/auth/decorators.py", line 23, in _wrapped_view
    return view_func(request, *args, **kwargs)
  File "/app/argus_final/venv/lib/python2.7/site-packages/django/views/generic/base.py", line 68, in view
    return self.dispatch(request, *args, **kwargs)
  File "/app/argus_final/app/argus/argus/mixins.py", line 14, in dispatch
    return super(GENERIC_PERMISSION_MIXIN, self).dispatch(request, *args, **kwargs)
  File "/app/argus_final/venv/lib/python2.7/site-packages/django/views/generic/base.py", line 88, in dispatch
    return handler(request, *args, **kwargs)
  File "/app/argus_final/app/argus/esync/views.py", line 169, in get
    context['keys'] = parse_standard_config(context['content'])
  File "/app/argus_final/app/argus/esync/lib/nginx_processor.py", line 11, in parse_standard_config
    rConfig = nginx.loads(config).as_dict
  File "/app/argus_final/venv/lib/python2.7/site-packages/nginx.py", line 402, in loads
    m = re.compile(r'^\s*events\s*{', re.S).search(data[index:])
TypeError: 'bool' object has no attribute '__getitem__'
2021-03-10 07:24:06,224 ERROR - Internal Server Error: /esync/om-fpms_pms_nginx/
Traceback (most recent call last):
  File "/app/argus_final/venv/lib/python2.7/site-packages/django/core/handlers/exception.py", line 41, in inner
    response = get_response(request)
  File "/app/argus_final/venv/lib/python2.7/site-packages/django/core/handlers/base.py", line 187, in _get_response
    response = self.process_exception_by_middleware(e, request)
  File "/app/argus_final/venv/lib/python2.7/site-packages/django/core/handlers/base.py", line 185, in _get_response
    response = wrapped_callback(request, *callback_args, **callback_kwargs)
  File "/app/argus_final/venv/lib/python2.7/site-packages/django/contrib/auth/decorators.py", line 23, in _wrapped_view
    return view_func(request, *args, **kwargs)
  File "/app/argus_final/venv/lib/python2.7/site-packages/django/views/generic/base.py", line 68, in view
    return self.dispatch(request, *args, **kwargs)
  File "/app/argus_final/app/argus/argus/mixins.py", line 14, in dispatch
    return super(GENERIC_PERMISSION_MIXIN, self).dispatch(request, *args, **kwargs)
  File "/app/argus_final/venv/lib/python2.7/site-packages/django/views/generic/base.py", line 88, in dispatch
    return handler(request, *args, **kwargs)
  File "/app/argus_final/app/argus/esync/views.py", line 169, in get
    context['keys'] = parse_standard_config(context['content'])
  File "/app/argus_final/app/argus/esync/lib/nginx_processor.py", line 11, in parse_standard_config
    rConfig = nginx.loads(config).as_dict
  File "/app/argus_final/venv/lib/python2.7/site-packages/nginx.py", line 402, in loads
    m = re.compile(r'^\s*events\s*{', re.S).search(data[index:])
TypeError: 'bool' object has no attribute '__getitem__'
2021-03-10 07:24:08,064 ERROR - Internal Server Error: /esync/om-fpms_pms_nginx/
Traceback (most recent call last):
  File "/app/argus_final/venv/lib/python2.7/site-packages/django/core/handlers/exception.py", line 41, in inner
    response = get_response(request)
  File "/app/argus_final/venv/lib/python2.7/site-packages/django/core/handlers/base.py", line 187, in _get_response
    response = self.process_exception_by_middleware(e, request)
  File "/app/argus_final/venv/lib/python2.7/site-packages/django/core/handlers/base.py", line 185, in _get_response
    response = wrapped_callback(request, *callback_args, **callback_kwargs)
  File "/app/argus_final/venv/lib/python2.7/site-packages/django/contrib/auth/decorators.py", line 23, in _wrapped_view
    return view_func(request, *args, **kwargs)
  File "/app/argus_final/venv/lib/python2.7/site-packages/django/views/generic/base.py", line 68, in view
    return self.dispatch(request, *args, **kwargs)
  File "/app/argus_final/app/argus/argus/mixins.py", line 14, in dispatch
    return super(GENERIC_PERMISSION_MIXIN, self).dispatch(request, *args, **kwargs)
  File "/app/argus_final/venv/lib/python2.7/site-packages/django/views/generic/base.py", line 88, in dispatch
    return handler(request, *args, **kwargs)
  File "/app/argus_final/app/argus/esync/views.py", line 169, in get
    context['keys'] = parse_standard_config(context['content'])
  File "/app/argus_final/app/argus/esync/lib/nginx_processor.py", line 11, in parse_standard_config
    rConfig = nginx.loads(config).as_dict
  File "/app/argus_final/venv/lib/python2.7/site-packages/nginx.py", line 402, in loads
    m = re.compile(r'^\s*events\s*{', re.S).search(data[index:])
TypeError: 'bool' object has no attribute '__getitem__'
2021-03-10 07:24:54,071 ERROR - Internal Server Error: /esync/om-fpms_pms_nginx/
Traceback (most recent call last):
  File "/app/argus_final/venv/lib/python2.7/site-packages/django/core/handlers/exception.py", line 41, in inner
    response = get_response(request)
  File "/app/argus_final/venv/lib/python2.7/site-packages/django/core/handlers/base.py", line 187, in _get_response
    response = self.process_exception_by_middleware(e, request)
  File "/app/argus_final/venv/lib/python2.7/site-packages/django/core/handlers/base.py", line 185, in _get_response
    response = wrapped_callback(request, *callback_args, **callback_kwargs)
  File "/app/argus_final/venv/lib/python2.7/site-packages/django/contrib/auth/decorators.py", line 23, in _wrapped_view
    return view_func(request, *args, **kwargs)
  File "/app/argus_final/venv/lib/python2.7/site-packages/django/views/generic/base.py", line 68, in view
    return self.dispatch(request, *args, **kwargs)
  File "/app/argus_final/app/argus/argus/mixins.py", line 14, in dispatch
    return super(GENERIC_PERMISSION_MIXIN, self).dispatch(request, *args, **kwargs)
  File "/app/argus_final/venv/lib/python2.7/site-packages/django/views/generic/base.py", line 88, in dispatch
    return handler(request, *args, **kwargs)
  File "/app/argus_final/app/argus/esync/views.py", line 169, in get
    context['keys'] = parse_standard_config(context['content'])
  File "/app/argus_final/app/argus/esync/lib/nginx_processor.py", line 11, in parse_standard_config
    rConfig = nginx.loads(config).as_dict
  File "/app/argus_final/venv/lib/python2.7/site-packages/nginx.py", line 402, in loads
    m = re.compile(r'^\s*events\s*{', re.S).search(data[index:])
TypeError: 'bool' object has no attribute '__getitem__'
2021-03-10 07:25:54,938 ERROR - Internal Server Error: /esync/om-fpms_pms_nginx/
Traceback (most recent call last):
  File "/app/argus_final/venv/lib/python2.7/site-packages/django/core/handlers/exception.py", line 41, in inner
    response = get_response(request)
  File "/app/argus_final/venv/lib/python2.7/site-packages/django/core/handlers/base.py", line 187, in _get_response
    response = self.process_exception_by_middleware(e, request)
  File "/app/argus_final/venv/lib/python2.7/site-packages/django/core/handlers/base.py", line 185, in _get_response
    response = wrapped_callback(request, *callback_args, **callback_kwargs)
  File "/app/argus_final/venv/lib/python2.7/site-packages/django/contrib/auth/decorators.py", line 23, in _wrapped_view
    return view_func(request, *args, **kwargs)
  File "/app/argus_final/venv/lib/python2.7/site-packages/django/views/generic/base.py", line 68, in view
    return self.dispatch(request, *args, **kwargs)
  File "/app/argus_final/app/argus/argus/mixins.py", line 14, in dispatch
    return super(GENERIC_PERMISSION_MIXIN, self).dispatch(request, *args, **kwargs)
  File "/app/argus_final/venv/lib/python2.7/site-packages/django/views/generic/base.py", line 88, in dispatch
    return handler(request, *args, **kwargs)
  File "/app/argus_final/app/argus/esync/views.py", line 169, in get
    context['keys'] = parse_standard_config(context['content'])
  File "/app/argus_final/app/argus/esync/lib/nginx_processor.py", line 11, in parse_standard_config
    rConfig = nginx.loads(config).as_dict
  File "/app/argus_final/venv/lib/python2.7/site-packages/nginx.py", line 402, in loads
    m = re.compile(r'^\s*events\s*{', re.S).search(data[index:])
TypeError: 'bool' object has no attribute '__getitem__'
2021-03-10 07:26:10,018 ERROR - Internal Server Error: /esync/om-fpms_pms_nginx/
Traceback (most recent call last):
  File "/app/argus_final/venv/lib/python2.7/site-packages/django/core/handlers/exception.py", line 41, in inner
    response = get_response(request)
  File "/app/argus_final/venv/lib/python2.7/site-packages/django/core/handlers/base.py", line 187, in _get_response
    response = self.process_exception_by_middleware(e, request)
  File "/app/argus_final/venv/lib/python2.7/site-packages/django/core/handlers/base.py", line 185, in _get_response
    response = wrapped_callback(request, *callback_args, **callback_kwargs)
  File "/app/argus_final/venv/lib/python2.7/site-packages/django/contrib/auth/decorators.py", line 23, in _wrapped_view
    return view_func(request, *args, **kwargs)
  File "/app/argus_final/venv/lib/python2.7/site-packages/django/views/generic/base.py", line 68, in view
    return self.dispatch(request, *args, **kwargs)
  File "/app/argus_final/app/argus/argus/mixins.py", line 14, in dispatch
    return super(GENERIC_PERMISSION_MIXIN, self).dispatch(request, *args, **kwargs)
  File "/app/argus_final/venv/lib/python2.7/site-packages/django/views/generic/base.py", line 88, in dispatch
    return handler(request, *args, **kwargs)
  File "/app/argus_final/app/argus/esync/views.py", line 169, in get
    context['keys'] = parse_standard_config(context['content'])
  File "/app/argus_final/app/argus/esync/lib/nginx_processor.py", line 11, in parse_standard_config
    rConfig = nginx.loads(config).as_dict
  File "/app/argus_final/venv/lib/python2.7/site-packages/nginx.py", line 402, in loads
    m = re.compile(r'^\s*events\s*{', re.S).search(data[index:])
TypeError: 'bool' object has no attribute '__getitem__'
2021-03-10 07:26:18,779 ERROR - Internal Server Error: /esync/om-fpms_pms_nginx/
Traceback (most recent call last):
  File "/app/argus_final/venv/lib/python2.7/site-packages/django/core/handlers/exception.py", line 41, in inner
    response = get_response(request)
  File "/app/argus_final/venv/lib/python2.7/site-packages/django/core/handlers/base.py", line 187, in _get_response
    response = self.process_exception_by_middleware(e, request)
  File "/app/argus_final/venv/lib/python2.7/site-packages/django/core/handlers/base.py", line 185, in _get_response
    response = wrapped_callback(request, *callback_args, **callback_kwargs)
  File "/app/argus_final/venv/lib/python2.7/site-packages/django/contrib/auth/decorators.py", line 23, in _wrapped_view
    return view_func(request, *args, **kwargs)
  File "/app/argus_final/venv/lib/python2.7/site-packages/django/views/generic/base.py", line 68, in view
    return self.dispatch(request, *args, **kwargs)
  File "/app/argus_final/app/argus/argus/mixins.py", line 14, in dispatch
    return super(GENERIC_PERMISSION_MIXIN, self).dispatch(request, *args, **kwargs)
  File "/app/argus_final/venv/lib/python2.7/site-packages/django/views/generic/base.py", line 88, in dispatch
    return handler(request, *args, **kwargs)
  File "/app/argus_final/app/argus/esync/views.py", line 169, in get
    context['keys'] = parse_standard_config(context['content'])
  File "/app/argus_final/app/argus/esync/lib/nginx_processor.py", line 11, in parse_standard_config
    rConfig = nginx.loads(config).as_dict
  File "/app/argus_final/venv/lib/python2.7/site-packages/nginx.py", line 402, in loads
    m = re.compile(r'^\s*events\s*{', re.S).search(data[index:])
TypeError: 'bool' object has no attribute '__getitem__'
2021-03-10 07:26:38,666 ERROR - Internal Server Error: /esync/om-fpms_pms_nginx/
Traceback (most recent call last):
  File "/app/argus_final/venv/lib/python2.7/site-packages/django/core/handlers/exception.py", line 41, in inner
    response = get_response(request)
  File "/app/argus_final/venv/lib/python2.7/site-packages/django/core/handlers/base.py", line 187, in _get_response
    response = self.process_exception_by_middleware(e, request)
  File "/app/argus_final/venv/lib/python2.7/site-packages/django/core/handlers/base.py", line 185, in _get_response
    response = wrapped_callback(request, *callback_args, **callback_kwargs)
  File "/app/argus_final/venv/lib/python2.7/site-packages/django/contrib/auth/decorators.py", line 23, in _wrapped_view
    return view_func(request, *args, **kwargs)
  File "/app/argus_final/venv/lib/python2.7/site-packages/django/views/generic/base.py", line 68, in view
    return self.dispatch(request, *args, **kwargs)
  File "/app/argus_final/app/argus/argus/mixins.py", line 14, in dispatch
    return super(GENERIC_PERMISSION_MIXIN, self).dispatch(request, *args, **kwargs)
  File "/app/argus_final/venv/lib/python2.7/site-packages/django/views/generic/base.py", line 88, in dispatch
    return handler(request, *args, **kwargs)
  File "/app/argus_final/app/argus/esync/views.py", line 169, in get
    context['keys'] = parse_standard_config(context['content'])
  File "/app/argus_final/app/argus/esync/lib/nginx_processor.py", line 11, in parse_standard_config
    rConfig = nginx.loads(config).as_dict
  File "/app/argus_final/venv/lib/python2.7/site-packages/nginx.py", line 402, in loads
    m = re.compile(r'^\s*events\s*{', re.S).search(data[index:])
TypeError: 'bool' object has no attribute '__getitem__'
2021-03-10 07:27:01,824 ERROR - Internal Server Error: /esync/om-fpms_pms_nginx/
Traceback (most recent call last):
  File "/app/argus_final/venv/lib/python2.7/site-packages/django/core/handlers/exception.py", line 41, in inner
    response = get_response(request)
  File "/app/argus_final/venv/lib/python2.7/site-packages/django/core/handlers/base.py", line 187, in _get_response
    response = self.process_exception_by_middleware(e, request)
  File "/app/argus_final/venv/lib/python2.7/site-packages/django/core/handlers/base.py", line 185, in _get_response
    response = wrapped_callback(request, *callback_args, **callback_kwargs)
  File "/app/argus_final/venv/lib/python2.7/site-packages/django/contrib/auth/decorators.py", line 23, in _wrapped_view
    return view_func(request, *args, **kwargs)
  File "/app/argus_final/venv/lib/python2.7/site-packages/django/views/generic/base.py", line 68, in view
    return self.dispatch(request, *args, **kwargs)
  File "/app/argus_final/app/argus/argus/mixins.py", line 14, in dispatch
    return super(GENERIC_PERMISSION_MIXIN, self).dispatch(request, *args, **kwargs)
  File "/app/argus_final/venv/lib/python2.7/site-packages/django/views/generic/base.py", line 88, in dispatch
    return handler(request, *args, **kwargs)
  File "/app/argus_final/app/argus/esync/views.py", line 169, in get
    context['keys'] = parse_standard_config(context['content'])
  File "/app/argus_final/app/argus/esync/lib/nginx_processor.py", line 11, in parse_standard_config
    rConfig = nginx.loads(config).as_dict
  File "/app/argus_final/venv/lib/python2.7/site-packages/nginx.py", line 402, in loads
    m = re.compile(r'^\s*events\s*{', re.S).search(data[index:])
TypeError: 'bool' object has no attribute '__getitem__'
2021-03-10 07:27:12,872 ERROR - Internal Server Error: /esync/om-fpms_pms_nginx/
Traceback (most recent call last):
  File "/app/argus_final/venv/lib/python2.7/site-packages/django/core/handlers/exception.py", line 41, in inner
    response = get_response(request)
  File "/app/argus_final/venv/lib/python2.7/site-packages/django/core/handlers/base.py", line 187, in _get_response
    response = self.process_exception_by_middleware(e, request)
  File "/app/argus_final/venv/lib/python2.7/site-packages/django/core/handlers/base.py", line 185, in _get_response
    response = wrapped_callback(request, *callback_args, **callback_kwargs)
  File "/app/argus_final/venv/lib/python2.7/site-packages/django/contrib/auth/decorators.py", line 23, in _wrapped_view
    return view_func(request, *args, **kwargs)
  File "/app/argus_final/venv/lib/python2.7/site-packages/django/views/generic/base.py", line 68, in view
    return self.dispatch(request, *args, **kwargs)
  File "/app/argus_final/app/argus/argus/mixins.py", line 14, in dispatch
    return super(GENERIC_PERMISSION_MIXIN, self).dispatch(request, *args, **kwargs)
  File "/app/argus_final/venv/lib/python2.7/site-packages/django/views/generic/base.py", line 88, in dispatch
    return handler(request, *args, **kwargs)
  File "/app/argus_final/app/argus/esync/views.py", line 169, in get
    context['keys'] = parse_standard_config(context['content'])
  File "/app/argus_final/app/argus/esync/lib/nginx_processor.py", line 11, in parse_standard_config
    rConfig = nginx.loads(config).as_dict
  File "/app/argus_final/venv/lib/python2.7/site-packages/nginx.py", line 402, in loads
    m = re.compile(r'^\s*events\s*{', re.S).search(data[index:])
TypeError: 'bool' object has no attribute '__getitem__'
2021-03-10 07:27:15,288 ERROR - Internal Server Error: /esync/om-fpms_pms_nginx/
Traceback (most recent call last):
  File "/app/argus_final/venv/lib/python2.7/site-packages/django/core/handlers/exception.py", line 41, in inner
    response = get_response(request)
  File "/app/argus_final/venv/lib/python2.7/site-packages/django/core/handlers/base.py", line 187, in _get_response
    response = self.process_exception_by_middleware(e, request)
  File "/app/argus_final/venv/lib/python2.7/site-packages/django/core/handlers/base.py", line 185, in _get_response
    response = wrapped_callback(request, *callback_args, **callback_kwargs)
  File "/app/argus_final/venv/lib/python2.7/site-packages/django/contrib/auth/decorators.py", line 23, in _wrapped_view
    return view_func(request, *args, **kwargs)
  File "/app/argus_final/venv/lib/python2.7/site-packages/django/views/generic/base.py", line 68, in view
    return self.dispatch(request, *args, **kwargs)
  File "/app/argus_final/app/argus/argus/mixins.py", line 14, in dispatch
    return super(GENERIC_PERMISSION_MIXIN, self).dispatch(request, *args, **kwargs)
  File "/app/argus_final/venv/lib/python2.7/site-packages/django/views/generic/base.py", line 88, in dispatch
    return handler(request, *args, **kwargs)
  File "/app/argus_final/app/argus/esync/views.py", line 169, in get
    context['keys'] = parse_standard_config(context['content'])
  File "/app/argus_final/app/argus/esync/lib/nginx_processor.py", line 11, in parse_standard_config
    rConfig = nginx.loads(config).as_dict
  File "/app/argus_final/venv/lib/python2.7/site-packages/nginx.py", line 402, in loads
    m = re.compile(r'^\s*events\s*{', re.S).search(data[index:])
TypeError: 'bool' object has no attribute '__getitem__'
2021-03-10 07:27:41,467 ERROR - Internal Server Error: /esync/om-fpms_pms_nginx/
Traceback (most recent call last):
  File "/app/argus_final/venv/lib/python2.7/site-packages/django/core/handlers/exception.py", line 41, in inner
    response = get_response(request)
  File "/app/argus_final/venv/lib/python2.7/site-packages/django/core/handlers/base.py", line 187, in _get_response
    response = self.process_exception_by_middleware(e, request)
  File "/app/argus_final/venv/lib/python2.7/site-packages/django/core/handlers/base.py", line 185, in _get_response
    response = wrapped_callback(request, *callback_args, **callback_kwargs)
  File "/app/argus_final/venv/lib/python2.7/site-packages/django/contrib/auth/decorators.py", line 23, in _wrapped_view
    return view_func(request, *args, **kwargs)
  File "/app/argus_final/venv/lib/python2.7/site-packages/django/views/generic/base.py", line 68, in view
    return self.dispatch(request, *args, **kwargs)
  File "/app/argus_final/app/argus/argus/mixins.py", line 14, in dispatch
    return super(GENERIC_PERMISSION_MIXIN, self).dispatch(request, *args, **kwargs)
  File "/app/argus_final/venv/lib/python2.7/site-packages/django/views/generic/base.py", line 88, in dispatch
    return handler(request, *args, **kwargs)
  File "/app/argus_final/app/argus/esync/views.py", line 169, in get
    context['keys'] = parse_standard_config(context['content'])
  File "/app/argus_final/app/argus/esync/lib/nginx_processor.py", line 11, in parse_standard_config
    rConfig = nginx.loads(config).as_dict
  File "/app/argus_final/venv/lib/python2.7/site-packages/nginx.py", line 402, in loads
    m = re.compile(r'^\s*events\s*{', re.S).search(data[index:])
TypeError: 'bool' object has no attribute '__getitem__'
2021-03-10 07:39:17,890 ERROR - Internal Server Error: /esync/om-fpms_pms_nginx/
Traceback (most recent call last):
  File "/app/argus_final/venv/lib/python2.7/site-packages/django/core/handlers/exception.py", line 41, in inner
    response = get_response(request)
  File "/app/argus_final/venv/lib/python2.7/site-packages/django/core/handlers/base.py", line 187, in _get_response
    response = self.process_exception_by_middleware(e, request)
  File "/app/argus_final/venv/lib/python2.7/site-packages/django/core/handlers/base.py", line 185, in _get_response
    response = wrapped_callback(request, *callback_args, **callback_kwargs)
  File "/app/argus_final/venv/lib/python2.7/site-packages/django/contrib/auth/decorators.py", line 23, in _wrapped_view
    return view_func(request, *args, **kwargs)
  File "/app/argus_final/venv/lib/python2.7/site-packages/django/views/generic/base.py", line 68, in view
    return self.dispatch(request, *args, **kwargs)
  File "/app/argus_final/app/argus/argus/mixins.py", line 14, in dispatch
    return super(GENERIC_PERMISSION_MIXIN, self).dispatch(request, *args, **kwargs)
  File "/app/argus_final/venv/lib/python2.7/site-packages/django/views/generic/base.py", line 88, in dispatch
    return handler(request, *args, **kwargs)
  File "/app/argus_final/app/argus/esync/views.py", line 169, in get
    context['keys'] = parse_standard_config(context['content'])
  File "/app/argus_final/app/argus/esync/lib/nginx_processor.py", line 11, in parse_standard_config
    rConfig = nginx.loads(config).as_dict
  File "/app/argus_final/venv/lib/python2.7/site-packages/nginx.py", line 402, in loads
    m = re.compile(r'^\s*events\s*{', re.S).search(data[index:])
TypeError: 'bool' object has no attribute '__getitem__'
2021-03-10 07:40:00,680 ERROR - Internal Server Error: /esync/om-fpms_pms_nginx/
Traceback (most recent call last):
  File "/app/argus_final/venv/lib/python2.7/site-packages/django/core/handlers/exception.py", line 41, in inner
    response = get_response(request)
  File "/app/argus_final/venv/lib/python2.7/site-packages/django/core/handlers/base.py", line 187, in _get_response
    response = self.process_exception_by_middleware(e, request)
  File "/app/argus_final/venv/lib/python2.7/site-packages/django/core/handlers/base.py", line 185, in _get_response
    response = wrapped_callback(request, *callback_args, **callback_kwargs)
  File "/app/argus_final/venv/lib/python2.7/site-packages/django/contrib/auth/decorators.py", line 23, in _wrapped_view
    return view_func(request, *args, **kwargs)
  File "/app/argus_final/venv/lib/python2.7/site-packages/django/views/generic/base.py", line 68, in view
    return self.dispatch(request, *args, **kwargs)
  File "/app/argus_final/app/argus/argus/mixins.py", line 14, in dispatch
    return super(GENERIC_PERMISSION_MIXIN, self).dispatch(request, *args, **kwargs)
  File "/app/argus_final/venv/lib/python2.7/site-packages/django/views/generic/base.py", line 88, in dispatch
    return handler(request, *args, **kwargs)
  File "/app/argus_final/app/argus/esync/views.py", line 169, in get
    context['keys'] = parse_standard_config(context['content'])
  File "/app/argus_final/app/argus/esync/lib/nginx_processor.py", line 11, in parse_standard_config
    rConfig = nginx.loads(config).as_dict
  File "/app/argus_final/venv/lib/python2.7/site-packages/nginx.py", line 402, in loads
    m = re.compile(r'^\s*events\s*{', re.S).search(data[index:])
TypeError: 'bool' object has no attribute '__getitem__'
2021-03-10 08:12:14,754 DEBUG - (jonas.nicanor) - Successfully loaded and updated table
2021-03-10 13:21:35,292 ERROR - Internal Server Error: /esync/om-fpms_pms_nginx/generate/
Traceback (most recent call last):
  File "/app/argus_final/venv/lib/python2.7/site-packages/django/core/handlers/exception.py", line 41, in inner
    response = get_response(request)
  File "/app/argus_final/venv/lib/python2.7/site-packages/django/core/handlers/base.py", line 187, in _get_response
    response = self.process_exception_by_middleware(e, request)
  File "/app/argus_final/venv/lib/python2.7/site-packages/django/core/handlers/base.py", line 185, in _get_response
    response = wrapped_callback(request, *callback_args, **callback_kwargs)
  File "/app/argus_final/venv/lib/python2.7/site-packages/django/contrib/auth/decorators.py", line 23, in _wrapped_view
    return view_func(request, *args, **kwargs)
  File "/app/argus_final/venv/lib/python2.7/site-packages/django/views/generic/base.py", line 68, in view
    return self.dispatch(request, *args, **kwargs)
  File "/app/argus_final/venv/lib/python2.7/site-packages/django/utils/decorators.py", line 67, in _wrapper
    return bound_func(*args, **kwargs)
  File "/app/argus_final/venv/lib/python2.7/site-packages/django/views/decorators/csrf.py", line 58, in wrapped_view
    return view_func(*args, **kwargs)
  File "/app/argus_final/venv/lib/python2.7/site-packages/django/utils/decorators.py", line 63, in bound_func
    return func.__get__(self, type(self))(*args2, **kwargs2)
  File "/app/argus_final/app/argus/argus/mixins.py", line 14, in dispatch
    return super(GENERIC_PERMISSION_MIXIN, self).dispatch(request, *args, **kwargs)
  File "/app/argus_final/venv/lib/python2.7/site-packages/django/views/generic/base.py", line 88, in dispatch
    return handler(request, *args, **kwargs)
  File "/app/argus_final/app/argus/esync/views.py", line 287, in post
    nonstandard_esync_log(hostgroup, request.user.username, [result[1]],activity_type='CREATE')
  File "/app/argus_final/app/argus/esync/lib/esync_logger.py", line 20, in nonstandard_esync_log
    f.write(i)
UnicodeEncodeError: 'ascii' codec can't encode characters in position 520-522: ordinal not in range(128)
2021-03-10 17:50:57,746 ERROR - Internal Server Error: /fwdcontrol/test-public-nginx/
Traceback (most recent call last):
  File "/app/argus_final/venv/lib/python2.7/site-packages/django/core/handlers/exception.py", line 41, in inner
    response = get_response(request)
  File "/app/argus_final/venv/lib/python2.7/site-packages/django/core/handlers/base.py", line 187, in _get_response
    response = self.process_exception_by_middleware(e, request)
  File "/app/argus_final/venv/lib/python2.7/site-packages/django/core/handlers/base.py", line 185, in _get_response
    response = wrapped_callback(request, *callback_args, **callback_kwargs)
  File "/app/argus_final/venv/lib/python2.7/site-packages/django/contrib/auth/decorators.py", line 23, in _wrapped_view
    return view_func(request, *args, **kwargs)
  File "/app/argus_final/venv/lib/python2.7/site-packages/django/views/generic/base.py", line 68, in view
    return self.dispatch(request, *args, **kwargs)
  File "/app/argus_final/venv/lib/python2.7/site-packages/django/utils/decorators.py", line 67, in _wrapper
    return bound_func(*args, **kwargs)
  File "/app/argus_final/venv/lib/python2.7/site-packages/django/views/decorators/csrf.py", line 58, in wrapped_view
    return view_func(*args, **kwargs)
  File "/app/argus_final/venv/lib/python2.7/site-packages/django/utils/decorators.py", line 63, in bound_func
    return func.__get__(self, type(self))(*args2, **kwargs2)
  File "/app/argus_final/app/argus/argus/mixins.py", line 14, in dispatch
    return super(GENERIC_PERMISSION_MIXIN, self).dispatch(request, *args, **kwargs)
  File "/app/argus_final/venv/lib/python2.7/site-packages/django/views/generic/base.py", line 88, in dispatch
    return handler(request, *args, **kwargs)
  File "/app/argus_final/app/argus/fwdcontrol/views.py", line 46, in get
    context['content'] = result.get()
  File "/app/argus_final/venv/lib/python2.7/site-packages/celery/result.py", line 224, in get
    on_message=on_message,
  File "/app/argus_final/venv/lib/python2.7/site-packages/celery/backends/async.py", line 190, in wait_for_pending
    return result.maybe_throw(callback=callback, propagate=propagate)
  File "/app/argus_final/venv/lib/python2.7/site-packages/celery/result.py", line 329, in maybe_throw
    self.throw(value, self._to_remote_traceback(tb))
  File "/app/argus_final/venv/lib/python2.7/site-packages/celery/result.py", line 322, in throw
    self.on_ready.throw(*args, **kwargs)
  File "/app/argus_final/venv/lib/python2.7/site-packages/vine/promises.py", line 217, in throw
    reraise(type(exc), exc, tb)
  File "<string>", line 1, in reraise
IOError: (u'[', u'E', u'r', u'r', u'n', u'o', u' ', u'2', u'1', u']', u' ', u'I', u's', u' ', u'a', u' ', u'd', u'i', u'r', u'e', u'c', u't', u'o', u'r', u'y', u':', u' ', u'u', u"'", u'/', u's', u'r', u'v', u'/', u't', u'e', u's', u't', u'-', u'p', u'u', u'b', u'l', u'i', u'c', u'-', u'n', u'g', u'i', u'n', u'x', u'/', u'c', u'o', u'n', u'f', u'.', u'd', u'/', u'l', u'e', u't', u's', u'e', u'n', u'c', u'r', u'y', u'p', u't', u'-', u's', u's', u'l', u'-', u'n', u'o', u'l', u'i', u'n', u'k', u"'")
2021-03-10 20:23:27,505 ERROR - Internal Server Error: /esync/om-test_nginx/generate/
Traceback (most recent call last):
  File "/app/argus_final/venv/lib/python2.7/site-packages/django/core/handlers/exception.py", line 41, in inner
    response = get_response(request)
  File "/app/argus_final/venv/lib/python2.7/site-packages/django/core/handlers/base.py", line 187, in _get_response
    response = self.process_exception_by_middleware(e, request)
  File "/app/argus_final/venv/lib/python2.7/site-packages/django/core/handlers/base.py", line 185, in _get_response
    response = wrapped_callback(request, *callback_args, **callback_kwargs)
  File "/app/argus_final/venv/lib/python2.7/site-packages/django/contrib/auth/decorators.py", line 23, in _wrapped_view
    return view_func(request, *args, **kwargs)
  File "/app/argus_final/venv/lib/python2.7/site-packages/django/views/generic/base.py", line 68, in view
    return self.dispatch(request, *args, **kwargs)
  File "/app/argus_final/venv/lib/python2.7/site-packages/django/utils/decorators.py", line 67, in _wrapper
    return bound_func(*args, **kwargs)
  File "/app/argus_final/venv/lib/python2.7/site-packages/django/views/decorators/csrf.py", line 58, in wrapped_view
    return view_func(*args, **kwargs)
  File "/app/argus_final/venv/lib/python2.7/site-packages/django/utils/decorators.py", line 63, in bound_func
    return func.__get__(self, type(self))(*args2, **kwargs2)
  File "/app/argus_final/app/argus/argus/mixins.py", line 14, in dispatch
    return super(GENERIC_PERMISSION_MIXIN, self).dispatch(request, *args, **kwargs)
  File "/app/argus_final/venv/lib/python2.7/site-packages/django/views/generic/base.py", line 88, in dispatch
    return handler(request, *args, **kwargs)
  File "/app/argus_final/app/argus/esync/views.py", line 287, in post
    nonstandard_esync_log(hostgroup, request.user.username, [result[1]],activity_type='CREATE')
  File "/app/argus_final/app/argus/esync/lib/esync_logger.py", line 20, in nonstandard_esync_log
    f.write(i)
UnicodeEncodeError: 'ascii' codec can't encode characters in position 251-253: ordinal not in range(128)
2021-03-11 00:47:02,819 ERROR - Internal Server Error: /esync/om-fpms_pms_nginx/
Traceback (most recent call last):
  File "/app/argus_final/venv/lib/python2.7/site-packages/django/core/handlers/exception.py", line 41, in inner
    response = get_response(request)
  File "/app/argus_final/venv/lib/python2.7/site-packages/django/core/handlers/base.py", line 187, in _get_response
    response = self.process_exception_by_middleware(e, request)
  File "/app/argus_final/venv/lib/python2.7/site-packages/django/core/handlers/base.py", line 185, in _get_response
    response = wrapped_callback(request, *callback_args, **callback_kwargs)
  File "/app/argus_final/venv/lib/python2.7/site-packages/django/contrib/auth/decorators.py", line 23, in _wrapped_view
    return view_func(request, *args, **kwargs)
  File "/app/argus_final/venv/lib/python2.7/site-packages/django/views/generic/base.py", line 68, in view
    return self.dispatch(request, *args, **kwargs)
  File "/app/argus_final/app/argus/argus/mixins.py", line 14, in dispatch
    return super(GENERIC_PERMISSION_MIXIN, self).dispatch(request, *args, **kwargs)
  File "/app/argus_final/venv/lib/python2.7/site-packages/django/views/generic/base.py", line 88, in dispatch
    return handler(request, *args, **kwargs)
  File "/app/argus_final/app/argus/esync/views.py", line 169, in get
    context['keys'] = parse_standard_config(context['content'])
  File "/app/argus_final/app/argus/esync/lib/nginx_processor.py", line 11, in parse_standard_config
    rConfig = nginx.loads(config).as_dict
  File "/app/argus_final/venv/lib/python2.7/site-packages/nginx.py", line 402, in loads
    m = re.compile(r'^\s*events\s*{', re.S).search(data[index:])
TypeError: 'bool' object has no attribute '__getitem__'
2021-03-11 11:48:01,455 DEBUG - (lyden.reyes) - Successfully loaded and updated table
2021-03-11 12:16:45,792 DEBUG - (teckxiu) - Successfully loaded and updated table
2021-03-11 12:24:12,670 DEBUG - (teckxiu) - Successfully loaded and updated table
2021-03-11 13:47:07,263 DEBUG - (lyden.reyes) - Successfully loaded and updated table
2021-03-11 16:34:40,669 ERROR - Internal Server Error: /esync/om-fpms_pms_nginx/generate/
Traceback (most recent call last):
  File "/app/argus_final/venv/lib/python2.7/site-packages/django/core/handlers/exception.py", line 41, in inner
    response = get_response(request)
  File "/app/argus_final/venv/lib/python2.7/site-packages/django/core/handlers/base.py", line 187, in _get_response
    response = self.process_exception_by_middleware(e, request)
  File "/app/argus_final/venv/lib/python2.7/site-packages/django/core/handlers/base.py", line 185, in _get_response
    response = wrapped_callback(request, *callback_args, **callback_kwargs)
  File "/app/argus_final/venv/lib/python2.7/site-packages/django/contrib/auth/decorators.py", line 23, in _wrapped_view
    return view_func(request, *args, **kwargs)
  File "/app/argus_final/venv/lib/python2.7/site-packages/django/views/generic/base.py", line 68, in view
    return self.dispatch(request, *args, **kwargs)
  File "/app/argus_final/venv/lib/python2.7/site-packages/django/utils/decorators.py", line 67, in _wrapper
    return bound_func(*args, **kwargs)
  File "/app/argus_final/venv/lib/python2.7/site-packages/django/views/decorators/csrf.py", line 58, in wrapped_view
    return view_func(*args, **kwargs)
  File "/app/argus_final/venv/lib/python2.7/site-packages/django/utils/decorators.py", line 63, in bound_func
    return func.__get__(self, type(self))(*args2, **kwargs2)
  File "/app/argus_final/app/argus/argus/mixins.py", line 14, in dispatch
    return super(GENERIC_PERMISSION_MIXIN, self).dispatch(request, *args, **kwargs)
  File "/app/argus_final/venv/lib/python2.7/site-packages/django/views/generic/base.py", line 88, in dispatch
    return handler(request, *args, **kwargs)
  File "/app/argus_final/app/argus/esync/views.py", line 287, in post
    nonstandard_esync_log(hostgroup, request.user.username, [result[1]],activity_type='CREATE')
  File "/app/argus_final/app/argus/esync/lib/esync_logger.py", line 20, in nonstandard_esync_log
    f.write(i)
UnicodeEncodeError: 'ascii' codec can't encode characters in position 556-557: ordinal not in range(128)
2021-03-12 08:17:46,082 DEBUG - (jonas.nicanor) - Successfully loaded and updated table
2021-03-12 08:18:00,026 DEBUG - (jonas.nicanor) - Successfully loaded and updated table
2021-03-12 15:21:50,665 ERROR - Internal Server Error: /esync/acc-midpay_nginx/generate/
Traceback (most recent call last):
  File "/app/argus_final/venv/lib/python2.7/site-packages/django/core/handlers/exception.py", line 41, in inner
    response = get_response(request)
  File "/app/argus_final/venv/lib/python2.7/site-packages/django/core/handlers/base.py", line 187, in _get_response
    response = self.process_exception_by_middleware(e, request)
  File "/app/argus_final/venv/lib/python2.7/site-packages/django/core/handlers/base.py", line 185, in _get_response
    response = wrapped_callback(request, *callback_args, **callback_kwargs)
  File "/app/argus_final/venv/lib/python2.7/site-packages/django/contrib/auth/decorators.py", line 23, in _wrapped_view
    return view_func(request, *args, **kwargs)
  File "/app/argus_final/venv/lib/python2.7/site-packages/django/views/generic/base.py", line 68, in view
    return self.dispatch(request, *args, **kwargs)
  File "/app/argus_final/venv/lib/python2.7/site-packages/django/utils/decorators.py", line 67, in _wrapper
    return bound_func(*args, **kwargs)
  File "/app/argus_final/venv/lib/python2.7/site-packages/django/views/decorators/csrf.py", line 58, in wrapped_view
    return view_func(*args, **kwargs)
  File "/app/argus_final/venv/lib/python2.7/site-packages/django/utils/decorators.py", line 63, in bound_func
    return func.__get__(self, type(self))(*args2, **kwargs2)
  File "/app/argus_final/app/argus/argus/mixins.py", line 14, in dispatch
    return super(GENERIC_PERMISSION_MIXIN, self).dispatch(request, *args, **kwargs)
  File "/app/argus_final/venv/lib/python2.7/site-packages/django/views/generic/base.py", line 88, in dispatch
    return handler(request, *args, **kwargs)
  File "/app/argus_final/app/argus/esync/views.py", line 287, in post
    nonstandard_esync_log(hostgroup, request.user.username, [result[1]],activity_type='CREATE')
  File "/app/argus_final/app/argus/esync/lib/esync_logger.py", line 20, in nonstandard_esync_log
    f.write(i)
UnicodeEncodeError: 'ascii' codec can't encode characters in position 214-218: ordinal not in range(128)
2021-03-12 15:34:13,365 ERROR - Internal Server Error: /esync/acc-midpay_nginx/generate/
Traceback (most recent call last):
  File "/app/argus_final/venv/lib/python2.7/site-packages/django/core/handlers/exception.py", line 41, in inner
    response = get_response(request)
  File "/app/argus_final/venv/lib/python2.7/site-packages/django/core/handlers/base.py", line 187, in _get_response
    response = self.process_exception_by_middleware(e, request)
  File "/app/argus_final/venv/lib/python2.7/site-packages/django/core/handlers/base.py", line 185, in _get_response
    response = wrapped_callback(request, *callback_args, **callback_kwargs)
  File "/app/argus_final/venv/lib/python2.7/site-packages/django/contrib/auth/decorators.py", line 23, in _wrapped_view
    return view_func(request, *args, **kwargs)
  File "/app/argus_final/venv/lib/python2.7/site-packages/django/views/generic/base.py", line 68, in view
    return self.dispatch(request, *args, **kwargs)
  File "/app/argus_final/venv/lib/python2.7/site-packages/django/utils/decorators.py", line 67, in _wrapper
    return bound_func(*args, **kwargs)
  File "/app/argus_final/venv/lib/python2.7/site-packages/django/views/decorators/csrf.py", line 58, in wrapped_view
    return view_func(*args, **kwargs)
  File "/app/argus_final/venv/lib/python2.7/site-packages/django/utils/decorators.py", line 63, in bound_func
    return func.__get__(self, type(self))(*args2, **kwargs2)
  File "/app/argus_final/app/argus/argus/mixins.py", line 14, in dispatch
    return super(GENERIC_PERMISSION_MIXIN, self).dispatch(request, *args, **kwargs)
  File "/app/argus_final/venv/lib/python2.7/site-packages/django/views/generic/base.py", line 88, in dispatch
    return handler(request, *args, **kwargs)
  File "/app/argus_final/app/argus/esync/views.py", line 287, in post
    nonstandard_esync_log(hostgroup, request.user.username, [result[1]],activity_type='CREATE')
  File "/app/argus_final/app/argus/esync/lib/esync_logger.py", line 20, in nonstandard_esync_log
    f.write(i)
UnicodeEncodeError: 'ascii' codec can't encode characters in position 440-446: ordinal not in range(128)
2021-03-13 10:27:55,869 DEBUG - (jonas.nicanor) - Successfully loaded and updated table
2021-03-13 10:28:21,598 DEBUG - (jonas.nicanor) - Successfully loaded and updated table
2021-03-13 10:28:31,838 DEBUG - (jonas.nicanor) - Successfully loaded and updated table
2021-03-13 10:29:31,713 DEBUG - (jonas.nicanor) - Successfully loaded and updated table
2021-03-13 10:31:06,299 DEBUG - (jonas.nicanor) - Successfully loaded and updated table
2021-03-13 10:34:02,444 DEBUG - (jonas.nicanor) - Successfully loaded and updated table
2021-03-14 00:19:58,511 DEBUG - (yroll.macalino) - Successfully loaded and updated table
2021-03-14 00:20:10,298 DEBUG - (yroll.macalino) - Successfully loaded and updated table
2021-03-14 00:22:35,971 DEBUG - (yroll.macalino) - Successfully loaded and updated table
2021-03-14 11:14:35,197 DEBUG - (james.cadelina) - Successfully loaded and updated table
2021-03-14 11:14:47,658 DEBUG - (james.cadelina) - Successfully loaded and updated table
2021-03-14 11:14:52,286 DEBUG - (james.cadelina) - Successfully loaded and updated table
2021-03-14 11:25:41,904 DEBUG - (james.cadelina) - Successfully loaded and updated table
2021-03-14 11:25:53,429 DEBUG - (james.cadelina) - Successfully loaded and updated table
2021-03-14 12:13:21,563 DEBUG - (james.cadelina) - Successfully loaded and updated table
2021-03-14 12:13:23,351 DEBUG - (nikko.aratan) - Successfully loaded and updated table
2021-03-14 12:14:01,829 DEBUG - (nikko.aratan) - Successfully loaded and updated table
2021-03-14 12:14:08,574 DEBUG - (nikko.aratan) - Successfully loaded and updated table
2021-03-14 12:14:25,856 DEBUG - (nikko.aratan) - Successfully loaded and updated table
2021-03-14 12:16:02,183 DEBUG - (nikko.aratan) - Successfully loaded and updated table
2021-03-14 12:18:42,583 DEBUG - (nikko.aratan) - Successfully loaded and updated table
2021-03-14 12:57:45,834 DEBUG - (nikko.aratan) - Successfully loaded and updated table
2021-03-14 12:58:05,501 DEBUG - (nikko.aratan) - Successfully loaded and updated table
2021-03-14 13:13:00,191 ERROR - Internal Server Error: /monitoring/
Traceback (most recent call last):
  File "/app/argus_final/venv/lib/python2.7/site-packages/django/core/handlers/exception.py", line 41, in inner
    response = get_response(request)
  File "/app/argus_final/venv/lib/python2.7/site-packages/django/core/handlers/base.py", line 187, in _get_response
    response = self.process_exception_by_middleware(e, request)
  File "/app/argus_final/venv/lib/python2.7/site-packages/django/core/handlers/base.py", line 185, in _get_response
    response = wrapped_callback(request, *callback_args, **callback_kwargs)
  File "/app/argus_final/venv/lib/python2.7/site-packages/django/contrib/auth/decorators.py", line 23, in _wrapped_view
    return view_func(request, *args, **kwargs)
  File "/app/argus_final/venv/lib/python2.7/site-packages/django/views/generic/base.py", line 68, in view
    return self.dispatch(request, *args, **kwargs)
  File "/app/argus_final/app/argus/argus/mixins.py", line 14, in dispatch
    return super(GENERIC_PERMISSION_MIXIN, self).dispatch(request, *args, **kwargs)
  File "/app/argus_final/venv/lib/python2.7/site-packages/django/views/generic/base.py", line 88, in dispatch
    return handler(request, *args, **kwargs)
  File "/app/argus_final/app/argus/monitoring/views.py", line 43, in get
    context['data'] = ZABBIX.getScreenGraphs('Network')
  File "/app/argus_final/app/argus/global_objects/zabbix_api.py", line 227, in getScreenGraphs
    for i in req['result'][0]['screenitems']:
IndexError: list index out of range
2021-03-14 13:13:06,568 DEBUG - (nikko.aratan) - Successfully loaded and updated table
2021-03-14 15:49:37,549 DEBUG - (nikko.aratan) - Successfully loaded and updated table
2021-03-14 15:49:51,066 ERROR - Internal Server Error: /domains/ssladded
Traceback (most recent call last):
  File "/app/argus_final/venv/lib/python2.7/site-packages/django/core/handlers/exception.py", line 41, in inner
    response = get_response(request)
  File "/app/argus_final/venv/lib/python2.7/site-packages/django/core/handlers/base.py", line 198, in _get_response
    "returned None instead." % (callback.__module__, view_name)
ValueError: The view domains.views.add_sslchecker didn't return an HttpResponse object. It returned None instead.
2021-03-14 15:50:03,782 ERROR - Internal Server Error: /domains/ssladded
Traceback (most recent call last):
  File "/app/argus_final/venv/lib/python2.7/site-packages/django/core/handlers/exception.py", line 41, in inner
    response = get_response(request)
  File "/app/argus_final/venv/lib/python2.7/site-packages/django/core/handlers/base.py", line 198, in _get_response
    "returned None instead." % (callback.__module__, view_name)
ValueError: The view domains.views.add_sslchecker didn't return an HttpResponse object. It returned None instead.
2021-03-14 15:50:13,398 ERROR - Internal Server Error: /domains/ssladded
Traceback (most recent call last):
  File "/app/argus_final/venv/lib/python2.7/site-packages/django/core/handlers/exception.py", line 41, in inner
    response = get_response(request)
  File "/app/argus_final/venv/lib/python2.7/site-packages/django/core/handlers/base.py", line 198, in _get_response
    "returned None instead." % (callback.__module__, view_name)
ValueError: The view domains.views.add_sslchecker didn't return an HttpResponse object. It returned None instead.
2021-03-15 08:53:19,701 DEBUG - (james.cadelina) - Successfully loaded and updated table
2021-03-15 09:02:03,351 DEBUG - (teckxiu) - Successfully loaded and updated table
2021-03-15 09:02:24,117 DEBUG - (teckxiu) - Successfully loaded and updated table
