2021-03-08 08:17:49,582 DEBUG - (lyden.reyes) - Successfully loaded and updated table
2021-03-08 12:12:09,802 ERROR - Internal Server Error: /esync/deploy/
Traceback (most recent call last):
  File "/app/argus_final/venv/lib/python2.7/site-packages/django/core/handlers/exception.py", line 41, in inner
    response = get_response(request)
  File "/app/argus_final/venv/lib/python2.7/site-packages/django/core/handlers/base.py", line 187, in _get_response
    response = self.process_exception_by_middleware(e, request)
  File "/app/argus_final/venv/lib/python2.7/site-packages/django/core/handlers/base.py", line 185, in _get_response
    response = wrapped_callback(request, *callback_args, **callback_kwargs)
  File "/app/argus_final/venv/lib/python2.7/site-packages/django/contrib/auth/decorators.py", line 23, in _wrapped_view
    return view_func(request, *args, **kwargs)
  File "/app/argus_final/venv/lib/python2.7/site-packages/django/views/generic/base.py", line 68, in view
    return self.dispatch(request, *args, **kwargs)
  File "/app/argus_final/venv/lib/python2.7/site-packages/django/utils/decorators.py", line 67, in _wrapper
    return bound_func(*args, **kwargs)
  File "/app/argus_final/venv/lib/python2.7/site-packages/django/views/decorators/csrf.py", line 58, in wrapped_view
    return view_func(*args, **kwargs)
  File "/app/argus_final/venv/lib/python2.7/site-packages/django/utils/decorators.py", line 63, in bound_func
    return func.__get__(self, type(self))(*args2, **kwargs2)
  File "/app/argus_final/app/argus/argus/mixins.py", line 14, in dispatch
    return super(GENERIC_PERMISSION_MIXIN, self).dispatch(request, *args, **kwargs)
  File "/app/argus_final/venv/lib/python2.7/site-packages/django/views/generic/base.py", line 88, in dispatch
    return handler(request, *args, **kwargs)
  File "/app/argus_final/app/argus/esync/views.py", line 709, in get
    'deployable':self.__get_deployable()
  File "/app/argus_final/app/argus/esync/views.py", line 702, in __get_deployable
    res = t.get()
  File "/app/argus_final/venv/lib/python2.7/site-packages/celery/result.py", line 224, in get
    on_message=on_message,
  File "/app/argus_final/venv/lib/python2.7/site-packages/celery/backends/async.py", line 190, in wait_for_pending
    return result.maybe_throw(callback=callback, propagate=propagate)
  File "/app/argus_final/venv/lib/python2.7/site-packages/celery/result.py", line 329, in maybe_throw
    self.throw(value, self._to_remote_traceback(tb))
  File "/app/argus_final/venv/lib/python2.7/site-packages/celery/result.py", line 322, in throw
    self.on_ready.throw(*args, **kwargs)
  File "/app/argus_final/venv/lib/python2.7/site-packages/vine/promises.py", line 217, in throw
    reraise(type(exc), exc, tb)
  File "<string>", line 1, in reraise
NotRegistered: (u'u', u"'", u'e', u's', u'y', u'n', u'c', u'_', u'w', u'o', u'r', u'k', u'e', u'r', u'-', u'C', u'L', u'O', u'U', u'D', u'.', u'g', u'e', u't', u'_', u'd', u'e', u'p', u'l', u'o', u'y', u'a', u'b', u'l', u'e', u'_', u'h', u'o', u's', u't', u's', u"'")
2021-03-08 12:24:14,636 ERROR - Internal Server Error: /esync/om-test_nginx/
Traceback (most recent call last):
  File "/app/argus_final/venv/lib/python2.7/site-packages/django/core/handlers/exception.py", line 41, in inner
    response = get_response(request)
  File "/app/argus_final/venv/lib/python2.7/site-packages/django/core/handlers/base.py", line 187, in _get_response
    response = self.process_exception_by_middleware(e, request)
  File "/app/argus_final/venv/lib/python2.7/site-packages/django/core/handlers/base.py", line 185, in _get_response
    response = wrapped_callback(request, *callback_args, **callback_kwargs)
  File "/app/argus_final/venv/lib/python2.7/site-packages/django/contrib/auth/decorators.py", line 23, in _wrapped_view
    return view_func(request, *args, **kwargs)
  File "/app/argus_final/venv/lib/python2.7/site-packages/django/views/generic/base.py", line 68, in view
    return self.dispatch(request, *args, **kwargs)
  File "/app/argus_final/app/argus/argus/mixins.py", line 14, in dispatch
    return super(GENERIC_PERMISSION_MIXIN, self).dispatch(request, *args, **kwargs)
  File "/app/argus_final/venv/lib/python2.7/site-packages/django/views/generic/base.py", line 88, in dispatch
    return handler(request, *args, **kwargs)
  File "/app/argus_final/app/argus/esync/views.py", line 169, in get
    context['keys'] = parse_standard_config(context['content'])
  File "/app/argus_final/app/argus/esync/lib/nginx_processor.py", line 11, in parse_standard_config
    rConfig = nginx.loads(config).as_dict
  File "/app/argus_final/venv/lib/python2.7/site-packages/nginx.py", line 402, in loads
    m = re.compile(r'^\s*events\s*{', re.S).search(data[index:])
TypeError: 'bool' object has no attribute '__getitem__'
2021-03-08 13:00:44,903 ERROR - Internal Server Error: /esync/om-test_nginx/
Traceback (most recent call last):
  File "/app/argus_final/venv/lib/python2.7/site-packages/django/core/handlers/exception.py", line 41, in inner
    response = get_response(request)
  File "/app/argus_final/venv/lib/python2.7/site-packages/django/core/handlers/base.py", line 187, in _get_response
    response = self.process_exception_by_middleware(e, request)
  File "/app/argus_final/venv/lib/python2.7/site-packages/django/core/handlers/base.py", line 185, in _get_response
    response = wrapped_callback(request, *callback_args, **callback_kwargs)
  File "/app/argus_final/venv/lib/python2.7/site-packages/django/contrib/auth/decorators.py", line 23, in _wrapped_view
    return view_func(request, *args, **kwargs)
  File "/app/argus_final/venv/lib/python2.7/site-packages/django/views/generic/base.py", line 68, in view
    return self.dispatch(request, *args, **kwargs)
  File "/app/argus_final/app/argus/argus/mixins.py", line 14, in dispatch
    return super(GENERIC_PERMISSION_MIXIN, self).dispatch(request, *args, **kwargs)
  File "/app/argus_final/venv/lib/python2.7/site-packages/django/views/generic/base.py", line 88, in dispatch
    return handler(request, *args, **kwargs)
  File "/app/argus_final/app/argus/esync/views.py", line 169, in get
    context['keys'] = parse_standard_config(context['content'])
  File "/app/argus_final/app/argus/esync/lib/nginx_processor.py", line 11, in parse_standard_config
    rConfig = nginx.loads(config).as_dict
  File "/app/argus_final/venv/lib/python2.7/site-packages/nginx.py", line 402, in loads
    m = re.compile(r'^\s*events\s*{', re.S).search(data[index:])
TypeError: 'bool' object has no attribute '__getitem__'
2021-03-08 15:34:07,675 ERROR - Internal Server Error: /monitoring/
Traceback (most recent call last):
  File "/app/argus_final/venv/lib/python2.7/site-packages/django/core/handlers/exception.py", line 41, in inner
    response = get_response(request)
  File "/app/argus_final/venv/lib/python2.7/site-packages/django/core/handlers/base.py", line 187, in _get_response
    response = self.process_exception_by_middleware(e, request)
  File "/app/argus_final/venv/lib/python2.7/site-packages/django/core/handlers/base.py", line 185, in _get_response
    response = wrapped_callback(request, *callback_args, **callback_kwargs)
  File "/app/argus_final/venv/lib/python2.7/site-packages/django/contrib/auth/decorators.py", line 23, in _wrapped_view
    return view_func(request, *args, **kwargs)
  File "/app/argus_final/venv/lib/python2.7/site-packages/django/views/generic/base.py", line 68, in view
    return self.dispatch(request, *args, **kwargs)
  File "/app/argus_final/app/argus/argus/mixins.py", line 14, in dispatch
    return super(GENERIC_PERMISSION_MIXIN, self).dispatch(request, *args, **kwargs)
  File "/app/argus_final/venv/lib/python2.7/site-packages/django/views/generic/base.py", line 88, in dispatch
    return handler(request, *args, **kwargs)
  File "/app/argus_final/app/argus/monitoring/views.py", line 43, in get
    context['data'] = ZABBIX.getScreenGraphs('Network')
  File "/app/argus_final/app/argus/global_objects/zabbix_api.py", line 227, in getScreenGraphs
    for i in req['result'][0]['screenitems']:
IndexError: list index out of range
2021-03-08 16:54:12,396 ERROR - Internal Server Error: /esync/om-fpms_pms_nginx/generate/
Traceback (most recent call last):
  File "/app/argus_final/venv/lib/python2.7/site-packages/django/core/handlers/exception.py", line 41, in inner
    response = get_response(request)
  File "/app/argus_final/venv/lib/python2.7/site-packages/django/core/handlers/base.py", line 187, in _get_response
    response = self.process_exception_by_middleware(e, request)
  File "/app/argus_final/venv/lib/python2.7/site-packages/django/core/handlers/base.py", line 185, in _get_response
    response = wrapped_callback(request, *callback_args, **callback_kwargs)
  File "/app/argus_final/venv/lib/python2.7/site-packages/django/contrib/auth/decorators.py", line 23, in _wrapped_view
    return view_func(request, *args, **kwargs)
  File "/app/argus_final/venv/lib/python2.7/site-packages/django/views/generic/base.py", line 68, in view
    return self.dispatch(request, *args, **kwargs)
  File "/app/argus_final/venv/lib/python2.7/site-packages/django/utils/decorators.py", line 67, in _wrapper
    return bound_func(*args, **kwargs)
  File "/app/argus_final/venv/lib/python2.7/site-packages/django/views/decorators/csrf.py", line 58, in wrapped_view
    return view_func(*args, **kwargs)
  File "/app/argus_final/venv/lib/python2.7/site-packages/django/utils/decorators.py", line 63, in bound_func
    return func.__get__(self, type(self))(*args2, **kwargs2)
  File "/app/argus_final/app/argus/argus/mixins.py", line 14, in dispatch
    return super(GENERIC_PERMISSION_MIXIN, self).dispatch(request, *args, **kwargs)
  File "/app/argus_final/venv/lib/python2.7/site-packages/django/views/generic/base.py", line 88, in dispatch
    return handler(request, *args, **kwargs)
  File "/app/argus_final/app/argus/esync/views.py", line 287, in post
    nonstandard_esync_log(hostgroup, request.user.username, [result[1]],activity_type='CREATE')
  File "/app/argus_final/app/argus/esync/lib/esync_logger.py", line 20, in nonstandard_esync_log
    f.write(i)
UnicodeEncodeError: 'ascii' codec can't encode characters in position 331-334: ordinal not in range(128)
2021-03-08 17:02:03,735 ERROR - Internal Server Error: /esync/om-test_nginx/
Traceback (most recent call last):
  File "/app/argus_final/venv/lib/python2.7/site-packages/django/core/handlers/exception.py", line 41, in inner
    response = get_response(request)
  File "/app/argus_final/venv/lib/python2.7/site-packages/django/core/handlers/base.py", line 187, in _get_response
    response = self.process_exception_by_middleware(e, request)
  File "/app/argus_final/venv/lib/python2.7/site-packages/django/core/handlers/base.py", line 185, in _get_response
    response = wrapped_callback(request, *callback_args, **callback_kwargs)
  File "/app/argus_final/venv/lib/python2.7/site-packages/django/contrib/auth/decorators.py", line 23, in _wrapped_view
    return view_func(request, *args, **kwargs)
  File "/app/argus_final/venv/lib/python2.7/site-packages/django/views/generic/base.py", line 68, in view
    return self.dispatch(request, *args, **kwargs)
  File "/app/argus_final/app/argus/argus/mixins.py", line 14, in dispatch
    return super(GENERIC_PERMISSION_MIXIN, self).dispatch(request, *args, **kwargs)
  File "/app/argus_final/venv/lib/python2.7/site-packages/django/views/generic/base.py", line 88, in dispatch
    return handler(request, *args, **kwargs)
  File "/app/argus_final/app/argus/esync/views.py", line 169, in get
    context['keys'] = parse_standard_config(context['content'])
  File "/app/argus_final/app/argus/esync/lib/nginx_processor.py", line 11, in parse_standard_config
    rConfig = nginx.loads(config).as_dict
  File "/app/argus_final/venv/lib/python2.7/site-packages/nginx.py", line 402, in loads
    m = re.compile(r'^\s*events\s*{', re.S).search(data[index:])
TypeError: 'bool' object has no attribute '__getitem__'
2021-03-08 23:09:06,955 DEBUG - starting thread (client mode): 0x2e1cf150L
2021-03-08 23:09:06,956 DEBUG - Local version/idstring: SSH-2.0-paramiko_2.6.0
2021-03-08 23:09:07,069 DEBUG - Remote version/idstring: SSH-2.0-OpenSSH_6.4
2021-03-08 23:09:07,070 INFO - Connected (version 2.0, client OpenSSH_6.4)
2021-03-08 23:09:07,083 DEBUG - kex algos:[u'ecdh-sha2-nistp256', u'ecdh-sha2-nistp384', u'ecdh-sha2-nistp521', u'diffie-hellman-group-exchange-sha256', u'diffie-hellman-group-exchange-sha1', u'diffie-hellman-group14-sha1', u'diffie-hellman-group1-sha1'] server key:[u'ssh-rsa', u'ecdsa-sha2-nistp256'] client encrypt:[u'aes128-ctr', u'aes192-ctr', u'aes256-ctr', u'arcfour256', u'arcfour128', u'aes128-gcm@openssh.com', u'aes256-gcm@openssh.com', u'aes128-cbc', u'3des-cbc', u'blowfish-cbc', u'cast128-cbc', u'aes192-cbc', u'aes256-cbc', u'arcfour', u'rijndael-cbc@lysator.liu.se'] server encrypt:[u'aes128-ctr', u'aes192-ctr', u'aes256-ctr', u'arcfour256', u'arcfour128', u'aes128-gcm@openssh.com', u'aes256-gcm@openssh.com', u'aes128-cbc', u'3des-cbc', u'blowfish-cbc', u'cast128-cbc', u'aes192-cbc', u'aes256-cbc', u'arcfour', u'rijndael-cbc@lysator.liu.se'] client mac:[u'hmac-md5-etm@openssh.com', u'hmac-sha1-etm@openssh.com', u'umac-64-etm@openssh.com', u'umac-128-etm@openssh.com', u'hmac-sha2-256-etm@openssh.com', u'hmac-sha2-512-etm@openssh.com', u'hmac-ripemd160-etm@openssh.com', u'hmac-sha1-96-etm@openssh.com', u'hmac-md5-96-etm@openssh.com', u'hmac-md5', u'hmac-sha1', u'umac-64@openssh.com', u'umac-128@openssh.com', u'hmac-sha2-256', u'hmac-sha2-512', u'hmac-ripemd160', u'hmac-ripemd160@openssh.com', u'hmac-sha1-96', u'hmac-md5-96'] server mac:[u'hmac-md5-etm@openssh.com', u'hmac-sha1-etm@openssh.com', u'umac-64-etm@openssh.com', u'umac-128-etm@openssh.com', u'hmac-sha2-256-etm@openssh.com', u'hmac-sha2-512-etm@openssh.com', u'hmac-ripemd160-etm@openssh.com', u'hmac-sha1-96-etm@openssh.com', u'hmac-md5-96-etm@openssh.com', u'hmac-md5', u'hmac-sha1', u'umac-64@openssh.com', u'umac-128@openssh.com', u'hmac-sha2-256', u'hmac-sha2-512', u'hmac-ripemd160', u'hmac-ripemd160@openssh.com', u'hmac-sha1-96', u'hmac-md5-96'] client compress:[u'none', u'zlib@openssh.com'] server compress:[u'none', u'zlib@openssh.com'] client lang:[u''] server lang:[u''] kex follows?False
2021-03-08 23:09:07,083 DEBUG - Kex agreed: ecdh-sha2-nistp256
2021-03-08 23:09:07,083 DEBUG - HostKey agreed: ecdsa-sha2-nistp256
2021-03-08 23:09:07,084 DEBUG - Cipher agreed: aes128-ctr
2021-03-08 23:09:07,084 DEBUG - MAC agreed: hmac-sha2-256
2021-03-08 23:09:07,084 DEBUG - Compression agreed: none
2021-03-08 23:09:07,092 DEBUG - kex engine KexNistp256 specified hash_algo <built-in function openssl_sha256>
2021-03-08 23:09:07,093 DEBUG - Switch to new keys ...
2021-03-08 23:09:07,123 DEBUG - Adding ecdsa-sha2-nistp256 host key for [103.56.16.4]:28032: 75d1c31170d6257e2001c1129928c81c
2021-03-08 23:09:07,125 DEBUG - Trying discovered key f1e2a20412f7e99b7abdb041b22f15e1 in /root/.ssh/id_rsa
2021-03-08 23:09:07,140 DEBUG - userauth is OK
2021-03-08 23:09:12,324 INFO - Authentication (publickey) successful!
2021-03-08 23:09:12,332 DEBUG - [chan 0] Max packet in: 32768 bytes
2021-03-08 23:09:12,785 DEBUG - Debug msg: Adding to environment: NAME=argus
2021-03-08 23:09:12,832 DEBUG - [chan 0] Max packet out: 32768 bytes
2021-03-08 23:09:12,832 DEBUG - Secsh channel 0 opened.
2021-03-08 23:09:12,862 DEBUG - [chan 0] Sesch channel 0 request ok
2021-03-08 23:09:12,873 DEBUG - [chan 0] Sesch channel 0 request ok
2021-03-08 23:09:12,874 DEBUG - [chan 1] Max packet in: 32768 bytes
2021-03-08 23:09:12,882 DEBUG - [chan 1] Max packet out: 32768 bytes
2021-03-08 23:09:12,883 DEBUG - Secsh channel 1 opened.
2021-03-08 23:09:12,903 DEBUG - [chan 1] Sesch channel 1 request ok
